Workbook
Name INTERCEPT_SCALED: Coefficients!$B$26
Name BASELINE_SMM: Coefficients!$B$27
Name BASELINE_CPR: Coefficients!$B$28

Sheet README
A1: V6E Voluntary Prepayment Calculator
A3: Model: V6E (18-feature logistic regression, test AUC 0.7614)
A4: Training period: 201812 to 202602
A5: Training events: 9,630 voluntary prepays in 1,225,921 eligible loan-months
A7: Tabs
A8: Coefficients - 18 feature parameters + intercept + diagnostics. Edit at your own risk.
A9: Loan_Snapshot - one row per loan, current-period CPR + per-feature attribution.
A10: Paste new loans into rows below the existing data; formulas autopopulate.
A11: Deal_Aggregator - UPB-weighted deal-level rollup. Edit Deal_ID column in Loan_Snapshot to control grouping.
A13: Math (centered native form)
A14: contribution_j = beta_native_j * (x_j - mean_j)
A15: logit_z = intercept_scaled + SUM(contributions)
... A37: Model: model_data_v6e.json (snapshot 202602)

Sheet Coefficients
A1: V6E Voluntary Prepayment Model - Coefficients
A2: Edit at your own risk. Loan_Snapshot pulls mean/std/beta_native from this tab.
A4: # | B4: feature | C4: group | D4: beta_scaled | E4: beta_native | F4: mean | G4: std | H4: label
A5: 1 | B5: refi_incentive_bps | C5: Rate & Restrictions | D5: 1.033619 | E5: 0.00529219 | F5: -49.12976 | G5: 195.3102 | H5: Net refi incentive (bp)
A6: 2 | B6: in_prepay_penalty | C6: Rate & Restrictions | D6: 0.118978 | E6: 0.3195021 | F6: 0.833659 | G6: 0.372386 | H6: In prepay penalty (1/0)
A7: 3 | B7: loan_age_months | C7: Loan Structure & Seasoning | D7: -0.20296 | E7: -0.00349527 | F7: 86.34898 | G7: 58.06699 | H7: Loan age (months)
A8: 4 | B8: log_upb | C8: Loan Structure & Seasoning | D8: 0.486231 | E8: 0.3897878 | F8: 15.38251 | G8: 1.247426 | H8: Log UPB
A9: 5 | B9: is_post_covid | C9: Loan Structure & Seasoning | D9: -0.306068 | E9: -0.9345385 | F9: 0.122192 | G9: 0.327507 | H9: Post-COVID vintage (1 if ≥2021)
A10: 6 | B10: cum_itm | C10: Burnout | D10: 0.446976 | E10: 0.02798139 | F10: 21.76565 | G10: 15.97405 | H10: Cumulative ITM months
A11: 7 | B11: burn_ratio | C11: Burnout | D11: -0.082251 | E11: -0.3124404 | F11: 0.325979 | G11: 0.263254 | H11: Burnout ratio
A12: 8 | B12: is_hc_232 | C12: FHA Program & Purpose | D12: -0.012292 | E12: -0.02829519 | F12: 0.252466 | G12: 0.434427 | H12: 232 Healthcare flag
A13: 9 | B13: is_223a7 | C13: FHA Program & Purpose | D13: 0.037602 | E13: 0.08666994 | F13: 0.251467 | G13: 0.433856 | H13: 223(a)(7) Streamlined refi
A14: 10 | B14: is_538 | C14: FHA Program & Purpose | D14: -0.148832 | E14: -0.6168215 | F14: 0.062074 | G14: 0.241289 | H14: 538 USDA Rural
A15: 11 | B15: lp_NC | C15: FHA Program & Purpose | D15: -0.009651 | E15: -0.0292121 | F15: 0.12469 | G15: 0.330367 | H15: Loan purpose: New Construction
A16: 12 | B16: iss_capital_funding | C16: Issuer (Servicer) | D16: -0.078439 | E16: -0.4520848 | F16: 0.031069 | G16: 0.173505 | H16: Issuer: Capital Funding
... A22: 18 | B22: iss_dwight | C22: Issuer (Servicer) | D22: 0.028424 | E22: 0.1639878 | F22: 0.031004 | G22: 0.173329 | H22: Issuer: Dwight Capital
A25: Model constants
A26: intercept_scaled | B26: -5.232982
A27: baseline_SMM (sigmoid of intercept_scaled) | B27: =1/(1+EXP(-B26))
A28: baseline_CPR (annualized from baseline_SMM) | B28: =1-(1-B27)^12
A30: Diagnostics
A31: test_AUC | B31: 0.7614
A32: panel_mean_CPR | B32: 0.090296
A33: training_pop_n | B33: 1225921
A34: training_events | B34: 9630
A35: panel_period_range | B35: 201812 - 202602

Sheet Loan_Snapshot
A1: Loan Identifiers | I1: Raw Inputs (editable) | T1: V6E Feature Values (formulas - do not edit) | AL1: Logit Contributions (β_native × (x − mean)) | BD1: CPR Summary | BH1: CPR Attribution (proportional method) | BZ1: Check
A2: loan_id | B2: deal_id | C2: pool_cusip | D2: issuer_name | E2: fha_category | F2: loan_purpose | G2: vintage_year | H2: period | I2: upb | J2: loan_rate_pct | K2: plc_rate_bps | L2: prepay_penalty_points | M2: loan_age_months_in | N2: cum_itm_in | O2: in_prepay_penalty_in | P2: is_hc_232_raw | Q2: is_223a7_raw | R2: is_538_raw | S2: is_new_construction_raw | T2: refi_incentive_bps | U2: in_prepay_penalty | V2: loan_age_months | W2: log_upb | X2: is_post_covid | Y2: cum_itm | Z2: burn_ratio | AA2: is_hc_232 | AB2: is_223a7 | AC2: is_538 | AD2: lp_NC | AE2: iss_capital_funding | AF2: iss_merchants | AG2: iss_wells_fargo | AH2: iss_walker_dunlop | AI2: iss_pnc | AJ2: iss_berkadia | AK2: iss_dwight | AL2: contrib_refi_incentive_bps | AM2: contrib_in_prepay_penalty | AN2: contrib_loan_age_months | AO2: contrib_log_upb | AP2: contrib_is_post_covid | AQ2: contrib_cum_itm | AR2: contrib_burn_ratio | AS2: contrib_is_hc_232 | AT2: contrib_is_223a7 | AU2: contrib_is_538 | AV2: contrib_lp_NC | AW2: contrib_iss_capital_funding | AX2: contrib_iss_merchants | AY2: contrib_iss_wells_fargo | AZ2: contrib_iss_walker_dunlop | BA2: contrib_iss_pnc | BB2: contrib_iss_berkadia | BC2: contrib_iss_dwight | BD2: total_logit_dev | BE2: logit_z | BF2: SMM | BG2: pred_CPR | BH2: attr_refi_incentive_bps | BI2: attr_in_prepay_penalty | BJ2: attr_loan_age_months | BK2: attr_log_upb | BL2: attr_is_post_covid | BM2: attr_cum_itm | BN2: attr_burn_ratio | BO2: attr_is_hc_232 | BP2: attr_is_223a7 | BQ2: attr_is_538 | BR2: attr_lp_NC | BS2: attr_iss_capital_funding | BT2: attr_iss_merchants | BU2: attr_iss_wells_fargo | BV2: attr_iss_walker_dunlop | BW2: attr_iss_pnc | BX2: attr_iss_berkadia | BY2: attr_iss_dwight | BZ2: Sanity
A3: mean | T3: =Coefficients!$F$5 | U3: =Coefficients!$F$6 | V3: =Coefficients!$F$7 | W3: =Coefficients!$F$8 | X3: =Coefficients!$F$9 | Y3: =Coefficients!$F$10 | Z3: =Coefficients!$F$11 | AA3: =Coefficients!$F$12 | AB3: =Coefficients!$F$13 | AC3: =Coefficients!$F$14 | AD3: =Coefficients!$F$15 | AE3: =Coefficients!$F$16 | AF3: =Coefficients!$F$17 | AG3: =Coefficients!$F$18 | AH3: =Coefficients!$F$19 | AI3: =Coefficients!$F$20 | AJ3: =Coefficients!$F$21 | AK3: =Coefficients!$F$22
A4: β_native | T4: =Coefficients!$E$5 | U4: =Coefficients!$E$6 | V4: =Coefficients!$E$7 | W4: =Coefficients!$E$8 | X4: =Coefficients!$E$9 | Y4: =Coefficients!$E$10 | Z4: =Coefficients!$E$11 | AA4: =Coefficients!$E$12 | AB4: =Coefficients!$E$13 | AC4: =Coefficients!$E$14 | AD4: =Coefficients!$E$15 | AE4: =Coefficients!$E$16 | AF4: =Coefficients!$E$17 | AG4: =Coefficients!$E$18 | AH4: =Coefficients!$E$19 | AI4: =Coefficients!$E$20 | AJ4: =Coefficients!$E$21 | AK4: =Coefficients!$E$22
A5: 3617UAX72_000000012211373 | B5: LUMENT_PRE21 | C5: 3617UAX72 | D5: LUMENT REAL ESTATE CAPITAL,LLC | E5: 223f | F5: RP | G5: 2015 | H5: 202602 | I5: 4746336.8 | J5: 2.96 | K5: 447 | L5: 5 | M5: 122 | N5: 1 | O5: 1 | P5: 0 | Q5: 0 | R5: 0 | S5: 0 | T5: =J5*100-(K5+(1+L5)*12.5) | U5: =O5 | V5: =M5 | W5: =LN(1+I5) | X5: =IF(G5>=2021,1,0) | Y5: =N5 | Z5: =IF(ISNUMBER(M5),N5/MAX(M5,1),0) | AA5: =P5 | AB5: =Q5 | AC5: =R5 | AD5: =S5 | AE5: =IF(ISNUMBER(SEARCH("CAPITAL FUNDING",D5)),1,0) | AF5: =IF(ISNUMBER(SEARCH("MERCHANTS",D5)),1,0) | AG5: =IF(ISNUMBER(SEARCH("WELLS FARGO",D5)),1,0) | AH5: =IF(ISNUMBER(SEARCH("WALKER",D5)),1,0) | AI5: =IF(ISNUMBER(SEARCH("PNC",D5)),1,0) | AJ5: =IF(ISNUMBER(SEARCH("BERKADIA",D5)),1,0) | AK5: =IF(ISNUMBER(SEARCH("DWIGHT",D5)),1,0) | AL5: =T$4*(T5-T$3) | AM5: =U$4*(U5-U$3) | AN5: =V$4*(V5-V$3) | AO5: =W$4*(W5-W$3) | AP5: =X$4*(X5-X$3) | AQ5: =Y$4*(Y5-Y$3) | AR5: =Z$4*(Z5-Z$3) | AS5: =AA$4*(AA5-AA$3) | ... BC5: =AK$4*(AK5-AK$3) | BD5: =SUM(AL5:BC5) | BE5: =INTERCEPT_SCALED+BD5 | BF5: =1/(1+EXP(-BE5)) | BG5: =1-(1-BF5)^12 | BH5: =IFERROR(AL5/BD5*(BG5-BASELINE_CPR),0) | BI5: =IFERROR(AM5/BD5*(BG5-BASELINE_CPR),0) | BJ5: =IFERROR(AN5/BD5*(BG5-BASELINE_CPR),0) | BK5: =IFERROR(AO5/BD5*(BG5-BASELINE_CPR),0) | BL5: =IFERROR(AP5/BD5*(BG5-BASELINE_CPR),0) | BM5: =IFERROR(AQ5/BD5*(BG5-BASELINE_CPR),0) | BN5: =IFERROR(AR5/BD5*(BG5-BASELINE_CPR),0) | BO5: =IFERROR(AS5/BD5*(BG5-BASELINE_CPR),0) | BP5: =IFERROR(AT5/BD5*(BG5-BASELINE_CPR),0) | BQ5: =IFERROR(AU5/BD5*(BG5-BASELINE_CPR),0) | BR5: =IFERROR(AV5/BD5*(BG5-BASELINE_CPR),0) | BS5: =IFERROR(AW5/BD5*(BG5-BASELINE_CPR),0) | BT5: =IFERROR(AX5/BD5*(BG5-BASELINE_CPR),0) | BU5: =IFERROR(AY5/BD5*(BG5-BASELINE_CPR),0) | BV5: =IFERROR(AZ5/BD5*(BG5-BASELINE_CPR),0) | BW5: =IFERROR(BA5/BD5*(BG5-BASELINE_CPR),0) | BX5: =IFERROR(BB5/BD5*(BG5-BASELINE_CPR),0) | BY5: =IFERROR(BC5/BD5*(BG5-BASELINE_CPR),0) | BZ5: =BASELINE_CPR+SUM(BH5:BY5)-BG5
A6: 3617H4UL3_000000012322093 | B6: LUMENT_PRE21 | C6: 3617H4UL3 | D6: LUMENT REAL ESTATE CAPITAL,LLC | E6: 232 | F6: RP | G6: 2018 | H6: 202602 | I6: 11482585 | J6: 4.35 | K6: 447 | L6: 0 | M6: 91 | N6: 35 | O6: 0 | P6: 1 | Q6: 0 | R6: 0 | S6: 0 | T6: =J6*100-(K6+(1+L6)*12.5) | U6: =O6 | V6: =M6 | W6: =LN(1+I6) | X6: =IF(G6>=2021,1,0) | Y6: =N6 | Z6: =IF(ISNUMBER(M6),N6/MAX(M6,1),0) | AA6: =P6 | AB6: =Q6 | AC6: =R6 | AD6: =S6 | AE6: =IF(ISNUMBER(SEARCH("CAPITAL FUNDING",D6)),1,0) | AF6: =IF(ISNUMBER(SEARCH("MERCHANTS",D6)),1,0) | AG6: =IF(ISNUMBER(SEARCH("WELLS FARGO",D6)),1,0) | AH6: =IF(ISNUMBER(SEARCH("WALKER",D6)),1,0) | AI6: =IF(ISNUMBER(SEARCH("PNC",D6)),1,0) | AJ6: =IF(ISNUMBER(SEARCH("BERKADIA",D6)),1,0) | AK6: =IF(ISNUMBER(SEARCH("DWIGHT",D6)),1,0) | AL6: =T$4*(T6-T$3) | AM6: =U$4*(U6-U$3) | AN6: =V$4*(V6-V$3) | AO6: =W$4*(W6-W$3) | AP6: =X$4*(X6-X$3) | AQ6: =Y$4*(Y6-Y$3) | AR6: =Z$4*(Z6-Z$3) | AS6: =AA$4*(AA6-AA$3) | ... BC6: =AK$4*(AK6-AK$3) | BD6: =SUM(AL6:BC6) | BE6: =INTERCEPT_SCALED+BD6 | BF6: =1/(1+EXP(-BE6)) | BG6: =1-(1-BF6)^12 | BH6: =IFERROR(AL6/BD6*(BG6-BASELINE_CPR),0) | BI6: =IFERROR(AM6/BD6*(BG6-BASELINE_CPR),0) | BJ6: =IFERROR(AN6/BD6*(BG6-BASELINE_CPR),0) | BK6: =IFERROR(AO6/BD6*(BG6-BASELINE_CPR),0) | BL6: =IFERROR(AP6/BD6*(BG6-BASELINE_CPR),0) | BM6: =IFERROR(AQ6/BD6*(BG6-BASELINE_CPR),0) | BN6: =IFERROR(AR6/BD6*(BG6-BASELINE_CPR),0) | BO6: =IFERROR(AS6/BD6*(BG6-BASELINE_CPR),0) | BP6: =IFERROR(AT6/BD6*(BG6-BASELINE_CPR),0) | BQ6: =IFERROR(AU6/BD6*(BG6-BASELINE_CPR),0) | BR6: =IFERROR(AV6/BD6*(BG6-BASELINE_CPR),0) | BS6: =IFERROR(AW6/BD6*(BG6-BASELINE_CPR),0) | BT6: =IFERROR(AX6/BD6*(BG6-BASELINE_CPR),0) | BU6: =IFERROR(AY6/BD6*(BG6-BASELINE_CPR),0) | BV6: =IFERROR(AZ6/BD6*(BG6-BASELINE_CPR),0) | BW6: =IFERROR(BA6/BD6*(BG6-BASELINE_CPR),0) | BX6: =IFERROR(BB6/BD6*(BG6-BASELINE_CPR),0) | BY6: =IFERROR(BC6/BD6*(BG6-BASELINE_CPR),0) | BZ6: =BASELINE_CPR+SUM(BH6:BY6)-BG6
A7: 3617QRGV6_000000002311435 | B7: LUMENT_PRE21 | C7: 3617QRGV6 | D7: LUMENT REAL ESTATE CAPITAL,LLC | E7: 223f | F7: RP | G7: 2017 | H7: 202602 | I7: 13751711 | J7: 3.15 | K7: 447 | L7: 5 | M7: 106 | N7: 9 | O7: 1 | P7: 0 | Q7: 0 | R7: 0 | S7: 0 | T7: =J7*100-(K7+(1+L7)*12.5) | U7: =O7 | V7: =M7 | W7: =LN(1+I7) | X7: =IF(G7>=2021,1,0) | Y7: =N7 | Z7: =IF(ISNUMBER(M7),N7/MAX(M7,1),0) | AA7: =P7 | AB7: =Q7 | AC7: =R7 | AD7: =S7 | AE7: =IF(ISNUMBER(SEARCH("CAPITAL FUNDING",D7)),1,0) | AF7: =IF(ISNUMBER(SEARCH("MERCHANTS",D7)),1,0) | AG7: =IF(ISNUMBER(SEARCH("WELLS FARGO",D7)),1,0) | AH7: =IF(ISNUMBER(SEARCH("WALKER",D7)),1,0) | AI7: =IF(ISNUMBER(SEARCH("PNC",D7)),1,0) | AJ7: =IF(ISNUMBER(SEARCH("BERKADIA",D7)),1,0) | AK7: =IF(ISNUMBER(SEARCH("DWIGHT",D7)),1,0) | AL7: =T$4*(T7-T$3) | AM7: =U$4*(U7-U$3) | AN7: =V$4*(V7-V$3) | AO7: =W$4*(W7-W$3) | AP7: =X$4*(X7-X$3) | AQ7: =Y$4*(Y7-Y$3) | AR7: =Z$4*(Z7-Z$3) | AS7: =AA$4*(AA7-AA$3) | ... BC7: =AK$4*(AK7-AK$3) | BD7: =SUM(AL7:BC7) | BE7: =INTERCEPT_SCALED+BD7 | BF7: =1/(1+EXP(-BE7)) | BG7: =1-(1-BF7)^12 | BH7: =IFERROR(AL7/BD7*(BG7-BASELINE_CPR),0) | BI7: =IFERROR(AM7/BD7*(BG7-BASELINE_CPR),0) | BJ7: =IFERROR(AN7/BD7*(BG7-BASELINE_CPR),0) | BK7: =IFERROR(AO7/BD7*(BG7-BASELINE_CPR),0) | BL7: =IFERROR(AP7/BD7*(BG7-BASELINE_CPR),0) | BM7: =IFERROR(AQ7/BD7*(BG7-BASELINE_CPR),0) | BN7: =IFERROR(AR7/BD7*(BG7-BASELINE_CPR),0) | BO7: =IFERROR(AS7/BD7*(BG7-BASELINE_CPR),0) | BP7: =IFERROR(AT7/BD7*(BG7-BASELINE_CPR),0) | BQ7: =IFERROR(AU7/BD7*(BG7-BASELINE_CPR),0) | BR7: =IFERROR(AV7/BD7*(BG7-BASELINE_CPR),0) | BS7: =IFERROR(AW7/BD7*(BG7-BASELINE_CPR),0) | BT7: =IFERROR(AX7/BD7*(BG7-BASELINE_CPR),0) | BU7: =IFERROR(AY7/BD7*(BG7-BASELINE_CPR),0) | BV7: =IFERROR(AZ7/BD7*(BG7-BASELINE_CPR),0) | BW7: =IFERROR(BA7/BD7*(BG7-BASELINE_CPR),0) | BX7: =IFERROR(BB7/BD7*(BG7-BASELINE_CPR),0) | BY7: =IFERROR(BC7/BD7*(BG7-BASELINE_CPR),0) | BZ7: =BASELINE_CPR+SUM(BH7:BY7)-BG7
A8: 3617GAE46_000000007122391 | B8: LUMENT_PRE21 | C8: 3617GAE46 | D8: LUMENT REAL ESTATE CAPITAL,LLC | E8: 232 | F8: RP | G8: 2018 | H8: 202602 | I8: 9767084.7 | J8: 3.58 | K8: 447 | L8: 4 | M8: 95 | N8: 27 | O8: 1 | P8: 1 | Q8: 0 | R8: 0 | S8: 0 | T8: =J8*100-(K8+(1+L8)*12.5) | U8: =O8 | V8: =M8 | W8: =LN(1+I8) | X8: =IF(G8>=2021,1,0) | Y8: =N8 | Z8: =IF(ISNUMBER(M8),N8/MAX(M8,1),0) | AA8: =P8 | AB8: =Q8 | AC8: =R8 | AD8: =S8 | AE8: =IF(ISNUMBER(SEARCH("CAPITAL FUNDING",D8)),1,0) | AF8: =IF(ISNUMBER(SEARCH("MERCHANTS",D8)),1,0) | AG8: =IF(ISNUMBER(SEARCH("WELLS FARGO",D8)),1,0) | AH8: =IF(ISNUMBER(SEARCH("WALKER",D8)),1,0) | AI8: =IF(ISNUMBER(SEARCH("PNC",D8)),1,0) | AJ8: =IF(ISNUMBER(SEARCH("BERKADIA",D8)),1,0) | AK8: =IF(ISNUMBER(SEARCH("DWIGHT",D8)),1,0) | AL8: =T$4*(T8-T$3) | AM8: =U$4*(U8-U$3) | AN8: =V$4*(V8-V$3) | AO8: =W$4*(W8-W$3) | AP8: =X$4*(X8-X$3) | AQ8: =Y$4*(Y8-Y$3) | AR8: =Z$4*(Z8-Z$3) | AS8: =AA$4*(AA8-AA$3) | ... BC8: =AK$4*(AK8-AK$3) | BD8: =SUM(AL8:BC8) | BE8: =INTERCEPT_SCALED+BD8 | BF8: =1/(1+EXP(-BE8)) | BG8: =1-(1-BF8)^12 | BH8: =IFERROR(AL8/BD8*(BG8-BASELINE_CPR),0) | BI8: =IFERROR(AM8/BD8*(BG8-BASELINE_CPR),0) | BJ8: =IFERROR(AN8/BD8*(BG8-BASELINE_CPR),0) | BK8: =IFERROR(AO8/BD8*(BG8-BASELINE_CPR),0) | BL8: =IFERROR(AP8/BD8*(BG8-BASELINE_CPR),0) | BM8: =IFERROR(AQ8/BD8*(BG8-BASELINE_CPR),0) | BN8: =IFERROR(AR8/BD8*(BG8-BASELINE_CPR),0) | BO8: =IFERROR(AS8/BD8*(BG8-BASELINE_CPR),0) | BP8: =IFERROR(AT8/BD8*(BG8-BASELINE_CPR),0) | BQ8: =IFERROR(AU8/BD8*(BG8-BASELINE_CPR),0) | BR8: =IFERROR(AV8/BD8*(BG8-BASELINE_CPR),0) | BS8: =IFERROR(AW8/BD8*(BG8-BASELINE_CPR),0) | BT8: =IFERROR(AX8/BD8*(BG8-BASELINE_CPR),0) | BU8: =IFERROR(AY8/BD8*(BG8-BASELINE_CPR),0) | BV8: =IFERROR(AZ8/BD8*(BG8-BASELINE_CPR),0) | BW8: =IFERROR(BA8/BD8*(BG8-BASELINE_CPR),0) | BX8: =IFERROR(BB8/BD8*(BG8-BASELINE_CPR),0) | BY8: =IFERROR(BC8/BD8*(BG8-BASELINE_CPR),0) | BZ8: =BASELINE_CPR+SUM(BH8:BY8)-BG8
A9: 3617X72J4_000000003422052 | B9: LUMENT_PRE21 | C9: 3617X72J4 | D9: LUMENT REAL ESTATE CAPITAL,LLC | E9: 232 | F9: RP | G9: 2011 | H9: 202602 | I9: 5069016.5 | J9: 3.05 | K9: 447 | L9: 6 | M9: 176 | N9: 0 | O9: 1 | P9: 1 | Q9: 0 | R9: 0 | S9: 0 | T9: =J9*100-(K9+(1+L9)*12.5) | U9: =O9 | V9: =M9 | W9: =LN(1+I9) | X9: =IF(G9>=2021,1,0) | Y9: =N9 | Z9: =IF(ISNUMBER(M9),N9/MAX(M9,1),0) | AA9: =P9 | AB9: =Q9 | AC9: =R9 | AD9: =S9 | AE9: =IF(ISNUMBER(SEARCH("CAPITAL FUNDING",D9)),1,0) | AF9: =IF(ISNUMBER(SEARCH("MERCHANTS",D9)),1,0) | AG9: =IF(ISNUMBER(SEARCH("WELLS FARGO",D9)),1,0) | AH9: =IF(ISNUMBER(SEARCH("WALKER",D9)),1,0) | AI9: =IF(ISNUMBER(SEARCH("PNC",D9)),1,0) | AJ9: =IF(ISNUMBER(SEARCH("BERKADIA",D9)),1,0) | AK9: =IF(ISNUMBER(SEARCH("DWIGHT",D9)),1,0) | AL9: =T$4*(T9-T$3) | AM9: =U$4*(U9-U$3) | AN9: =V$4*(V9-V$3) | AO9: =W$4*(W9-W$3) | AP9: =X$4*(X9-X$3) | AQ9: =Y$4*(Y9-Y$3) | AR9: =Z$4*(Z9-Z$3) | AS9: =AA$4*(AA9-AA$3) | ... BC9: =AK$4*(AK9-AK$3) | BD9: =SUM(AL9:BC9) | BE9: =INTERCEPT_SCALED+BD9 | BF9: =1/(1+EXP(-BE9)) | BG9: =1-(1-BF9)^12 | BH9: =IFERROR(AL9/BD9*(BG9-BASELINE_CPR),0) | BI9: =IFERROR(AM9/BD9*(BG9-BASELINE_CPR),0) | BJ9: =IFERROR(AN9/BD9*(BG9-BASELINE_CPR),0) | BK9: =IFERROR(AO9/BD9*(BG9-BASELINE_CPR),0) | BL9: =IFERROR(AP9/BD9*(BG9-BASELINE_CPR),0) | BM9: =IFERROR(AQ9/BD9*(BG9-BASELINE_CPR),0) | BN9: =IFERROR(AR9/BD9*(BG9-BASELINE_CPR),0) | BO9: =IFERROR(AS9/BD9*(BG9-BASELINE_CPR),0) | BP9: =IFERROR(AT9/BD9*(BG9-BASELINE_CPR),0) | BQ9: =IFERROR(AU9/BD9*(BG9-BASELINE_CPR),0) | BR9: =IFERROR(AV9/BD9*(BG9-BASELINE_CPR),0) | BS9: =IFERROR(AW9/BD9*(BG9-BASELINE_CPR),0) | BT9: =IFERROR(AX9/BD9*(BG9-BASELINE_CPR),0) | BU9: =IFERROR(AY9/BD9*(BG9-BASELINE_CPR),0) | BV9: =IFERROR(AZ9/BD9*(BG9-BASELINE_CPR),0) | BW9: =IFERROR(BA9/BD9*(BG9-BASELINE_CPR),0) | BX9: =IFERROR(BB9/BD9*(BG9-BASELINE_CPR),0) | BY9: =IFERROR(BC9/BD9*(BG9-BASELINE_CPR),0) | BZ9: =BASELINE_CPR+SUM(BH9:BY9)-BG9
A10: 3617X74P8_000000007343145 | B10: LUMENT_PRE21 | C10: 3617X74P8 | D10: LUMENT REAL ESTATE CAPITAL,LLC | E10: 232 | F10: RP | G10: 2013 | H10: 202602 | I10: 11587614 | J10: 3.42 | K10: 447 | L10: 6 | M10: 148 | N10: 1 | O10: 1 | P10: 1 | Q10: 1 | R10: 0 | S10: 0 | T10: =J10*100-(K10+(1+L10)*12.5) | U10: =O10 | V10: =M10 | W10: =LN(1+I10) | X10: =IF(G10>=2021,1,0) | Y10: =N10 | Z10: =IF(ISNUMBER(M10),N10/MAX(M10,1),0) | AA10: =P10 | AB10: =Q10 | AC10: =R10 | AD10: =S10 | AE10: =IF(ISNUMBER(SEARCH("CAPITAL FUNDING",D10)),1,0) | AF10: =IF(ISNUMBER(SEARCH("MERCHANTS",D10)),1,0) | AG10: =IF(ISNUMBER(SEARCH("WELLS FARGO",D10)),1,0) | AH10: =IF(ISNUMBER(SEARCH("WALKER",D10)),1,0) | AI10: =IF(ISNUMBER(SEARCH("PNC",D10)),1,0) | AJ10: =IF(ISNUMBER(SEARCH("BERKADIA",D10)),1,0) | AK10: =IF(ISNUMBER(SEARCH("DWIGHT",D10)),1,0) | AL10: =T$4*(T10-T$3) | AM10: =U$4*(U10-U$3) | AN10: =V$4*(V10-V$3) | AO10: =W$4*(W10-W$3) | AP10: =X$4*(X10-X$3) | AQ10: =Y$4*(Y10-Y$3) | AR10: =Z$4*(Z10-Z$3) | AS10: =AA$4*(AA10-AA$3) | ... BC10: =AK$4*(AK10-AK$3) | BD10: =SUM(AL10:BC10) | BE10: =INTERCEPT_SCALED+BD10 | BF10: =1/(1+EXP(-BE10)) | BG10: =1-(1-BF10)^12 | BH10: =IFERROR(AL10/BD10*(BG10-BASELINE_CPR),0) | BI10: =IFERROR(AM10/BD10*(BG10-BASELINE_CPR),0) | BJ10: =IFERROR(AN10/BD10*(BG10-BASELINE_CPR),0) | BK10: =IFERROR(AO10/BD10*(BG10-BASELINE_CPR),0) | BL10: =IFERROR(AP10/BD10*(BG10-BASELINE_CPR),0) | BM10: =IFERROR(AQ10/BD10*(BG10-BASELINE_CPR),0) | BN10: =IFERROR(AR10/BD10*(BG10-BASELINE_CPR),0) | BO10: =IFERROR(AS10/BD10*(BG10-BASELINE_CPR),0) | BP10: =IFERROR(AT10/BD10*(BG10-BASELINE_CPR),0) | BQ10: =IFERROR(AU10/BD10*(BG10-BASELINE_CPR),0) | BR10: =IFERROR(AV10/BD10*(BG10-BASELINE_CPR),0) | BS10: =IFERROR(AW10/BD10*(BG10-BASELINE_CPR),0) | BT10: =IFERROR(AX10/BD10*(BG10-BASELINE_CPR),0) | BU10: =IFERROR(AY10/BD10*(BG10-BASELINE_CPR),0) | BV10: =IFERROR(AZ10/BD10*(BG10-BASELINE_CPR),0) | BW10: =IFERROR(BA10/BD10*(BG10-BASELINE_CPR),0) | BX10: =IFERROR(BB10/BD10*(BG10-BASELINE_CPR),0) | BY10: =IFERROR(BC10/BD10*(BG10-BASELINE_CPR),0) | BZ10: =BASELINE_CPR+SUM(BH10:BY10)-BG10
A11: 3620AEYZ7_000000010535179 | B11: LUMENT_PRE21 | C11: 3620AEYZ7 | D11: LUMENT REAL ESTATE CAPITAL,LLC | E11: OTHER | F11: OTHER | G11: 2010 | H11: 202602 | I11: 7782165.9 | J11: 3.38 | K11: 447 | L11: 0 | M11: 182 | N11: 36 | O11: 0 | P11: 0 | Q11: 0 | R11: 0 | S11: 0 | T11: =J11*100-(K11+(1+L11)*12.5) | U11: =O11 | V11: =M11 | W11: =LN(1+I11) | X11: =IF(G11>=2021,1,0) | Y11: =N11 | Z11: =IF(ISNUMBER(M11),N11/MAX(M11,1),0) | AA11: =P11 | AB11: =Q11 | AC11: =R11 | AD11: =S11 | AE11: =IF(ISNUMBER(SEARCH("CAPITAL FUNDING",D11)),1,0) | AF11: =IF(ISNUMBER(SEARCH("MERCHANTS",D11)),1,0) | AG11: =IF(ISNUMBER(SEARCH("WELLS FARGO",D11)),1,0) | AH11: =IF(ISNUMBER(SEARCH("WALKER",D11)),1,0) | AI11: =IF(ISNUMBER(SEARCH("PNC",D11)),1,0) | AJ11: =IF(ISNUMBER(SEARCH("BERKADIA",D11)),1,0) | AK11: =IF(ISNUMBER(SEARCH("DWIGHT",D11)),1,0) | AL11: =T$4*(T11-T$3) | AM11: =U$4*(U11-U$3) | AN11: =V$4*(V11-V$3) | AO11: =W$4*(W11-W$3) | AP11: =X$4*(X11-X$3) | AQ11: =Y$4*(Y11-Y$3) | AR11: =Z$4*(Z11-Z$3) | AS11: =AA$4*(AA11-AA$3) | ... BC11: =AK$4*(AK11-AK$3) | BD11: =SUM(AL11:BC11) | BE11: =INTERCEPT_SCALED+BD11 | BF11: =1/(1+EXP(-BE11)) | BG11: =1-(1-BF11)^12 | BH11: =IFERROR(AL11/BD11*(BG11-BASELINE_CPR),0) | BI11: =IFERROR(AM11/BD11*(BG11-BASELINE_CPR),0) | BJ11: =IFERROR(AN11/BD11*(BG11-BASELINE_CPR),0) | BK11: =IFERROR(AO11/BD11*(BG11-BASELINE_CPR),0) | BL11: =IFERROR(AP11/BD11*(BG11-BASELINE_CPR),0) | BM11: =IFERROR(AQ11/BD11*(BG11-BASELINE_CPR),0) | BN11: =IFERROR(AR11/BD11*(BG11-BASELINE_CPR),0) | BO11: =IFERROR(AS11/BD11*(BG11-BASELINE_CPR),0) | BP11: =IFERROR(AT11/BD11*(BG11-BASELINE_CPR),0) | BQ11: =IFERROR(AU11/BD11*(BG11-BASELINE_CPR),0) | BR11: =IFERROR(AV11/BD11*(BG11-BASELINE_CPR),0) | BS11: =IFERROR(AW11/BD11*(BG11-BASELINE_CPR),0) | BT11: =IFERROR(AX11/BD11*(BG11-BASELINE_CPR),0) | BU11: =IFERROR(AY11/BD11*(BG11-BASELINE_CPR),0) | BV11: =IFERROR(AZ11/BD11*(BG11-BASELINE_CPR),0) | BW11: =IFERROR(BA11/BD11*(BG11-BASELINE_CPR),0) | BX11: =IFERROR(BB11/BD11*(BG11-BASELINE_CPR),0) | BY11: =IFERROR(BC11/BD11*(BG11-BASELINE_CPR),0) | BZ11: =BASELINE_CPR+SUM(BH11:BY11)-BG11
A12: 3618BNC43_000000001211581 | B12: LUMENT_POST21 | C12: 3618BNC43 | D12: LUMENT REAL ESTATE CAPITAL,LLC | E12: 223f | F12: RP | G12: 2023 | H12: 202602 | I12: 30791262 | J12: 5.36 | K12: 447 | L12: 8 | M12: 32 | N12: 0 | O12: 1 | P12: 0 | Q12: 0 | R12: 0 | S12: 0 | T12: =J12*100-(K12+(1+L12)*12.5) | U12: =O12 | V12: =M12 | W12: =LN(1+I12) | X12: =IF(G12>=2021,1,0) | Y12: =N12 | Z12: =IF(ISNUMBER(M12),N12/MAX(M12,1),0) | AA12: =P12 | AB12: =Q12 | AC12: =R12 | AD12: =S12 | AE12: =IF(ISNUMBER(SEARCH("CAPITAL FUNDING",D12)),1,0) | AF12: =IF(ISNUMBER(SEARCH("MERCHANTS",D12)),1,0) | AG12: =IF(ISNUMBER(SEARCH("WELLS FARGO",D12)),1,0) | AH12: =IF(ISNUMBER(SEARCH("WALKER",D12)),1,0) | AI12: =IF(ISNUMBER(SEARCH("PNC",D12)),1,0) | AJ12: =IF(ISNUMBER(SEARCH("BERKADIA",D12)),1,0) | AK12: =IF(ISNUMBER(SEARCH("DWIGHT",D12)),1,0) | AL12: =T$4*(T12-T$3) | AM12: =U$4*(U12-U$3) | AN12: =V$4*(V12-V$3) | AO12: =W$4*(W12-W$3) | AP12: =X$4*(X12-X$3) | AQ12: =Y$4*(Y12-Y$3) | AR12: =Z$4*(Z12-Z$3) | AS12: =AA$4*(AA12-AA$3) | ... BC12: =AK$4*(AK12-AK$3) | BD12: =SUM(AL12:BC12) | BE12: =INTERCEPT_SCALED+BD12 | BF12: =1/(1+EXP(-BE12)) | BG12: =1-(1-BF12)^12 | BH12: =IFERROR(AL12/BD12*(BG12-BASELINE_CPR),0) | BI12: =IFERROR(AM12/BD12*(BG12-BASELINE_CPR),0) | BJ12: =IFERROR(AN12/BD12*(BG12-BASELINE_CPR),0) | BK12: =IFERROR(AO12/BD12*(BG12-BASELINE_CPR),0) | BL12: =IFERROR(AP12/BD12*(BG12-BASELINE_CPR),0) | BM12: =IFERROR(AQ12/BD12*(BG12-BASELINE_CPR),0) | BN12: =IFERROR(AR12/BD12*(BG12-BASELINE_CPR),0) | BO12: =IFERROR(AS12/BD12*(BG12-BASELINE_CPR),0) | BP12: =IFERROR(AT12/BD12*(BG12-BASELINE_CPR),0) | BQ12: =IFERROR(AU12/BD12*(BG12-BASELINE_CPR),0) | BR12: =IFERROR(AV12/BD12*(BG12-BASELINE_CPR),0) | BS12: =IFERROR(AW12/BD12*(BG12-BASELINE_CPR),0) | BT12: =IFERROR(AX12/BD12*(BG12-BASELINE_CPR),0) | BU12: =IFERROR(AY12/BD12*(BG12-BASELINE_CPR),0) | BV12: =IFERROR(AZ12/BD12*(BG12-BASELINE_CPR),0) | BW12: =IFERROR(BA12/BD12*(BG12-BASELINE_CPR),0) | BX12: =IFERROR(BB12/BD12*(BG12-BASELINE_CPR),0) | BY12: =IFERROR(BC12/BD12*(BG12-BASELINE_CPR),0) | BZ12: =BASELINE_CPR+SUM(BH12:BY12)-BG12
A13: 3618KLMG9_000000001211630 | B13: LUMENT_POST21 | C13: 3618KLMG9 | D13: LUMENT REAL ESTATE CAPITAL,LLC | E13: 223f | F13: RP | G13: 2025 | H13: 202602 | I13: 59508580 | J13: 5.65 | K13: 447 | L13: 10 | M13: 4 | N13: 0 | O13: 1 | P13: 0 | Q13: 0 | R13: 0 | S13: 0 | T13: =J13*100-(K13+(1+L13)*12.5) | U13: =O13 | V13: =M13 | W13: =LN(1+I13) | X13: =IF(G13>=2021,1,0) | Y13: =N13 | Z13: =IF(ISNUMBER(M13),N13/MAX(M13,1),0) | AA13: =P13 | AB13: =Q13 | AC13: =R13 | AD13: =S13 | AE13: =IF(ISNUMBER(SEARCH("CAPITAL FUNDING",D13)),1,0) | AF13: =IF(ISNUMBER(SEARCH("MERCHANTS",D13)),1,0) | AG13: =IF(ISNUMBER(SEARCH("WELLS FARGO",D13)),1,0) | AH13: =IF(ISNUMBER(SEARCH("WALKER",D13)),1,0) | AI13: =IF(ISNUMBER(SEARCH("PNC",D13)),1,0) | AJ13: =IF(ISNUMBER(SEARCH("BERKADIA",D13)),1,0) | AK13: =IF(ISNUMBER(SEARCH("DWIGHT",D13)),1,0) | AL13: =T$4*(T13-T$3) | AM13: =U$4*(U13-U$3) | AN13: =V$4*(V13-V$3) | AO13: =W$4*(W13-W$3) | AP13: =X$4*(X13-X$3) | AQ13: =Y$4*(Y13-Y$3) | AR13: =Z$4*(Z13-Z$3) | AS13: =AA$4*(AA13-AA$3) | ... BC13: =AK$4*(AK13-AK$3) | BD13: =SUM(AL13:BC13) | BE13: =INTERCEPT_SCALED+BD13 | BF13: =1/(1+EXP(-BE13)) | BG13: =1-(1-BF13)^12 | BH13: =IFERROR(AL13/BD13*(BG13-BASELINE_CPR),0) | BI13: =IFERROR(AM13/BD13*(BG13-BASELINE_CPR),0) | BJ13: =IFERROR(AN13/BD13*(BG13-BASELINE_CPR),0) | BK13: =IFERROR(AO13/BD13*(BG13-BASELINE_CPR),0) | BL13: =IFERROR(AP13/BD13*(BG13-BASELINE_CPR),0) | BM13: =IFERROR(AQ13/BD13*(BG13-BASELINE_CPR),0) | BN13: =IFERROR(AR13/BD13*(BG13-BASELINE_CPR),0) | BO13: =IFERROR(AS13/BD13*(BG13-BASELINE_CPR),0) | BP13: =IFERROR(AT13/BD13*(BG13-BASELINE_CPR),0) | BQ13: =IFERROR(AU13/BD13*(BG13-BASELINE_CPR),0) | BR13: =IFERROR(AV13/BD13*(BG13-BASELINE_CPR),0) | BS13: =IFERROR(AW13/BD13*(BG13-BASELINE_CPR),0) | BT13: =IFERROR(AX13/BD13*(BG13-BASELINE_CPR),0) | BU13: =IFERROR(AY13/BD13*(BG13-BASELINE_CPR),0) | BV13: =IFERROR(AZ13/BD13*(BG13-BASELINE_CPR),0) | BW13: =IFERROR(BA13/BD13*(BG13-BASELINE_CPR),0) | BX13: =IFERROR(BB13/BD13*(BG13-BASELINE_CPR),0) | BY13: =IFERROR(BC13/BD13*(BG13-BASELINE_CPR),0) | BZ13: =BASELINE_CPR+SUM(BH13:BY13)-BG13
A14: 36297HB49_000000010222024 | B14: LUMENT_PRE21 | C14: 36297HB49 | D14: LUMENT REAL ESTATE CAPITAL,LLC | E14: 232 | F14: RP | G14: 2009 | H14: 202602 | I14: 2318598.5 | J14: 5.65 | K14: 447 | L14: 0 | M14: 200 | N14: 84 | O14: 0 | P14: 1 | Q14: 0 | R14: 0 | S14: 0 | T14: =J14*100-(K14+(1+L14)*12.5) | U14: =O14 | V14: =M14 | W14: =LN(1+I14) | X14: =IF(G14>=2021,1,0) | Y14: =N14 | Z14: =IF(ISNUMBER(M14),N14/MAX(M14,1),0) | AA14: =P14 | AB14: =Q14 | AC14: =R14 | AD14: =S14 | AE14: =IF(ISNUMBER(SEARCH("CAPITAL FUNDING",D14)),1,0) | AF14: =IF(ISNUMBER(SEARCH("MERCHANTS",D14)),1,0) | AG14: =IF(ISNUMBER(SEARCH("WELLS FARGO",D14)),1,0) | AH14: =IF(ISNUMBER(SEARCH("WALKER",D14)),1,0) | AI14: =IF(ISNUMBER(SEARCH("PNC",D14)),1,0) | AJ14: =IF(ISNUMBER(SEARCH("BERKADIA",D14)),1,0) | AK14: =IF(ISNUMBER(SEARCH("DWIGHT",D14)),1,0) | AL14: =T$4*(T14-T$3) | AM14: =U$4*(U14-U$3) | AN14: =V$4*(V14-V$3) | AO14: =W$4*(W14-W$3) | AP14: =X$4*(X14-X$3) | AQ14: =Y$4*(Y14-Y$3) | AR14: =Z$4*(Z14-Z$3) | AS14: =AA$4*(AA14-AA$3) | ... BC14: =AK$4*(AK14-AK$3) | BD14: =SUM(AL14:BC14) | BE14: =INTERCEPT_SCALED+BD14 | BF14: =1/(1+EXP(-BE14)) | BG14: =1-(1-BF14)^12 | BH14: =IFERROR(AL14/BD14*(BG14-BASELINE_CPR),0) | BI14: =IFERROR(AM14/BD14*(BG14-BASELINE_CPR),0) | BJ14: =IFERROR(AN14/BD14*(BG14-BASELINE_CPR),0) | BK14: =IFERROR(AO14/BD14*(BG14-BASELINE_CPR),0) | BL14: =IFERROR(AP14/BD14*(BG14-BASELINE_CPR),0) | BM14: =IFERROR(AQ14/BD14*(BG14-BASELINE_CPR),0) | BN14: =IFERROR(AR14/BD14*(BG14-BASELINE_CPR),0) | BO14: =IFERROR(AS14/BD14*(BG14-BASELINE_CPR),0) | BP14: =IFERROR(AT14/BD14*(BG14-BASELINE_CPR),0) | BQ14: =IFERROR(AU14/BD14*(BG14-BASELINE_CPR),0) | BR14: =IFERROR(AV14/BD14*(BG14-BASELINE_CPR),0) | BS14: =IFERROR(AW14/BD14*(BG14-BASELINE_CPR),0) | BT14: =IFERROR(AX14/BD14*(BG14-BASELINE_CPR),0) | BU14: =IFERROR(AY14/BD14*(BG14-BASELINE_CPR),0) | BV14: =IFERROR(AZ14/BD14*(BG14-BASELINE_CPR),0) | BW14: =IFERROR(BA14/BD14*(BG14-BASELINE_CPR),0) | BX14: =IFERROR(BB14/BD14*(BG14-BASELINE_CPR),0) | BY14: =IFERROR(BC14/BD14*(BG14-BASELINE_CPR),0) | BZ14: =BASELINE_CPR+SUM(BH14:BY14)-BG14
A15: 3618HNAN7_000000006122229 | B15: LUMENT_POST21 | C15: 3618HNAN7 | D15: LUMENT REAL ESTATE CAPITAL,LLC | E15: 232 | F15: RP | G15: 2024 | H15: 202602 | I15: 10649283 | J15: 5.35 | K15: 447 | L15: 9 | M15: 14 | N15: 0 | O15: 1 | P15: 1 | Q15: 0 | R15: 0 | S15: 0 | T15: =J15*100-(K15+(1+L15)*12.5) | U15: =O15 | V15: =M15 | W15: =LN(1+I15) | X15: =IF(G15>=2021,1,0) | Y15: =N15 | Z15: =IF(ISNUMBER(M15),N15/MAX(M15,1),0) | AA15: =P15 | AB15: =Q15 | AC15: =R15 | AD15: =S15 | AE15: =IF(ISNUMBER(SEARCH("CAPITAL FUNDING",D15)),1,0) | AF15: =IF(ISNUMBER(SEARCH("MERCHANTS",D15)),1,0) | AG15: =IF(ISNUMBER(SEARCH("WELLS FARGO",D15)),1,0) | AH15: =IF(ISNUMBER(SEARCH("WALKER",D15)),1,0) | AI15: =IF(ISNUMBER(SEARCH("PNC",D15)),1,0) | AJ15: =IF(ISNUMBER(SEARCH("BERKADIA",D15)),1,0) | AK15: =IF(ISNUMBER(SEARCH("DWIGHT",D15)),1,0) | AL15: =T$4*(T15-T$3) | AM15: =U$4*(U15-U$3) | AN15: =V$4*(V15-V$3) | AO15: =W$4*(W15-W$3) | AP15: =X$4*(X15-X$3) | AQ15: =Y$4*(Y15-Y$3) | AR15: =Z$4*(Z15-Z$3) | AS15: =AA$4*(AA15-AA$3) | ... BC15: =AK$4*(AK15-AK$3) | BD15: =SUM(AL15:BC15) | BE15: =INTERCEPT_SCALED+BD15 | BF15: =1/(1+EXP(-BE15)) | BG15: =1-(1-BF15)^12 | BH15: =IFERROR(AL15/BD15*(BG15-BASELINE_CPR),0) | BI15: =IFERROR(AM15/BD15*(BG15-BASELINE_CPR),0) | BJ15: =IFERROR(AN15/BD15*(BG15-BASELINE_CPR),0) | BK15: =IFERROR(AO15/BD15*(BG15-BASELINE_CPR),0) | BL15: =IFERROR(AP15/BD15*(BG15-BASELINE_CPR),0) | BM15: =IFERROR(AQ15/BD15*(BG15-BASELINE_CPR),0) | BN15: =IFERROR(AR15/BD15*(BG15-BASELINE_CPR),0) | BO15: =IFERROR(AS15/BD15*(BG15-BASELINE_CPR),0) | BP15: =IFERROR(AT15/BD15*(BG15-BASELINE_CPR),0) | BQ15: =IFERROR(AU15/BD15*(BG15-BASELINE_CPR),0) | BR15: =IFERROR(AV15/BD15*(BG15-BASELINE_CPR),0) | BS15: =IFERROR(AW15/BD15*(BG15-BASELINE_CPR),0) | BT15: =IFERROR(AX15/BD15*(BG15-BASELINE_CPR),0) | BU15: =IFERROR(AY15/BD15*(BG15-BASELINE_CPR),0) | BV15: =IFERROR(AZ15/BD15*(BG15-BASELINE_CPR),0) | BW15: =IFERROR(BA15/BD15*(BG15-BASELINE_CPR),0) | BX15: =IFERROR(BB15/BD15*(BG15-BASELINE_CPR),0) | BY15: =IFERROR(BC15/BD15*(BG15-BASELINE_CPR),0) | BZ15: =BASELINE_CPR+SUM(BH15:BY15)-BG15
A16: 3617LC5T1_000000004611186 | B16: LUMENT_PRE21 | C16: 3617LC5T1 | D16: LUMENT REAL ESTATE CAPITAL,LLC | E16: 223f | F16: RP | G16: 2019 | H16: 202602 | I16: 14083196 | J16: 2.95 | K16: 447 | L16: 4 | M16: 75 | N16: 7 | O16: 1 | P16: 0 | Q16: 0 | R16: 0 | S16: 0 | T16: =J16*100-(K16+(1+L16)*12.5) | U16: =O16 | V16: =M16 | W16: =LN(1+I16) | X16: =IF(G16>=2021,1,0) | Y16: =N16 | Z16: =IF(ISNUMBER(M16),N16/MAX(M16,1),0) | AA16: =P16 | AB16: =Q16 | AC16: =R16 | AD16: =S16 | AE16: =IF(ISNUMBER(SEARCH("CAPITAL FUNDING",D16)),1,0) | AF16: =IF(ISNUMBER(SEARCH("MERCHANTS",D16)),1,0) | AG16: =IF(ISNUMBER(SEARCH("WELLS FARGO",D16)),1,0) | AH16: =IF(ISNUMBER(SEARCH("WALKER",D16)),1,0) | AI16: =IF(ISNUMBER(SEARCH("PNC",D16)),1,0) | AJ16: =IF(ISNUMBER(SEARCH("BERKADIA",D16)),1,0) | AK16: =IF(ISNUMBER(SEARCH("DWIGHT",D16)),1,0) | AL16: =T$4*(T16-T$3) | AM16: =U$4*(U16-U$3) | AN16: =V$4*(V16-V$3) | AO16: =W$4*(W16-W$3) | AP16: =X$4*(X16-X$3) | AQ16: =Y$4*(Y16-Y$3) | AR16: =Z$4*(Z16-Z$3) | AS16: =AA$4*(AA16-AA$3) | ... BC16: =AK$4*(AK16-AK$3) | BD16: =SUM(AL16:BC16) | BE16: =INTERCEPT_SCALED+BD16 | BF16: =1/(1+EXP(-BE16)) | BG16: =1-(1-BF16)^12 | BH16: =IFERROR(AL16/BD16*(BG16-BASELINE_CPR),0) | BI16: =IFERROR(AM16/BD16*(BG16-BASELINE_CPR),0) | BJ16: =IFERROR(AN16/BD16*(BG16-BASELINE_CPR),0) | BK16: =IFERROR(AO16/BD16*(BG16-BASELINE_CPR),0) | BL16: =IFERROR(AP16/BD16*(BG16-BASELINE_CPR),0) | BM16: =IFERROR(AQ16/BD16*(BG16-BASELINE_CPR),0) | BN16: =IFERROR(AR16/BD16*(BG16-BASELINE_CPR),0) | BO16: =IFERROR(AS16/BD16*(BG16-BASELINE_CPR),0) | BP16: =IFERROR(AT16/BD16*(BG16-BASELINE_CPR),0) | BQ16: =IFERROR(AU16/BD16*(BG16-BASELINE_CPR),0) | BR16: =IFERROR(AV16/BD16*(BG16-BASELINE_CPR),0) | BS16: =IFERROR(AW16/BD16*(BG16-BASELINE_CPR),0) | BT16: =IFERROR(AX16/BD16*(BG16-BASELINE_CPR),0) | BU16: =IFERROR(AY16/BD16*(BG16-BASELINE_CPR),0) | BV16: =IFERROR(AZ16/BD16*(BG16-BASELINE_CPR),0) | BW16: =IFERROR(BA16/BD16*(BG16-BASELINE_CPR),0) | BX16: =IFERROR(BB16/BD16*(BG16-BASELINE_CPR),0) | BY16: =IFERROR(BC16/BD16*(BG16-BASELINE_CPR),0) | BZ16: =BASELINE_CPR+SUM(BH16:BY16)-BG16
... A256: 3617QBNR2_000000008311216 | B256: NORTHMARQ_POST21 | C256: 3617QBNR2 | D256: NORTHMARQ FINANCE, LLC | E256: 223f | F256: RP | G256: 2021 | H256: 202602 | I256: 9833583.3 | J256: 2.7 | K256: 447 | L256: 6 | M256: 58 | N256: 0 | O256: 1 | P256: 0 | Q256: 0 | R256: 0 | S256: 0 | T256: =J256*100-(K256+(1+L256)*12.5) | U256: =O256 | V256: =M256 | W256: =LN(1+I256) | X256: =IF(G256>=2021,1,0) | Y256: =N256 | Z256: =IF(ISNUMBER(M256),N256/MAX(M256,1),0) | AA256: =P256 | AB256: =Q256 | AC256: =R256 | AD256: =S256 | AE256: =IF(ISNUMBER(SEARCH("CAPITAL FUNDING",D256)),1,0) | AF256: =IF(ISNUMBER(SEARCH("MERCHANTS",D256)),1,0) | AG256: =IF(ISNUMBER(SEARCH("WELLS FARGO",D256)),1,0) | AH256: =IF(ISNUMBER(SEARCH("WALKER",D256)),1,0) | AI256: =IF(ISNUMBER(SEARCH("PNC",D256)),1,0) | AJ256: =IF(ISNUMBER(SEARCH("BERKADIA",D256)),1,0) | AK256: =IF(ISNUMBER(SEARCH("DWIGHT",D256)),1,0) | AL256: =T$4*(T256-T$3) | AM256: =U$4*(U256-U$3) | AN256: =V$4*(V256-V$3) | AO256: =W$4*(W256-W$3) | AP256: =X$4*(X256-X$3) | AQ256: =Y$4*(Y256-Y$3) | AR256: =Z$4*(Z256-Z$3) | AS256: =AA$4*(AA256-AA$3) | ... BC256: =AK$4*(AK256-AK$3) | BD256: =SUM(AL256:BC256) | BE256: =INTERCEPT_SCALED+BD256 | BF256: =1/(1+EXP(-BE256)) | BG256: =1-(1-BF256)^12 | BH256: =IFERROR(AL256/BD256*(BG256-BASELINE_CPR),0) | BI256: =IFERROR(AM256/BD256*(BG256-BASELINE_CPR),0) | BJ256: =IFERROR(AN256/BD256*(BG256-BASELINE_CPR),0) | BK256: =IFERROR(AO256/BD256*(BG256-BASELINE_CPR),0) | BL256: =IFERROR(AP256/BD256*(BG256-BASELINE_CPR),0) | BM256: =IFERROR(AQ256/BD256*(BG256-BASELINE_CPR),0) | BN256: =IFERROR(AR256/BD256*(BG256-BASELINE_CPR),0) | BO256: =IFERROR(AS256/BD256*(BG256-BASELINE_CPR),0) | BP256: =IFERROR(AT256/BD256*(BG256-BASELINE_CPR),0) | BQ256: =IFERROR(AU256/BD256*(BG256-BASELINE_CPR),0) | BR256: =IFERROR(AV256/BD256*(BG256-BASELINE_CPR),0) | BS256: =IFERROR(AW256/BD256*(BG256-BASELINE_CPR),0) | BT256: =IFERROR(AX256/BD256*(BG256-BASELINE_CPR),0) | BU256: =IFERROR(AY256/BD256*(BG256-BASELINE_CPR),0) | BV256: =IFERROR(AZ256/BD256*(BG256-BASELINE_CPR),0) | BW256: =IFERROR(BA256/BD256*(BG256-BASELINE_CPR),0) | BX256: =IFERROR(BB256/BD256*(BG256-BASELINE_CPR),0) | BY256: =IFERROR(BC256/BD256*(BG256-BASELINE_CPR),0) | BZ256: =BASELINE_CPR+SUM(BH256:BY256)-BG256

Sheet Deal_Aggregator
A1: Deal-level Rollup (UPB-weighted)
A2: Deal_ID is sourced from Loan_Snapshot column B. Edit there to regroup.
A4: Deal_ID | B4: n_loans | C4: total_UPB | D4: wavg_pred_CPR | E4: attr_refi_incentive_bps | F4: attr_in_prepay_penalty | G4: attr_loan_age_months | H4: attr_log_upb | I4: attr_is_post_covid | J4: attr_cum_itm | K4: attr_burn_ratio | L4: attr_is_hc_232 | M4: attr_is_223a7 | N4: attr_is_538 | O4: attr_lp_NC | P4: attr_iss_capital_funding | Q4: attr_iss_merchants | R4: attr_iss_wells_fargo | S4: attr_iss_walker_dunlop | T4: attr_iss_pnc | U4: attr_iss_berkadia | V4: attr_iss_dwight | W4: sanity_check
A5: LUMENT_PRE21 | B5: =COUNTIF(Loan_Snapshot!$B$5:$B$256,$A5) | C5: =SUMIF(Loan_Snapshot!$B$5:$B$256,$A5,Loan_Snapshot!$I$5:$I$256) | D5: =IFERROR(SUMPRODUCT((Loan_Snapshot!$B$5:$B$256=$A5)*Loan_Snapshot!$I$5:$I$256*Loan_Snapshot!$BG$5:$BG$256)/$C5,0) | E5: =IFERROR(SUMPRODUCT((Loan_Snapshot!$B$5:$B$256=$A5)*Loan_Snapshot!$I$5:$I$256*Loan_Snapshot!$BH$5:$BH$256)/$C5,0) | F5: =IFERROR(SUMPRODUCT((Loan_Snapshot!$B$5:$B$256=$A5)*Loan_Snapshot!$I$5:$I$256*Loan_Snapshot!$BI$5:$BI$256)/$C5,0) | G5: =IFERROR(SUMPRODUCT((Loan_Snapshot!$B$5:$B$256=$A5)*Loan_Snapshot!$I$5:$I$256*Loan_Snapshot!$BJ$5:$BJ$256)/$C5,0) | H5: =IFERROR(SUMPRODUCT((Loan_Snapshot!$B$5:$B$256=$A5)*Loan_Snapshot!$I$5:$I$256*Loan_Snapshot!$BK$5:$BK$256)/$C5,0) | I5: =IFERROR(SUMPRODUCT((Loan_Snapshot!$B$5:$B$256=$A5)*Loan_Snapshot!$I$5:$I$256*Loan_Snapshot!$BL$5:$BL$256)/$C5,0) | J5: =IFERROR(SUMPRODUCT((Loan_Snapshot!$B$5:$B$256=$A5)*Loan_Snapshot!$I$5:$I$256*Loan_Snapshot!$BM$5:$BM$256)/$C5,0) | K5: =IFERROR(SUMPRODUCT((Loan_Snapshot!$B$5:$B$256=$A5)*Loan_Snapshot!$I$5:$I$256*Loan_Snapshot!$BN$5:$BN$256)/$C5,0) | L5: =IFERROR(SUMPRODUCT((Loan_Snapshot!$B$5:$B$256=$A5)*Loan_Snapshot!$I$5:$I$256*Loan_Snapshot!$BO$5:$BO$256)/$C5,0) | M5: =IFERROR(SUMPRODUCT((Loan_Snapshot!$B$5:$B$256=$A5)*Loan_Snapshot!$I$5:$I$256*Loan_Snapshot!$BP$5:$BP$256)/$C5,0) | N5: =IFERROR(SUMPRODUCT((Loan_Snapshot!$B$5:$B$256=$A5)*Loan_Snapshot!$I$5:$I$256*Loan_Snapshot!$BQ$5:$BQ$256)/$C5,0) | O5: =IFERROR(SUMPRODUCT((Loan_Snapshot!$B$5:$B$256=$A5)*Loan_Snapshot!$I$5:$I$256*Loan_Snapshot!$BR$5:$BR$256)/$C5,0) | P5: =IFERROR(SUMPRODUCT((Loan_Snapshot!$B$5:$B$256=$A5)*Loan_Snapshot!$I$5:$I$256*Loan_Snapshot!$BS$5:$BS$256)/$C5,0) | Q5: =IFERROR(SUMPRODUCT((Loan_Snapshot!$B$5:$B$256=$A5)*Loan_Snapshot!$I$5:$I$256*Loan_Snapshot!$BT$5:$BT$256)/$C5,0) | R5: =IFERROR(SUMPRODUCT((Loan_Snapshot!$B$5:$B$256=$A5)*Loan_Snapshot!$I$5:$I$256*Loan_Snapshot!$BU$5:$BU$256)/$C5,0) | S5: =IFERROR(SUMPRODUCT((Loan_Snapshot!$B$5:$B$256=$A5)*Loan_Snapshot!$I$5:$I$256*Loan_Snapshot!$BV$5:$BV$256)/$C5,0) | T5: =IFERROR(SUMPRODUCT((Loan_Snapshot!$B$5:$B$256=$A5)*Loan_Snapshot!$I$5:$I$256*Loan_Snapshot!$BW$5:$BW$256)/$C5,0) | U5: =IFERROR(SUMPRODUCT((Loan_Snapshot!$B$5:$B$256=$A5)*Loan_Snapshot!$I$5:$I$256*Loan_Snapshot!$BX$5:$BX$256)/$C5,0) | V5: =IFERROR(SUMPRODUCT((Loan_Snapshot!$B$5:$B$256=$A5)*Loan_Snapshot!$I$5:$I$256*Loan_Snapshot!$BY$5:$BY$256)/$C5,0) | W5: =BASELINE_CPR+SUM(E5:V5)-$D5
A6: BERKADIA_PRE21 | B6: =COUNTIF(Loan_Snapshot!$B$5:$B$256,$A6) | C6: =SUMIF(Loan_Snapshot!$B$5:$B$256,$A6,Loan_Snapshot!$I$5:$I$256) | D6: =IFERROR(SUMPRODUCT((Loan_Snapshot!$B$5:$B$256=$A6)*Loan_Snapshot!$I$5:$I$256*Loan_Snapshot!$BG$5:$BG$256)/$C6,0) | E6: =IFERROR(SUMPRODUCT((Loan_Snapshot!$B$5:$B$256=$A6)*Loan_Snapshot!$I$5:$I$256*Loan_Snapshot!$BH$5:$BH$256)/$C6,0) | F6: =IFERROR(SUMPRODUCT((Loan_Snapshot!$B$5:$B$256=$A6)*Loan_Snapshot!$I$5:$I$256*Loan_Snapshot!$BI$5:$BI$256)/$C6,0) | G6: =IFERROR(SUMPRODUCT((Loan_Snapshot!$B$5:$B$256=$A6)*Loan_Snapshot!$I$5:$I$256*Loan_Snapshot!$BJ$5:$BJ$256)/$C6,0) | H6: =IFERROR(SUMPRODUCT((Loan_Snapshot!$B$5:$B$256=$A6)*Loan_Snapshot!$I$5:$I$256*Loan_Snapshot!$BK$5:$BK$256)/$C6,0) | I6: =IFERROR(SUMPRODUCT((Loan_Snapshot!$B$5:$B$256=$A6)*Loan_Snapshot!$I$5:$I$256*Loan_Snapshot!$BL$5:$BL$256)/$C6,0) | J6: =IFERROR(SUMPRODUCT((Loan_Snapshot!$B$5:$B$256=$A6)*Loan_Snapshot!$I$5:$I$256*Loan_Snapshot!$BM$5:$BM$256)/$C6,0) | K6: =IFERROR(SUMPRODUCT((Loan_Snapshot!$B$5:$B$256=$A6)*Loan_Snapshot!$I$5:$I$256*Loan_Snapshot!$BN$5:$BN$256)/$C6,0) | L6: =IFERROR(SUMPRODUCT((Loan_Snapshot!$B$5:$B$256=$A6)*Loan_Snapshot!$I$5:$I$256*Loan_Snapshot!$BO$5:$BO$256)/$C6,0) | M6: =IFERROR(SUMPRODUCT((Loan_Snapshot!$B$5:$B$256=$A6)*Loan_Snapshot!$I$5:$I$256*Loan_Snapshot!$BP$5:$BP$256)/$C6,0) | N6: =IFERROR(SUMPRODUCT((Loan_Snapshot!$B$5:$B$256=$A6)*Loan_Snapshot!$I$5:$I$256*Loan_Snapshot!$BQ$5:$BQ$256)/$C6,0) | O6: =IFERROR(SUMPRODUCT((Loan_Snapshot!$B$5:$B$256=$A6)*Loan_Snapshot!$I$5:$I$256*Loan_Snapshot!$BR$5:$BR$256)/$C6,0) | P6: =IFERROR(SUMPRODUCT((Loan_Snapshot!$B$5:$B$256=$A6)*Loan_Snapshot!$I$5:$I$256*Loan_Snapshot!$BS$5:$BS$256)/$C6,0) | Q6: =IFERROR(SUMPRODUCT((Loan_Snapshot!$B$5:$B$256=$A6)*Loan_Snapshot!$I$5:$I$256*Loan_Snapshot!$BT$5:$BT$256)/$C6,0) | R6: =IFERROR(SUMPRODUCT((Loan_Snapshot!$B$5:$B$256=$A6)*Loan_Snapshot!$I$5:$I$256*Loan_Snapshot!$BU$5:$BU$256)/$C6,0) | S6: =IFERROR(SUMPRODUCT((Loan_Snapshot!$B$5:$B$256=$A6)*Loan_Snapshot!$I$5:$I$256*Loan_Snapshot!$BV$5:$BV$256)/$C6,0) | T6: =IFERROR(SUMPRODUCT((Loan_Snapshot!$B$5:$B$256=$A6)*Loan_Snapshot!$I$5:$I$256*Loan_Snapshot!$BW$5:$BW$256)/$C6,0) | U6: =IFERROR(SUMPRODUCT((Loan_Snapshot!$B$5:$B$256=$A6)*Loan_Snapshot!$I$5:$I$256*Loan_Snapshot!$BX$5:$BX$256)/$C6,0) | V6: =IFERROR(SUMPRODUCT((Loan_Snapshot!$B$5:$B$256=$A6)*Loan_Snapshot!$I$5:$I$256*Loan_Snapshot!$BY$5:$BY$256)/$C6,0) | W6: =BASELINE_CPR+SUM(E6:V6)-$D6
A7: PNC_PRE21 | B7: =COUNTIF(Loan_Snapshot!$B$5:$B$256,$A7) | C7: =SUMIF(Loan_Snapshot!$B$5:$B$256,$A7,Loan_Snapshot!$I$5:$I$256) | D7: =IFERROR(SUMPRODUCT((Loan_Snapshot!$B$5:$B$256=$A7)*Loan_Snapshot!$I$5:$I$256*Loan_Snapshot!$BG$5:$BG$256)/$C7,0) | E7: =IFERROR(SUMPRODUCT((Loan_Snapshot!$B$5:$B$256=$A7)*Loan_Snapshot!$I$5:$I$256*Loan_Snapshot!$BH$5:$BH$256)/$C7,0) | F7: =IFERROR(SUMPRODUCT((Loan_Snapshot!$B$5:$B$256=$A7)*Loan_Snapshot!$I$5:$I$256*Loan_Snapshot!$BI$5:$BI$256)/$C7,0) | G7: =IFERROR(SUMPRODUCT((Loan_Snapshot!$B$5:$B$256=$A7)*Loan_Snapshot!$I$5:$I$256*Loan_Snapshot!$BJ$5:$BJ$256)/$C7,0) | H7: =IFERROR(SUMPRODUCT((Loan_Snapshot!$B$5:$B$256=$A7)*Loan_Snapshot!$I$5:$I$256*Loan_Snapshot!$BK$5:$BK$256)/$C7,0) | I7: =IFERROR(SUMPRODUCT((Loan_Snapshot!$B$5:$B$256=$A7)*Loan_Snapshot!$I$5:$I$256*Loan_Snapshot!$BL$5:$BL$256)/$C7,0) | J7: =IFERROR(SUMPRODUCT((Loan_Snapshot!$B$5:$B$256=$A7)*Loan_Snapshot!$I$5:$I$256*Loan_Snapshot!$BM$5:$BM$256)/$C7,0) | K7: =IFERROR(SUMPRODUCT((Loan_Snapshot!$B$5:$B$256=$A7)*Loan_Snapshot!$I$5:$I$256*Loan_Snapshot!$BN$5:$BN$256)/$C7,0) | L7: =IFERROR(SUMPRODUCT((Loan_Snapshot!$B$5:$B$256=$A7)*Loan_Snapshot!$I$5:$I$256*Loan_Snapshot!$BO$5:$BO$256)/$C7,0) | M7: =IFERROR(SUMPRODUCT((Loan_Snapshot!$B$5:$B$256=$A7)*Loan_Snapshot!$I$5:$I$256*Loan_Snapshot!$BP$5:$BP$256)/$C7,0) | N7: =IFERROR(SUMPRODUCT((Loan_Snapshot!$B$5:$B$256=$A7)*Loan_Snapshot!$I$5:$I$256*Loan_Snapshot!$BQ$5:$BQ$256)/$C7,0) | O7: =IFERROR(SUMPRODUCT((Loan_Snapshot!$B$5:$B$256=$A7)*Loan_Snapshot!$I$5:$I$256*Loan_Snapshot!$BR$5:$BR$256)/$C7,0) | P7: =IFERROR(SUMPRODUCT((Loan_Snapshot!$B$5:$B$256=$A7)*Loan_Snapshot!$I$5:$I$256*Loan_Snapshot!$BS$5:$BS$256)/$C7,0) | Q7: =IFERROR(SUMPRODUCT((Loan_Snapshot!$B$5:$B$256=$A7)*Loan_Snapshot!$I$5:$I$256*Loan_Snapshot!$BT$5:$BT$256)/$C7,0) | R7: =IFERROR(SUMPRODUCT((Loan_Snapshot!$B$5:$B$256=$A7)*Loan_Snapshot!$I$5:$I$256*Loan_Snapshot!$BU$5:$BU$256)/$C7,0) | S7: =IFERROR(SUMPRODUCT((Loan_Snapshot!$B$5:$B$256=$A7)*Loan_Snapshot!$I$5:$I$256*Loan_Snapshot!$BV$5:$BV$256)/$C7,0) | T7: =IFERROR(SUMPRODUCT((Loan_Snapshot!$B$5:$B$256=$A7)*Loan_Snapshot!$I$5:$I$256*Loan_Snapshot!$BW$5:$BW$256)/$C7,0) | U7: =IFERROR(SUMPRODUCT((Loan_Snapshot!$B$5:$B$256=$A7)*Loan_Snapshot!$I$5:$I$256*Loan_Snapshot!$BX$5:$BX$256)/$C7,0) | V7: =IFERROR(SUMPRODUCT((Loan_Snapshot!$B$5:$B$256=$A7)*Loan_Snapshot!$I$5:$I$256*Loan_Snapshot!$BY$5:$BY$256)/$C7,0) | W7: =BASELINE_CPR+SUM(E7:V7)-$D7
A8: WALKER_PRE21 | B8: =COUNTIF(Loan_Snapshot!$B$5:$B$256,$A8) | C8: =SUMIF(Loan_Snapshot!$B$5:$B$256,$A8,Loan_Snapshot!$I$5:$I$256) | D8: =IFERROR(SUMPRODUCT((Loan_Snapshot!$B$5:$B$256=$A8)*Loan_Snapshot!$I$5:$I$256*Loan_Snapshot!$BG$5:$BG$256)/$C8,0) | E8: =IFERROR(SUMPRODUCT((Loan_Snapshot!$B$5:$B$256=$A8)*Loan_Snapshot!$I$5:$I$256*Loan_Snapshot!$BH$5:$BH$256)/$C8,0) | F8: =IFERROR(SUMPRODUCT((Loan_Snapshot!$B$5:$B$256=$A8)*Loan_Snapshot!$I$5:$I$256*Loan_Snapshot!$BI$5:$BI$256)/$C8,0) | G8: =IFERROR(SUMPRODUCT((Loan_Snapshot!$B$5:$B$256=$A8)*Loan_Snapshot!$I$5:$I$256*Loan_Snapshot!$BJ$5:$BJ$256)/$C8,0) | H8: =IFERROR(SUMPRODUCT((Loan_Snapshot!$B$5:$B$256=$A8)*Loan_Snapshot!$I$5:$I$256*Loan_Snapshot!$BK$5:$BK$256)/$C8,0) | I8: =IFERROR(SUMPRODUCT((Loan_Snapshot!$B$5:$B$256=$A8)*Loan_Snapshot!$I$5:$I$256*Loan_Snapshot!$BL$5:$BL$256)/$C8,0) | J8: =IFERROR(SUMPRODUCT((Loan_Snapshot!$B$5:$B$256=$A8)*Loan_Snapshot!$I$5:$I$256*Loan_Snapshot!$BM$5:$BM$256)/$C8,0) | K8: =IFERROR(SUMPRODUCT((Loan_Snapshot!$B$5:$B$256=$A8)*Loan_Snapshot!$I$5:$I$256*Loan_Snapshot!$BN$5:$BN$256)/$C8,0) | L8: =IFERROR(SUMPRODUCT((Loan_Snapshot!$B$5:$B$256=$A8)*Loan_Snapshot!$I$5:$I$256*Loan_Snapshot!$BO$5:$BO$256)/$C8,0) | M8: =IFERROR(SUMPRODUCT((Loan_Snapshot!$B$5:$B$256=$A8)*Loan_Snapshot!$I$5:$I$256*Loan_Snapshot!$BP$5:$BP$256)/$C8,0) | N8: =IFERROR(SUMPRODUCT((Loan_Snapshot!$B$5:$B$256=$A8)*Loan_Snapshot!$I$5:$I$256*Loan_Snapshot!$BQ$5:$BQ$256)/$C8,0) | O8: =IFERROR(SUMPRODUCT((Loan_Snapshot!$B$5:$B$256=$A8)*Loan_Snapshot!$I$5:$I$256*Loan_Snapshot!$BR$5:$BR$256)/$C8,0) | P8: =IFERROR(SUMPRODUCT((Loan_Snapshot!$B$5:$B$256=$A8)*Loan_Snapshot!$I$5:$I$256*Loan_Snapshot!$BS$5:$BS$256)/$C8,0) | Q8: =IFERROR(SUMPRODUCT((Loan_Snapshot!$B$5:$B$256=$A8)*Loan_Snapshot!$I$5:$I$256*Loan_Snapshot!$BT$5:$BT$256)/$C8,0) | R8: =IFERROR(SUMPRODUCT((Loan_Snapshot!$B$5:$B$256=$A8)*Loan_Snapshot!$I$5:$I$256*Loan_Snapshot!$BU$5:$BU$256)/$C8,0) | S8: =IFERROR(SUMPRODUCT((Loan_Snapshot!$B$5:$B$256=$A8)*Loan_Snapshot!$I$5:$I$256*Loan_Snapshot!$BV$5:$BV$256)/$C8,0) | T8: =IFERROR(SUMPRODUCT((Loan_Snapshot!$B$5:$B$256=$A8)*Loan_Snapshot!$I$5:$I$256*Loan_Snapshot!$BW$5:$BW$256)/$C8,0) | U8: =IFERROR(SUMPRODUCT((Loan_Snapshot!$B$5:$B$256=$A8)*Loan_Snapshot!$I$5:$I$256*Loan_Snapshot!$BX$5:$BX$256)/$C8,0) | V8: =IFERROR(SUMPRODUCT((Loan_Snapshot!$B$5:$B$256=$A8)*Loan_Snapshot!$I$5:$I$256*Loan_Snapshot!$BY$5:$BY$256)/$C8,0) | W8: =BASELINE_CPR+SUM(E8:V8)-$D8
A9: WELLS_PRE21 | B9: =COUNTIF(Loan_Snapshot!$B$5:$B$256,$A9) | C9: =SUMIF(Loan_Snapshot!$B$5:$B$256,$A9,Loan_Snapshot!$I$5:$I$256) | D9: =IFERROR(SUMPRODUCT((Loan_Snapshot!$B$5:$B$256=$A9)*Loan_Snapshot!$I$5:$I$256*Loan_Snapshot!$BG$5:$BG$256)/$C9,0) | E9: =IFERROR(SUMPRODUCT((Loan_Snapshot!$B$5:$B$256=$A9)*Loan_Snapshot!$I$5:$I$256*Loan_Snapshot!$BH$5:$BH$256)/$C9,0) | F9: =IFERROR(SUMPRODUCT((Loan_Snapshot!$B$5:$B$256=$A9)*Loan_Snapshot!$I$5:$I$256*Loan_Snapshot!$BI$5:$BI$256)/$C9,0) | G9: =IFERROR(SUMPRODUCT((Loan_Snapshot!$B$5:$B$256=$A9)*Loan_Snapshot!$I$5:$I$256*Loan_Snapshot!$BJ$5:$BJ$256)/$C9,0) | H9: =IFERROR(SUMPRODUCT((Loan_Snapshot!$B$5:$B$256=$A9)*Loan_Snapshot!$I$5:$I$256*Loan_Snapshot!$BK$5:$BK$256)/$C9,0) | I9: =IFERROR(SUMPRODUCT((Loan_Snapshot!$B$5:$B$256=$A9)*Loan_Snapshot!$I$5:$I$256*Loan_Snapshot!$BL$5:$BL$256)/$C9,0) | J9: =IFERROR(SUMPRODUCT((Loan_Snapshot!$B$5:$B$256=$A9)*Loan_Snapshot!$I$5:$I$256*Loan_Snapshot!$BM$5:$BM$256)/$C9,0) | K9: =IFERROR(SUMPRODUCT((Loan_Snapshot!$B$5:$B$256=$A9)*Loan_Snapshot!$I$5:$I$256*Loan_Snapshot!$BN$5:$BN$256)/$C9,0) | L9: =IFERROR(SUMPRODUCT((Loan_Snapshot!$B$5:$B$256=$A9)*Loan_Snapshot!$I$5:$I$256*Loan_Snapshot!$BO$5:$BO$256)/$C9,0) | M9: =IFERROR(SUMPRODUCT((Loan_Snapshot!$B$5:$B$256=$A9)*Loan_Snapshot!$I$5:$I$256*Loan_Snapshot!$BP$5:$BP$256)/$C9,0) | N9: =IFERROR(SUMPRODUCT((Loan_Snapshot!$B$5:$B$256=$A9)*Loan_Snapshot!$I$5:$I$256*Loan_Snapshot!$BQ$5:$BQ$256)/$C9,0) | O9: =IFERROR(SUMPRODUCT((Loan_Snapshot!$B$5:$B$256=$A9)*Loan_Snapshot!$I$5:$I$256*Loan_Snapshot!$BR$5:$BR$256)/$C9,0) | P9: =IFERROR(SUMPRODUCT((Loan_Snapshot!$B$5:$B$256=$A9)*Loan_Snapshot!$I$5:$I$256*Loan_Snapshot!$BS$5:$BS$256)/$C9,0) | Q9: =IFERROR(SUMPRODUCT((Loan_Snapshot!$B$5:$B$256=$A9)*Loan_Snapshot!$I$5:$I$256*Loan_Snapshot!$BT$5:$BT$256)/$C9,0) | R9: =IFERROR(SUMPRODUCT((Loan_Snapshot!$B$5:$B$256=$A9)*Loan_Snapshot!$I$5:$I$256*Loan_Snapshot!$BU$5:$BU$256)/$C9,0) | S9: =IFERROR(SUMPRODUCT((Loan_Snapshot!$B$5:$B$256=$A9)*Loan_Snapshot!$I$5:$I$256*Loan_Snapshot!$BV$5:$BV$256)/$C9,0) | T9: =IFERROR(SUMPRODUCT((Loan_Snapshot!$B$5:$B$256=$A9)*Loan_Snapshot!$I$5:$I$256*Loan_Snapshot!$BW$5:$BW$256)/$C9,0) | U9: =IFERROR(SUMPRODUCT((Loan_Snapshot!$B$5:$B$256=$A9)*Loan_Snapshot!$I$5:$I$256*Loan_Snapshot!$BX$5:$BX$256)/$C9,0) | V9: =IFERROR(SUMPRODUCT((Loan_Snapshot!$B$5:$B$256=$A9)*Loan_Snapshot!$I$5:$I$256*Loan_Snapshot!$BY$5:$BY$256)/$C9,0) | W9: =BASELINE_CPR+SUM(E9:V9)-$D9
A10: GREYSTONE_POST21 | B10: =COUNTIF(Loan_Snapshot!$B$5:$B$256,$A10) | C10: =SUMIF(Loan_Snapshot!$B$5:$B$256,$A10,Loan_Snapshot!$I$5:$I$256) | D10: =IFERROR(SUMPRODUCT((Loan_Snapshot!$B$5:$B$256=$A10)*Loan_Snapshot!$I$5:$I$256*Loan_Snapshot!$BG$5:$BG$256)/$C10,0) | E10: =IFERROR(SUMPRODUCT((Loan_Snapshot!$B$5:$B$256=$A10)*Loan_Snapshot!$I$5:$I$256*Loan_Snapshot!$BH$5:$BH$256)/$C10,0) | F10: =IFERROR(SUMPRODUCT((Loan_Snapshot!$B$5:$B$256=$A10)*Loan_Snapshot!$I$5:$I$256*Loan_Snapshot!$BI$5:$BI$256)/$C10,0) | G10: =IFERROR(SUMPRODUCT((Loan_Snapshot!$B$5:$B$256=$A10)*Loan_Snapshot!$I$5:$I$256*Loan_Snapshot!$BJ$5:$BJ$256)/$C10,0) | H10: =IFERROR(SUMPRODUCT((Loan_Snapshot!$B$5:$B$256=$A10)*Loan_Snapshot!$I$5:$I$256*Loan_Snapshot!$BK$5:$BK$256)/$C10,0) | I10: =IFERROR(SUMPRODUCT((Loan_Snapshot!$B$5:$B$256=$A10)*Loan_Snapshot!$I$5:$I$256*Loan_Snapshot!$BL$5:$BL$256)/$C10,0) | J10: =IFERROR(SUMPRODUCT((Loan_Snapshot!$B$5:$B$256=$A10)*Loan_Snapshot!$I$5:$I$256*Loan_Snapshot!$BM$5:$BM$256)/$C10,0) | K10: =IFERROR(SUMPRODUCT((Loan_Snapshot!$B$5:$B$256=$A10)*Loan_Snapshot!$I$5:$I$256*Loan_Snapshot!$BN$5:$BN$256)/$C10,0) | L10: =IFERROR(SUMPRODUCT((Loan_Snapshot!$B$5:$B$256=$A10)*Loan_Snapshot!$I$5:$I$256*Loan_Snapshot!$BO$5:$BO$256)/$C10,0) | M10: =IFERROR(SUMPRODUCT((Loan_Snapshot!$B$5:$B$256=$A10)*Loan_Snapshot!$I$5:$I$256*Loan_Snapshot!$BP$5:$BP$256)/$C10,0) | N10: =IFERROR(SUMPRODUCT((Loan_Snapshot!$B$5:$B$256=$A10)*Loan_Snapshot!$I$5:$I$256*Loan_Snapshot!$BQ$5:$BQ$256)/$C10,0) | O10: =IFERROR(SUMPRODUCT((Loan_Snapshot!$B$5:$B$256=$A10)*Loan_Snapshot!$I$5:$I$256*Loan_Snapshot!$BR$5:$BR$256)/$C10,0) | P10: =IFERROR(SUMPRODUCT((Loan_Snapshot!$B$5:$B$256=$A10)*Loan_Snapshot!$I$5:$I$256*Loan_Snapshot!$BS$5:$BS$256)/$C10,0) | Q10: =IFERROR(SUMPRODUCT((Loan_Snapshot!$B$5:$B$256=$A10)*Loan_Snapshot!$I$5:$I$256*Loan_Snapshot!$BT$5:$BT$256)/$C10,0) | R10: =IFERROR(SUMPRODUCT((Loan_Snapshot!$B$5:$B$256=$A10)*Loan_Snapshot!$I$5:$I$256*Loan_Snapshot!$BU$5:$BU$256)/$C10,0) | S10: =IFERROR(SUMPRODUCT((Loan_Snapshot!$B$5:$B$256=$A10)*Loan_Snapshot!$I$5:$I$256*Loan_Snapshot!$BV$5:$BV$256)/$C10,0) | T10: =IFERROR(SUMPRODUCT((Loan_Snapshot!$B$5:$B$256=$A10)*Loan_Snapshot!$I$5:$I$256*Loan_Snapshot!$BW$5:$BW$256)/$C10,0) | U10: =IFERROR(SUMPRODUCT((Loan_Snapshot!$B$5:$B$256=$A10)*Loan_Snapshot!$I$5:$I$256*Loan_Snapshot!$BX$5:$BX$256)/$C10,0) | V10: =IFERROR(SUMPRODUCT((Loan_Snapshot!$B$5:$B$256=$A10)*Loan_Snapshot!$I$5:$I$256*Loan_Snapshot!$BY$5:$BY$256)/$C10,0) | W10: =BASELINE_CPR+SUM(E10:V10)-$D10
A11: CAPITAL_PRE21 | B11: =COUNTIF(Loan_Snapshot!$B$5:$B$256,$A11) | C11: =SUMIF(Loan_Snapshot!$B$5:$B$256,$A11,Loan_Snapshot!$I$5:$I$256) | D11: =IFERROR(SUMPRODUCT((Loan_Snapshot!$B$5:$B$256=$A11)*Loan_Snapshot!$I$5:$I$256*Loan_Snapshot!$BG$5:$BG$256)/$C11,0) | E11: =IFERROR(SUMPRODUCT((Loan_Snapshot!$B$5:$B$256=$A11)*Loan_Snapshot!$I$5:$I$256*Loan_Snapshot!$BH$5:$BH$256)/$C11,0) | F11: =IFERROR(SUMPRODUCT((Loan_Snapshot!$B$5:$B$256=$A11)*Loan_Snapshot!$I$5:$I$256*Loan_Snapshot!$BI$5:$BI$256)/$C11,0) | G11: =IFERROR(SUMPRODUCT((Loan_Snapshot!$B$5:$B$256=$A11)*Loan_Snapshot!$I$5:$I$256*Loan_Snapshot!$BJ$5:$BJ$256)/$C11,0) | H11: =IFERROR(SUMPRODUCT((Loan_Snapshot!$B$5:$B$256=$A11)*Loan_Snapshot!$I$5:$I$256*Loan_Snapshot!$BK$5:$BK$256)/$C11,0) | I11: =IFERROR(SUMPRODUCT((Loan_Snapshot!$B$5:$B$256=$A11)*Loan_Snapshot!$I$5:$I$256*Loan_Snapshot!$BL$5:$BL$256)/$C11,0) | J11: =IFERROR(SUMPRODUCT((Loan_Snapshot!$B$5:$B$256=$A11)*Loan_Snapshot!$I$5:$I$256*Loan_Snapshot!$BM$5:$BM$256)/$C11,0) | K11: =IFERROR(SUMPRODUCT((Loan_Snapshot!$B$5:$B$256=$A11)*Loan_Snapshot!$I$5:$I$256*Loan_Snapshot!$BN$5:$BN$256)/$C11,0) | L11: =IFERROR(SUMPRODUCT((Loan_Snapshot!$B$5:$B$256=$A11)*Loan_Snapshot!$I$5:$I$256*Loan_Snapshot!$BO$5:$BO$256)/$C11,0) | M11: =IFERROR(SUMPRODUCT((Loan_Snapshot!$B$5:$B$256=$A11)*Loan_Snapshot!$I$5:$I$256*Loan_Snapshot!$BP$5:$BP$256)/$C11,0) | N11: =IFERROR(SUMPRODUCT((Loan_Snapshot!$B$5:$B$256=$A11)*Loan_Snapshot!$I$5:$I$256*Loan_Snapshot!$BQ$5:$BQ$256)/$C11,0) | O11: =IFERROR(SUMPRODUCT((Loan_Snapshot!$B$5:$B$256=$A11)*Loan_Snapshot!$I$5:$I$256*Loan_Snapshot!$BR$5:$BR$256)/$C11,0) | P11: =IFERROR(SUMPRODUCT((Loan_Snapshot!$B$5:$B$256=$A11)*Loan_Snapshot!$I$5:$I$256*Loan_Snapshot!$BS$5:$BS$256)/$C11,0) | Q11: =IFERROR(SUMPRODUCT((Loan_Snapshot!$B$5:$B$256=$A11)*Loan_Snapshot!$I$5:$I$256*Loan_Snapshot!$BT$5:$BT$256)/$C11,0) | R11: =IFERROR(SUMPRODUCT((Loan_Snapshot!$B$5:$B$256=$A11)*Loan_Snapshot!$I$5:$I$256*Loan_Snapshot!$BU$5:$BU$256)/$C11,0) | S11: =IFERROR(SUMPRODUCT((Loan_Snapshot!$B$5:$B$256=$A11)*Loan_Snapshot!$I$5:$I$256*Loan_Snapshot!$BV$5:$BV$256)/$C11,0) | T11: =IFERROR(SUMPRODUCT((Loan_Snapshot!$B$5:$B$256=$A11)*Loan_Snapshot!$I$5:$I$256*Loan_Snapshot!$BW$5:$BW$256)/$C11,0) | U11: =IFERROR(SUMPRODUCT((Loan_Snapshot!$B$5:$B$256=$A11)*Loan_Snapshot!$I$5:$I$256*Loan_Snapshot!$BX$5:$BX$256)/$C11,0) | V11: =IFERROR(SUMPRODUCT((Loan_Snapshot!$B$5:$B$256=$A11)*Loan_Snapshot!$I$5:$I$256*Loan_Snapshot!$BY$5:$BY$256)/$C11,0) | W11: =BASELINE_CPR+SUM(E11:V11)-$D11
A12: MERCHANTS_PRE21 | B12: =COUNTIF(Loan_Snapshot!$B$5:$B$256,$A12) | C12: =SUMIF(Loan_Snapshot!$B$5:$B$256,$A12,Loan_Snapshot!$I$5:$I$256) | D12: =IFERROR(SUMPRODUCT((Loan_Snapshot!$B$5:$B$256=$A12)*Loan_Snapshot!$I$5:$I$256*Loan_Snapshot!$BG$5:$BG$256)/$C12,0) | E12: =IFERROR(SUMPRODUCT((Loan_Snapshot!$B$5:$B$256=$A12)*Loan_Snapshot!$I$5:$I$256*Loan_Snapshot!$BH$5:$BH$256)/$C12,0) | F12: =IFERROR(SUMPRODUCT((Loan_Snapshot!$B$5:$B$256=$A12)*Loan_Snapshot!$I$5:$I$256*Loan_Snapshot!$BI$5:$BI$256)/$C12,0) | G12: =IFERROR(SUMPRODUCT((Loan_Snapshot!$B$5:$B$256=$A12)*Loan_Snapshot!$I$5:$I$256*Loan_Snapshot!$BJ$5:$BJ$256)/$C12,0) | H12: =IFERROR(SUMPRODUCT((Loan_Snapshot!$B$5:$B$256=$A12)*Loan_Snapshot!$I$5:$I$256*Loan_Snapshot!$BK$5:$BK$256)/$C12,0) | I12: =IFERROR(SUMPRODUCT((Loan_Snapshot!$B$5:$B$256=$A12)*Loan_Snapshot!$I$5:$I$256*Loan_Snapshot!$BL$5:$BL$256)/$C12,0) | J12: =IFERROR(SUMPRODUCT((Loan_Snapshot!$B$5:$B$256=$A12)*Loan_Snapshot!$I$5:$I$256*Loan_Snapshot!$BM$5:$BM$256)/$C12,0) | K12: =IFERROR(SUMPRODUCT((Loan_Snapshot!$B$5:$B$256=$A12)*Loan_Snapshot!$I$5:$I$256*Loan_Snapshot!$BN$5:$BN$256)/$C12,0) | L12: =IFERROR(SUMPRODUCT((Loan_Snapshot!$B$5:$B$256=$A12)*Loan_Snapshot!$I$5:$I$256*Loan_Snapshot!$BO$5:$BO$256)/$C12,0) | M12: =IFERROR(SUMPRODUCT((Loan_Snapshot!$B$5:$B$256=$A12)*Loan_Snapshot!$I$5:$I$256*Loan_Snapshot!$BP$5:$BP$256)/$C12,0) | N12: =IFERROR(SUMPRODUCT((Loan_Snapshot!$B$5:$B$256=$A12)*Loan_Snapshot!$I$5:$I$256*Loan_Snapshot!$BQ$5:$BQ$256)/$C12,0) | O12: =IFERROR(SUMPRODUCT((Loan_Snapshot!$B$5:$B$256=$A12)*Loan_Snapshot!$I$5:$I$256*Loan_Snapshot!$BR$5:$BR$256)/$C12,0) | P12: =IFERROR(SUMPRODUCT((Loan_Snapshot!$B$5:$B$256=$A12)*Loan_Snapshot!$I$5:$I$256*Loan_Snapshot!$BS$5:$BS$256)/$C12,0) | Q12: =IFERROR(SUMPRODUCT((Loan_Snapshot!$B$5:$B$256=$A12)*Loan_Snapshot!$I$5:$I$256*Loan_Snapshot!$BT$5:$BT$256)/$C12,0) | R12: =IFERROR(SUMPRODUCT((Loan_Snapshot!$B$5:$B$256=$A12)*Loan_Snapshot!$I$5:$I$256*Loan_Snapshot!$BU$5:$BU$256)/$C12,0) | S12: =IFERROR(SUMPRODUCT((Loan_Snapshot!$B$5:$B$256=$A12)*Loan_Snapshot!$I$5:$I$256*Loan_Snapshot!$BV$5:$BV$256)/$C12,0) | T12: =IFERROR(SUMPRODUCT((Loan_Snapshot!$B$5:$B$256=$A12)*Loan_Snapshot!$I$5:$I$256*Loan_Snapshot!$BW$5:$BW$256)/$C12,0) | U12: =IFERROR(SUMPRODUCT((Loan_Snapshot!$B$5:$B$256=$A12)*Loan_Snapshot!$I$5:$I$256*Loan_Snapshot!$BX$5:$BX$256)/$C12,0) | V12: =IFERROR(SUMPRODUCT((Loan_Snapshot!$B$5:$B$256=$A12)*Loan_Snapshot!$I$5:$I$256*Loan_Snapshot!$BY$5:$BY$256)/$C12,0) | W12: =BASELINE_CPR+SUM(E12:V12)-$D12
A13: KEYBANK_PRE21 | B13: =COUNTIF(Loan_Snapshot!$B$5:$B$256,$A13) | C13: =SUMIF(Loan_Snapshot!$B$5:$B$256,$A13,Loan_Snapshot!$I$5:$I$256) | D13: =IFERROR(SUMPRODUCT((Loan_Snapshot!$B$5:$B$256=$A13)*Loan_Snapshot!$I$5:$I$256*Loan_Snapshot!$BG$5:$BG$256)/$C13,0) | E13: =IFERROR(SUMPRODUCT((Loan_Snapshot!$B$5:$B$256=$A13)*Loan_Snapshot!$I$5:$I$256*Loan_Snapshot!$BH$5:$BH$256)/$C13,0) | F13: =IFERROR(SUMPRODUCT((Loan_Snapshot!$B$5:$B$256=$A13)*Loan_Snapshot!$I$5:$I$256*Loan_Snapshot!$BI$5:$BI$256)/$C13,0) | G13: =IFERROR(SUMPRODUCT((Loan_Snapshot!$B$5:$B$256=$A13)*Loan_Snapshot!$I$5:$I$256*Loan_Snapshot!$BJ$5:$BJ$256)/$C13,0) | H13: =IFERROR(SUMPRODUCT((Loan_Snapshot!$B$5:$B$256=$A13)*Loan_Snapshot!$I$5:$I$256*Loan_Snapshot!$BK$5:$BK$256)/$C13,0) | I13: =IFERROR(SUMPRODUCT((Loan_Snapshot!$B$5:$B$256=$A13)*Loan_Snapshot!$I$5:$I$256*Loan_Snapshot!$BL$5:$BL$256)/$C13,0) | J13: =IFERROR(SUMPRODUCT((Loan_Snapshot!$B$5:$B$256=$A13)*Loan_Snapshot!$I$5:$I$256*Loan_Snapshot!$BM$5:$BM$256)/$C13,0) | K13: =IFERROR(SUMPRODUCT((Loan_Snapshot!$B$5:$B$256=$A13)*Loan_Snapshot!$I$5:$I$256*Loan_Snapshot!$BN$5:$BN$256)/$C13,0) | L13: =IFERROR(SUMPRODUCT((Loan_Snapshot!$B$5:$B$256=$A13)*Loan_Snapshot!$I$5:$I$256*Loan_Snapshot!$BO$5:$BO$256)/$C13,0) | M13: =IFERROR(SUMPRODUCT((Loan_Snapshot!$B$5:$B$256=$A13)*Loan_Snapshot!$I$5:$I$256*Loan_Snapshot!$BP$5:$BP$256)/$C13,0) | N13: =IFERROR(SUMPRODUCT((Loan_Snapshot!$B$5:$B$256=$A13)*Loan_Snapshot!$I$5:$I$256*Loan_Snapshot!$BQ$5:$BQ$256)/$C13,0) | O13: =IFERROR(SUMPRODUCT((Loan_Snapshot!$B$5:$B$256=$A13)*Loan_Snapshot!$I$5:$I$256*Loan_Snapshot!$BR$5:$BR$256)/$C13,0) | P13: =IFERROR(SUMPRODUCT((Loan_Snapshot!$B$5:$B$256=$A13)*Loan_Snapshot!$I$5:$I$256*Loan_Snapshot!$BS$5:$BS$256)/$C13,0) | Q13: =IFERROR(SUMPRODUCT((Loan_Snapshot!$B$5:$B$256=$A13)*Loan_Snapshot!$I$5:$I$256*Loan_Snapshot!$BT$5:$BT$256)/$C13,0) | R13: =IFERROR(SUMPRODUCT((Loan_Snapshot!$B$5:$B$256=$A13)*Loan_Snapshot!$I$5:$I$256*Loan_Snapshot!$BU$5:$BU$256)/$C13,0) | S13: =IFERROR(SUMPRODUCT((Loan_Snapshot!$B$5:$B$256=$A13)*Loan_Snapshot!$I$5:$I$256*Loan_Snapshot!$BV$5:$BV$256)/$C13,0) | T13: =IFERROR(SUMPRODUCT((Loan_Snapshot!$B$5:$B$256=$A13)*Loan_Snapshot!$I$5:$I$256*Loan_Snapshot!$BW$5:$BW$256)/$C13,0) | U13: =IFERROR(SUMPRODUCT((Loan_Snapshot!$B$5:$B$256=$A13)*Loan_Snapshot!$I$5:$I$256*Loan_Snapshot!$BX$5:$BX$256)/$C13,0) | V13: =IFERROR(SUMPRODUCT((Loan_Snapshot!$B$5:$B$256=$A13)*Loan_Snapshot!$I$5:$I$256*Loan_Snapshot!$BY$5:$BY$256)/$C13,0) | W13: =BASELINE_CPR+SUM(E13:V13)-$D13
A14: LUMENT_POST21 | B14: =COUNTIF(Loan_Snapshot!$B$5:$B$256,$A14) | C14: =SUMIF(Loan_Snapshot!$B$5:$B$256,$A14,Loan_Snapshot!$I$5:$I$256) | D14: =IFERROR(SUMPRODUCT((Loan_Snapshot!$B$5:$B$256=$A14)*Loan_Snapshot!$I$5:$I$256*Loan_Snapshot!$BG$5:$BG$256)/$C14,0) | E14: =IFERROR(SUMPRODUCT((Loan_Snapshot!$B$5:$B$256=$A14)*Loan_Snapshot!$I$5:$I$256*Loan_Snapshot!$BH$5:$BH$256)/$C14,0) | F14: =IFERROR(SUMPRODUCT((Loan_Snapshot!$B$5:$B$256=$A14)*Loan_Snapshot!$I$5:$I$256*Loan_Snapshot!$BI$5:$BI$256)/$C14,0) | G14: =IFERROR(SUMPRODUCT((Loan_Snapshot!$B$5:$B$256=$A14)*Loan_Snapshot!$I$5:$I$256*Loan_Snapshot!$BJ$5:$BJ$256)/$C14,0) | H14: =IFERROR(SUMPRODUCT((Loan_Snapshot!$B$5:$B$256=$A14)*Loan_Snapshot!$I$5:$I$256*Loan_Snapshot!$BK$5:$BK$256)/$C14,0) | I14: =IFERROR(SUMPRODUCT((Loan_Snapshot!$B$5:$B$256=$A14)*Loan_Snapshot!$I$5:$I$256*Loan_Snapshot!$BL$5:$BL$256)/$C14,0) | J14: =IFERROR(SUMPRODUCT((Loan_Snapshot!$B$5:$B$256=$A14)*Loan_Snapshot!$I$5:$I$256*Loan_Snapshot!$BM$5:$BM$256)/$C14,0) | K14: =IFERROR(SUMPRODUCT((Loan_Snapshot!$B$5:$B$256=$A14)*Loan_Snapshot!$I$5:$I$256*Loan_Snapshot!$BN$5:$BN$256)/$C14,0) | L14: =IFERROR(SUMPRODUCT((Loan_Snapshot!$B$5:$B$256=$A14)*Loan_Snapshot!$I$5:$I$256*Loan_Snapshot!$BO$5:$BO$256)/$C14,0) | M14: =IFERROR(SUMPRODUCT((Loan_Snapshot!$B$5:$B$256=$A14)*Loan_Snapshot!$I$5:$I$256*Loan_Snapshot!$BP$5:$BP$256)/$C14,0) | N14: =IFERROR(SUMPRODUCT((Loan_Snapshot!$B$5:$B$256=$A14)*Loan_Snapshot!$I$5:$I$256*Loan_Snapshot!$BQ$5:$BQ$256)/$C14,0) | O14: =IFERROR(SUMPRODUCT((Loan_Snapshot!$B$5:$B$256=$A14)*Loan_Snapshot!$I$5:$I$256*Loan_Snapshot!$BR$5:$BR$256)/$C14,0) | P14: =IFERROR(SUMPRODUCT((Loan_Snapshot!$B$5:$B$256=$A14)*Loan_Snapshot!$I$5:$I$256*Loan_Snapshot!$BS$5:$BS$256)/$C14,0) | Q14: =IFERROR(SUMPRODUCT((Loan_Snapshot!$B$5:$B$256=$A14)*Loan_Snapshot!$I$5:$I$256*Loan_Snapshot!$BT$5:$BT$256)/$C14,0) | R14: =IFERROR(SUMPRODUCT((Loan_Snapshot!$B$5:$B$256=$A14)*Loan_Snapshot!$I$5:$I$256*Loan_Snapshot!$BU$5:$BU$256)/$C14,0) | S14: =IFERROR(SUMPRODUCT((Loan_Snapshot!$B$5:$B$256=$A14)*Loan_Snapshot!$I$5:$I$256*Loan_Snapshot!$BV$5:$BV$256)/$C14,0) | T14: =IFERROR(SUMPRODUCT((Loan_Snapshot!$B$5:$B$256=$A14)*Loan_Snapshot!$I$5:$I$256*Loan_Snapshot!$BW$5:$BW$256)/$C14,0) | U14: =IFERROR(SUMPRODUCT((Loan_Snapshot!$B$5:$B$256=$A14)*Loan_Snapshot!$I$5:$I$256*Loan_Snapshot!$BX$5:$BX$256)/$C14,0) | V14: =IFERROR(SUMPRODUCT((Loan_Snapshot!$B$5:$B$256=$A14)*Loan_Snapshot!$I$5:$I$256*Loan_Snapshot!$BY$5:$BY$256)/$C14,0) | W14: =BASELINE_CPR+SUM(E14:V14)-$D14
