Workbook
Name INTERCEPT_SCALED: Coefficients!$B$32
Name BASELINE_SMM: Coefficients!$B$33
Name BASELINE_CPR: Coefficients!$B$34

Sheet README
A1: V6F Voluntary Prepayment Calculator
A3: Model: V6F (24-feature logistic regression, test AUC 0.7854)
A4: Training period: 201812 to 202602
A5: Training events: 7,686 voluntary prepays in 982,361 eligible loan-months
A7: Tabs
A8: Coefficients - 24 feature parameters + intercept + diagnostics. Edit at your own risk.
A9: Loan_Snapshot - one row per loan, current-period CPR + per-feature attribution.
A10: Paste new loans into rows below the existing data; formulas autopopulate.
A11: Deal_Aggregator - UPB-weighted deal-level rollup. Edit Deal_ID column in Loan_Snapshot to control grouping.
A13: Math (centered native form)
A14: contribution_j = beta_native_j * (x_j - mean_j)
A15: logit_z = intercept_scaled + SUM(contributions)
... A37: Model: model_data_v6e.json (snapshot 202603)

Sheet Coefficients
A1: V6F Voluntary Prepayment Model - Coefficients
A2: Edit at your own risk. Loan_Snapshot pulls mean/std/beta_native from this tab.
A4: # | B4: feature | C4: group | D4: beta_scaled | E4: beta_native | F4: mean | G4: std | H4: label
A5: 1 | B5: gross_refi_incentive_bps | C5: Rate & Penalty | D5: 0.570192 | E5: 0.00310379 | F5: 2.265188 | G5: 183.70832 | H5: Gross refi incentive (bp, penalty-neutral)
A6: 2 | B6: prepay_penalty_points | C6: Rate & Penalty | D6: -0.363185 | E6: -0.10008426 | F6: 5.076951 | G6: 3.628791 | H6: Prepay penalty points (continuous 0-10)
A7: 3 | B7: age_0_36 | C7: Seasoning (piecewise) | D7: 0.271688 | E7: 0.0319566 | F7: 32.292252 | G7: 8.501787 | H7: Age 0-36m (piecewise)
A8: 4 | B8: age_36_120 | C8: Seasoning (piecewise) | D8: 0.193293 | E8: 0.00577619 | F8: 40.759952 | G8: 33.463732 | H8: Age 36-120m (piecewise)
A9: 5 | B9: age_120plus | C9: Seasoning (piecewise) | D9: -0.098758 | E9: -0.00340313 | F9: 11.313631 | G9: 29.01982 | H9: Age 120m+ (piecewise)
A10: 6 | B10: months_to_maturity | C10: Maturity | D10: -0.032003 | E10: -0.00036144 | F10: 328.58708 | G10: 88.544231 | H10: Months to maturity
A11: 7 | B11: pre_maturity_flag | C11: Maturity | D11: 0.11705 | E11: 2.7884682 | F11: 0.001765 | G11: 0.041976 | H11: Within 0-24m of maturity (1/0)
A12: 8 | B12: months_since_lockout_end | C12: Post-lockout surge | D12: -0.012941 | E12: -0.0012261 | F12: 6.432159 | G12: 10.554518 | H12: Months since lockout end (cap 24)
A13: 9 | B13: log_upb | C13: Size | D13: 0.41296 | E13: 0.33366269 | F13: 15.369157 | G13: 1.237657 | H13: Log UPB
A14: 10 | B14: small_loan | C14: Size | D14: -0.101312 | E14: -0.23837744 | F14: 0.236621 | G14: 0.425007 | H14: UPB < $2M (1/0)
A15: 11 | B15: large_loan | C15: Size | D15: -0.04312 | E15: -0.38151918 | F15: 0.012941 | G15: 0.113021 | H15: UPB > $50M (1/0)
A16: 12 | B16: burn_ratio | C16: Burnout & Regime | D16: 0.178127 | E16: 0.72898702 | F16: 0.195122 | G16: 0.244349 | H16: Burnout ratio (cum_itm / age)
... A28: 24 | B28: gross_refi__x__prepay_pen | C28: Interactions | D28: 0.637551 | E28: 0.00059719 | F28: -65.148699 | G28: 1067.5759 | H28: Interaction: gross_refi_incentive_bps x prepay_penalty_points
A31: Model constants
A32: intercept_scaled | B32: -5.525031
A33: baseline_SMM (sigmoid of intercept_scaled) | B33: =1/(1+EXP(-B32))
A34: baseline_CPR (annualized from baseline_SMM) | B34: =1-(1-B33)^12
A36: Diagnostics
A37: test_AUC | B37: 0.7854
A38: panel_mean_CPR | B38: 0.089951
A39: training_pop_n | B39: 982361
A40: training_events | B40: 7686
A41: panel_period_range | B41: 201812 - 202602

Sheet Loan_Snapshot
A1: Loan Identifiers | I1: Raw Inputs (editable) | V1: V6E Feature Values (formulas - do not edit) | AT1: Logit Contributions (β_native × (x − mean)) | BR1: CPR Summary | BV1: CPR Attribution (proportional method) | CT1: Check
A2: loan_id | B2: deal_id | C2: pool_cusip | D2: issuer_name | E2: fha_category | F2: loan_purpose | G2: vintage_year | H2: period | I2: upb | J2: loan_rate_pct | K2: plc_rate_bps | L2: prepay_penalty_points | M2: loan_age_months_in | N2: cum_itm_in | O2: loan_maturity_yyyymm | P2: lockout_end_yyyymm | Q2: issuer_number_str | R2: is_hc_232_raw | S2: is_223a7_raw | T2: is_538_raw | U2: is_new_construction_raw | V2: gross_refi_incentive_bps | W2: prepay_penalty_points | X2: age_0_36 | Y2: age_36_120 | Z2: age_120plus | AA2: months_to_maturity | AB2: pre_maturity_flag | AC2: months_since_lockout_end | AD2: log_upb | AE2: small_loan | AF2: large_loan | AG2: burn_ratio | AH2: is_post_covid | AI2: is_223a7 | AJ2: is_538 | AK2: is_hc_232 | AL2: lp_NC | AM2: iss_capital_funding | AN2: iss_pnc | AO2: iss_wells_fargo | AP2: iss_dwight | AQ2: iss_greystone | AR2: iss_lument_combined | AS2: gross_refi__x__prepay_pen | AT2: contrib_gross_refi_incentive_bps | AU2: contrib_prepay_penalty_points | AV2: contrib_age_0_36 | AW2: contrib_age_36_120 | AX2: contrib_age_120plus | AY2: contrib_months_to_maturity | AZ2: contrib_pre_maturity_flag | BA2: contrib_months_since_lockout_end | BB2: contrib_log_upb | BC2: contrib_small_loan | BD2: contrib_large_loan | BE2: contrib_burn_ratio | BF2: contrib_is_post_covid | BG2: contrib_is_223a7 | BH2: contrib_is_538 | BI2: contrib_is_hc_232 | BJ2: contrib_lp_NC | BK2: contrib_iss_capital_funding | BL2: contrib_iss_pnc | BM2: contrib_iss_wells_fargo | BN2: contrib_iss_dwight | BO2: contrib_iss_greystone | BP2: contrib_iss_lument_combined | BQ2: contrib_gross_refi__x__prepay_pen | BR2: total_logit_dev | BS2: logit_z | BT2: SMM | BU2: pred_CPR | BV2: attr_gross_refi_incentive_bps | BW2: attr_prepay_penalty_points | BX2: attr_age_0_36 | BY2: attr_age_36_120 | BZ2: attr_age_120plus | CA2: attr_months_to_maturity | CB2: attr_pre_maturity_flag | CC2: attr_months_since_lockout_end | CD2: attr_log_upb | CE2: attr_small_loan | CF2: attr_large_loan | CG2: attr_burn_ratio | CH2: attr_is_post_covid | CI2: attr_is_223a7 | CJ2: attr_is_538 | CK2: attr_is_hc_232 | CL2: attr_lp_NC | CM2: attr_iss_capital_funding | CN2: attr_iss_pnc | CO2: attr_iss_wells_fargo | CP2: attr_iss_dwight | CQ2: attr_iss_greystone | CR2: attr_iss_lument_combined | CS2: attr_gross_refi__x__prepay_pen | CT2: Sanity
A3: mean | V3: =Coefficients!$F$5 | W3: =Coefficients!$F$6 | X3: =Coefficients!$F$7 | Y3: =Coefficients!$F$8 | Z3: =Coefficients!$F$9 | AA3: =Coefficients!$F$10 | AB3: =Coefficients!$F$11 | AC3: =Coefficients!$F$12 | AD3: =Coefficients!$F$13 | AE3: =Coefficients!$F$14 | AF3: =Coefficients!$F$15 | AG3: =Coefficients!$F$16 | AH3: =Coefficients!$F$17 | AI3: =Coefficients!$F$18 | AJ3: =Coefficients!$F$19 | AK3: =Coefficients!$F$20 | AL3: =Coefficients!$F$21 | AM3: =Coefficients!$F$22 | AN3: =Coefficients!$F$23 | AO3: =Coefficients!$F$24 | AP3: =Coefficients!$F$25 | AQ3: =Coefficients!$F$26 | AR3: =Coefficients!$F$27 | AS3: =Coefficients!$F$28
A4: β_native | V4: =Coefficients!$E$5 | W4: =Coefficients!$E$6 | X4: =Coefficients!$E$7 | Y4: =Coefficients!$E$8 | Z4: =Coefficients!$E$9 | AA4: =Coefficients!$E$10 | AB4: =Coefficients!$E$11 | AC4: =Coefficients!$E$12 | AD4: =Coefficients!$E$13 | AE4: =Coefficients!$E$14 | AF4: =Coefficients!$E$15 | AG4: =Coefficients!$E$16 | AH4: =Coefficients!$E$17 | AI4: =Coefficients!$E$18 | AJ4: =Coefficients!$E$19 | AK4: =Coefficients!$E$20 | AL4: =Coefficients!$E$21 | AM4: =Coefficients!$E$22 | AN4: =Coefficients!$E$23 | AO4: =Coefficients!$E$24 | AP4: =Coefficients!$E$25 | AQ4: =Coefficients!$E$26 | AR4: =Coefficients!$E$27 | AS4: =Coefficients!$E$28
A5: 3617UAX72_000000012211373 | B5: LUMENT_PRE21 | C5: 3617UAX72 | D5: LUMENT REAL ESTATE CAPITAL,LLC | E5: 223f | F5: RP | G5: 2015 | H5: 202602 | I5: 4746336.8 | J5: 2.96 | K5: 447 | L5: 5 | M5: 122 | N5: 1 | O5: 205101 | Q5: 3896 | R5: 0 | S5: 0 | T5: 0 | U5: 0 | V5: =J5*100-K5 | W5: =L5 | X5: =MIN(M5,36) | Y5: =MIN(MAX(M5-36,0),84) | Z5: =MAX(M5-120,0) | AA5: =IF(OR(O5="",NOT(ISNUMBER(O5))),360,MAX(0,MIN(480,(INT(O5/100)-INT(VALUE(H5)/100))*12+MOD(O5,100)-MOD(VALUE(H5),100)))) | AB5: =IF(AND(AA5>0,AA5<=24),1,0) | AC5: =IF(OR(P5="",NOT(ISNUMBER(P5))),0,MAX(0,MIN(24,(INT(VALUE(H5)/100)-INT(P5/100))*12+MOD(VALUE(H5),100)-MOD(P5,100)))) | AD5: =LN(1+I5) | AE5: =IF(I5<2000000,1,0) | AF5: =IF(I5>50000000,1,0) | AG5: =IF(ISNUMBER(M5),N5/MAX(M5,1),0) | AH5: =IF(G5>=2021,1,0) | AI5: =S5 | AJ5: =T5 | AK5: =R5 | AL5: =U5 | AM5: =IF(ISNUMBER(SEARCH("CAPITAL FUNDING",D5)),1,0) | AN5: =IF(ISNUMBER(SEARCH("PNC",D5)),1,0) | AO5: =IF(ISNUMBER(SEARCH("WELLS FARGO",D5)),1,0) | AP5: =IF(ISNUMBER(SEARCH("DWIGHT",D5)),1,0) | AQ5: =IF(ISNUMBER(SEARCH("GREYSTONE",D5)),1,0) | AR5: =IF(OR(Q5="3896",Q5="3557"),1,0) | AS5: =V5*W5 | AT5: =V$4*(V5-V$3) | AU5: =W$4*(W5-W$3) | AV5: =X$4*(X5-X$3) | AW5: =Y$4*(Y5-Y$3) | AX5: =Z$4*(Z5-Z$3) | AY5: =AA$4*(AA5-AA$3) | AZ5: =AB$4*(AB5-AB$3) | BA5: =AC$4*(AC5-AC$3) | ... BQ5: =AS$4*(AS5-AS$3) | BR5: =SUM(AT5:BQ5) | BS5: =INTERCEPT_SCALED+BR5 | BT5: =1/(1+EXP(-BS5)) | BU5: =1-(1-BT5)^12 | BV5: =IFERROR(AT5/BR5*(BU5-BASELINE_CPR),0) | BW5: =IFERROR(AU5/BR5*(BU5-BASELINE_CPR),0) | BX5: =IFERROR(AV5/BR5*(BU5-BASELINE_CPR),0) | BY5: =IFERROR(AW5/BR5*(BU5-BASELINE_CPR),0) | BZ5: =IFERROR(AX5/BR5*(BU5-BASELINE_CPR),0) | CA5: =IFERROR(AY5/BR5*(BU5-BASELINE_CPR),0) | CB5: =IFERROR(AZ5/BR5*(BU5-BASELINE_CPR),0) | CC5: =IFERROR(BA5/BR5*(BU5-BASELINE_CPR),0) | CD5: =IFERROR(BB5/BR5*(BU5-BASELINE_CPR),0) | CE5: =IFERROR(BC5/BR5*(BU5-BASELINE_CPR),0) | CF5: =IFERROR(BD5/BR5*(BU5-BASELINE_CPR),0) | CG5: =IFERROR(BE5/BR5*(BU5-BASELINE_CPR),0) | CH5: =IFERROR(BF5/BR5*(BU5-BASELINE_CPR),0) | CI5: =IFERROR(BG5/BR5*(BU5-BASELINE_CPR),0) | CJ5: =IFERROR(BH5/BR5*(BU5-BASELINE_CPR),0) | CK5: =IFERROR(BI5/BR5*(BU5-BASELINE_CPR),0) | CL5: =IFERROR(BJ5/BR5*(BU5-BASELINE_CPR),0) | CM5: =IFERROR(BK5/BR5*(BU5-BASELINE_CPR),0) | CN5: =IFERROR(BL5/BR5*(BU5-BASELINE_CPR),0) | CO5: =IFERROR(BM5/BR5*(BU5-BASELINE_CPR),0) | CP5: =IFERROR(BN5/BR5*(BU5-BASELINE_CPR),0) | CQ5: =IFERROR(BO5/BR5*(BU5-BASELINE_CPR),0) | CR5: =IFERROR(BP5/BR5*(BU5-BASELINE_CPR),0) | CS5: =IFERROR(BQ5/BR5*(BU5-BASELINE_CPR),0) | CT5: =BASELINE_CPR+SUM(BV5:CS5)-BU5
A6: 3617H4UL3_000000012322093 | B6: LUMENT_PRE21 | C6: 3617H4UL3 | D6: LUMENT REAL ESTATE CAPITAL,LLC | E6: 232 | F6: RP | G6: 2018 | H6: 202602 | I6: 11482585 | J6: 4.35 | K6: 447 | L6: 0 | M6: 91 | N6: 35 | O6: 205308 | Q6: 3896 | R6: 1 | S6: 0 | T6: 0 | U6: 0 | V6: =J6*100-K6 | W6: =L6 | X6: =MIN(M6,36) | Y6: =MIN(MAX(M6-36,0),84) | Z6: =MAX(M6-120,0) | AA6: =IF(OR(O6="",NOT(ISNUMBER(O6))),360,MAX(0,MIN(480,(INT(O6/100)-INT(VALUE(H6)/100))*12+MOD(O6,100)-MOD(VALUE(H6),100)))) | AB6: =IF(AND(AA6>0,AA6<=24),1,0) | AC6: =IF(OR(P6="",NOT(ISNUMBER(P6))),0,MAX(0,MIN(24,(INT(VALUE(H6)/100)-INT(P6/100))*12+MOD(VALUE(H6),100)-MOD(P6,100)))) | AD6: =LN(1+I6) | AE6: =IF(I6<2000000,1,0) | AF6: =IF(I6>50000000,1,0) | AG6: =IF(ISNUMBER(M6),N6/MAX(M6,1),0) | AH6: =IF(G6>=2021,1,0) | AI6: =S6 | AJ6: =T6 | AK6: =R6 | AL6: =U6 | AM6: =IF(ISNUMBER(SEARCH("CAPITAL FUNDING",D6)),1,0) | AN6: =IF(ISNUMBER(SEARCH("PNC",D6)),1,0) | AO6: =IF(ISNUMBER(SEARCH("WELLS FARGO",D6)),1,0) | AP6: =IF(ISNUMBER(SEARCH("DWIGHT",D6)),1,0) | AQ6: =IF(ISNUMBER(SEARCH("GREYSTONE",D6)),1,0) | AR6: =IF(OR(Q6="3896",Q6="3557"),1,0) | AS6: =V6*W6 | AT6: =V$4*(V6-V$3) | AU6: =W$4*(W6-W$3) | AV6: =X$4*(X6-X$3) | AW6: =Y$4*(Y6-Y$3) | AX6: =Z$4*(Z6-Z$3) | AY6: =AA$4*(AA6-AA$3) | AZ6: =AB$4*(AB6-AB$3) | BA6: =AC$4*(AC6-AC$3) | ... BQ6: =AS$4*(AS6-AS$3) | BR6: =SUM(AT6:BQ6) | BS6: =INTERCEPT_SCALED+BR6 | BT6: =1/(1+EXP(-BS6)) | BU6: =1-(1-BT6)^12 | BV6: =IFERROR(AT6/BR6*(BU6-BASELINE_CPR),0) | BW6: =IFERROR(AU6/BR6*(BU6-BASELINE_CPR),0) | BX6: =IFERROR(AV6/BR6*(BU6-BASELINE_CPR),0) | BY6: =IFERROR(AW6/BR6*(BU6-BASELINE_CPR),0) | BZ6: =IFERROR(AX6/BR6*(BU6-BASELINE_CPR),0) | CA6: =IFERROR(AY6/BR6*(BU6-BASELINE_CPR),0) | CB6: =IFERROR(AZ6/BR6*(BU6-BASELINE_CPR),0) | CC6: =IFERROR(BA6/BR6*(BU6-BASELINE_CPR),0) | CD6: =IFERROR(BB6/BR6*(BU6-BASELINE_CPR),0) | CE6: =IFERROR(BC6/BR6*(BU6-BASELINE_CPR),0) | CF6: =IFERROR(BD6/BR6*(BU6-BASELINE_CPR),0) | CG6: =IFERROR(BE6/BR6*(BU6-BASELINE_CPR),0) | CH6: =IFERROR(BF6/BR6*(BU6-BASELINE_CPR),0) | CI6: =IFERROR(BG6/BR6*(BU6-BASELINE_CPR),0) | CJ6: =IFERROR(BH6/BR6*(BU6-BASELINE_CPR),0) | CK6: =IFERROR(BI6/BR6*(BU6-BASELINE_CPR),0) | CL6: =IFERROR(BJ6/BR6*(BU6-BASELINE_CPR),0) | CM6: =IFERROR(BK6/BR6*(BU6-BASELINE_CPR),0) | CN6: =IFERROR(BL6/BR6*(BU6-BASELINE_CPR),0) | CO6: =IFERROR(BM6/BR6*(BU6-BASELINE_CPR),0) | CP6: =IFERROR(BN6/BR6*(BU6-BASELINE_CPR),0) | CQ6: =IFERROR(BO6/BR6*(BU6-BASELINE_CPR),0) | CR6: =IFERROR(BP6/BR6*(BU6-BASELINE_CPR),0) | CS6: =IFERROR(BQ6/BR6*(BU6-BASELINE_CPR),0) | CT6: =BASELINE_CPR+SUM(BV6:CS6)-BU6
A7: 3617QRGV6_000000002311435 | B7: LUMENT_PRE21 | C7: 3617QRGV6 | D7: LUMENT REAL ESTATE CAPITAL,LLC | E7: 223f | F7: RP | G7: 2017 | H7: 202602 | I7: 13751711 | J7: 3.15 | K7: 447 | L7: 5 | M7: 106 | N7: 9 | O7: 205205 | Q7: 3896 | R7: 0 | S7: 0 | T7: 0 | U7: 0 | V7: =J7*100-K7 | W7: =L7 | X7: =MIN(M7,36) | Y7: =MIN(MAX(M7-36,0),84) | Z7: =MAX(M7-120,0) | AA7: =IF(OR(O7="",NOT(ISNUMBER(O7))),360,MAX(0,MIN(480,(INT(O7/100)-INT(VALUE(H7)/100))*12+MOD(O7,100)-MOD(VALUE(H7),100)))) | AB7: =IF(AND(AA7>0,AA7<=24),1,0) | AC7: =IF(OR(P7="",NOT(ISNUMBER(P7))),0,MAX(0,MIN(24,(INT(VALUE(H7)/100)-INT(P7/100))*12+MOD(VALUE(H7),100)-MOD(P7,100)))) | AD7: =LN(1+I7) | AE7: =IF(I7<2000000,1,0) | AF7: =IF(I7>50000000,1,0) | AG7: =IF(ISNUMBER(M7),N7/MAX(M7,1),0) | AH7: =IF(G7>=2021,1,0) | AI7: =S7 | AJ7: =T7 | AK7: =R7 | AL7: =U7 | AM7: =IF(ISNUMBER(SEARCH("CAPITAL FUNDING",D7)),1,0) | AN7: =IF(ISNUMBER(SEARCH("PNC",D7)),1,0) | AO7: =IF(ISNUMBER(SEARCH("WELLS FARGO",D7)),1,0) | AP7: =IF(ISNUMBER(SEARCH("DWIGHT",D7)),1,0) | AQ7: =IF(ISNUMBER(SEARCH("GREYSTONE",D7)),1,0) | AR7: =IF(OR(Q7="3896",Q7="3557"),1,0) | AS7: =V7*W7 | AT7: =V$4*(V7-V$3) | AU7: =W$4*(W7-W$3) | AV7: =X$4*(X7-X$3) | AW7: =Y$4*(Y7-Y$3) | AX7: =Z$4*(Z7-Z$3) | AY7: =AA$4*(AA7-AA$3) | AZ7: =AB$4*(AB7-AB$3) | BA7: =AC$4*(AC7-AC$3) | ... BQ7: =AS$4*(AS7-AS$3) | BR7: =SUM(AT7:BQ7) | BS7: =INTERCEPT_SCALED+BR7 | BT7: =1/(1+EXP(-BS7)) | BU7: =1-(1-BT7)^12 | BV7: =IFERROR(AT7/BR7*(BU7-BASELINE_CPR),0) | BW7: =IFERROR(AU7/BR7*(BU7-BASELINE_CPR),0) | BX7: =IFERROR(AV7/BR7*(BU7-BASELINE_CPR),0) | BY7: =IFERROR(AW7/BR7*(BU7-BASELINE_CPR),0) | BZ7: =IFERROR(AX7/BR7*(BU7-BASELINE_CPR),0) | CA7: =IFERROR(AY7/BR7*(BU7-BASELINE_CPR),0) | CB7: =IFERROR(AZ7/BR7*(BU7-BASELINE_CPR),0) | CC7: =IFERROR(BA7/BR7*(BU7-BASELINE_CPR),0) | CD7: =IFERROR(BB7/BR7*(BU7-BASELINE_CPR),0) | CE7: =IFERROR(BC7/BR7*(BU7-BASELINE_CPR),0) | CF7: =IFERROR(BD7/BR7*(BU7-BASELINE_CPR),0) | CG7: =IFERROR(BE7/BR7*(BU7-BASELINE_CPR),0) | CH7: =IFERROR(BF7/BR7*(BU7-BASELINE_CPR),0) | CI7: =IFERROR(BG7/BR7*(BU7-BASELINE_CPR),0) | CJ7: =IFERROR(BH7/BR7*(BU7-BASELINE_CPR),0) | CK7: =IFERROR(BI7/BR7*(BU7-BASELINE_CPR),0) | CL7: =IFERROR(BJ7/BR7*(BU7-BASELINE_CPR),0) | CM7: =IFERROR(BK7/BR7*(BU7-BASELINE_CPR),0) | CN7: =IFERROR(BL7/BR7*(BU7-BASELINE_CPR),0) | CO7: =IFERROR(BM7/BR7*(BU7-BASELINE_CPR),0) | CP7: =IFERROR(BN7/BR7*(BU7-BASELINE_CPR),0) | CQ7: =IFERROR(BO7/BR7*(BU7-BASELINE_CPR),0) | CR7: =IFERROR(BP7/BR7*(BU7-BASELINE_CPR),0) | CS7: =IFERROR(BQ7/BR7*(BU7-BASELINE_CPR),0) | CT7: =BASELINE_CPR+SUM(BV7:CS7)-BU7
A8: 3617GAE46_000000007122391 | B8: LUMENT_PRE21 | C8: 3617GAE46 | D8: LUMENT REAL ESTATE CAPITAL,LLC | E8: 232 | F8: RP | G8: 2018 | H8: 202602 | I8: 9767084.7 | J8: 3.58 | K8: 447 | L8: 4 | M8: 95 | N8: 27 | O8: 205304 | Q8: 3896 | R8: 1 | S8: 0 | T8: 0 | U8: 0 | V8: =J8*100-K8 | W8: =L8 | X8: =MIN(M8,36) | Y8: =MIN(MAX(M8-36,0),84) | Z8: =MAX(M8-120,0) | AA8: =IF(OR(O8="",NOT(ISNUMBER(O8))),360,MAX(0,MIN(480,(INT(O8/100)-INT(VALUE(H8)/100))*12+MOD(O8,100)-MOD(VALUE(H8),100)))) | AB8: =IF(AND(AA8>0,AA8<=24),1,0) | AC8: =IF(OR(P8="",NOT(ISNUMBER(P8))),0,MAX(0,MIN(24,(INT(VALUE(H8)/100)-INT(P8/100))*12+MOD(VALUE(H8),100)-MOD(P8,100)))) | AD8: =LN(1+I8) | AE8: =IF(I8<2000000,1,0) | AF8: =IF(I8>50000000,1,0) | AG8: =IF(ISNUMBER(M8),N8/MAX(M8,1),0) | AH8: =IF(G8>=2021,1,0) | AI8: =S8 | AJ8: =T8 | AK8: =R8 | AL8: =U8 | AM8: =IF(ISNUMBER(SEARCH("CAPITAL FUNDING",D8)),1,0) | AN8: =IF(ISNUMBER(SEARCH("PNC",D8)),1,0) | AO8: =IF(ISNUMBER(SEARCH("WELLS FARGO",D8)),1,0) | AP8: =IF(ISNUMBER(SEARCH("DWIGHT",D8)),1,0) | AQ8: =IF(ISNUMBER(SEARCH("GREYSTONE",D8)),1,0) | AR8: =IF(OR(Q8="3896",Q8="3557"),1,0) | AS8: =V8*W8 | AT8: =V$4*(V8-V$3) | AU8: =W$4*(W8-W$3) | AV8: =X$4*(X8-X$3) | AW8: =Y$4*(Y8-Y$3) | AX8: =Z$4*(Z8-Z$3) | AY8: =AA$4*(AA8-AA$3) | AZ8: =AB$4*(AB8-AB$3) | BA8: =AC$4*(AC8-AC$3) | ... BQ8: =AS$4*(AS8-AS$3) | BR8: =SUM(AT8:BQ8) | BS8: =INTERCEPT_SCALED+BR8 | BT8: =1/(1+EXP(-BS8)) | BU8: =1-(1-BT8)^12 | BV8: =IFERROR(AT8/BR8*(BU8-BASELINE_CPR),0) | BW8: =IFERROR(AU8/BR8*(BU8-BASELINE_CPR),0) | BX8: =IFERROR(AV8/BR8*(BU8-BASELINE_CPR),0) | BY8: =IFERROR(AW8/BR8*(BU8-BASELINE_CPR),0) | BZ8: =IFERROR(AX8/BR8*(BU8-BASELINE_CPR),0) | CA8: =IFERROR(AY8/BR8*(BU8-BASELINE_CPR),0) | CB8: =IFERROR(AZ8/BR8*(BU8-BASELINE_CPR),0) | CC8: =IFERROR(BA8/BR8*(BU8-BASELINE_CPR),0) | CD8: =IFERROR(BB8/BR8*(BU8-BASELINE_CPR),0) | CE8: =IFERROR(BC8/BR8*(BU8-BASELINE_CPR),0) | CF8: =IFERROR(BD8/BR8*(BU8-BASELINE_CPR),0) | CG8: =IFERROR(BE8/BR8*(BU8-BASELINE_CPR),0) | CH8: =IFERROR(BF8/BR8*(BU8-BASELINE_CPR),0) | CI8: =IFERROR(BG8/BR8*(BU8-BASELINE_CPR),0) | CJ8: =IFERROR(BH8/BR8*(BU8-BASELINE_CPR),0) | CK8: =IFERROR(BI8/BR8*(BU8-BASELINE_CPR),0) | CL8: =IFERROR(BJ8/BR8*(BU8-BASELINE_CPR),0) | CM8: =IFERROR(BK8/BR8*(BU8-BASELINE_CPR),0) | CN8: =IFERROR(BL8/BR8*(BU8-BASELINE_CPR),0) | CO8: =IFERROR(BM8/BR8*(BU8-BASELINE_CPR),0) | CP8: =IFERROR(BN8/BR8*(BU8-BASELINE_CPR),0) | CQ8: =IFERROR(BO8/BR8*(BU8-BASELINE_CPR),0) | CR8: =IFERROR(BP8/BR8*(BU8-BASELINE_CPR),0) | CS8: =IFERROR(BQ8/BR8*(BU8-BASELINE_CPR),0) | CT8: =BASELINE_CPR+SUM(BV8:CS8)-BU8
A9: 3617X72J4_000000003422052 | B9: LUMENT_PRE21 | C9: 3617X72J4 | D9: LUMENT REAL ESTATE CAPITAL,LLC | E9: 232 | F9: RP | G9: 2011 | H9: 202602 | I9: 5069016.5 | J9: 3.05 | K9: 447 | L9: 6 | M9: 176 | N9: 0 | O9: 204607 | Q9: 3896 | R9: 1 | S9: 0 | T9: 0 | U9: 0 | V9: =J9*100-K9 | W9: =L9 | X9: =MIN(M9,36) | Y9: =MIN(MAX(M9-36,0),84) | Z9: =MAX(M9-120,0) | AA9: =IF(OR(O9="",NOT(ISNUMBER(O9))),360,MAX(0,MIN(480,(INT(O9/100)-INT(VALUE(H9)/100))*12+MOD(O9,100)-MOD(VALUE(H9),100)))) | AB9: =IF(AND(AA9>0,AA9<=24),1,0) | AC9: =IF(OR(P9="",NOT(ISNUMBER(P9))),0,MAX(0,MIN(24,(INT(VALUE(H9)/100)-INT(P9/100))*12+MOD(VALUE(H9),100)-MOD(P9,100)))) | AD9: =LN(1+I9) | AE9: =IF(I9<2000000,1,0) | AF9: =IF(I9>50000000,1,0) | AG9: =IF(ISNUMBER(M9),N9/MAX(M9,1),0) | AH9: =IF(G9>=2021,1,0) | AI9: =S9 | AJ9: =T9 | AK9: =R9 | AL9: =U9 | AM9: =IF(ISNUMBER(SEARCH("CAPITAL FUNDING",D9)),1,0) | AN9: =IF(ISNUMBER(SEARCH("PNC",D9)),1,0) | AO9: =IF(ISNUMBER(SEARCH("WELLS FARGO",D9)),1,0) | AP9: =IF(ISNUMBER(SEARCH("DWIGHT",D9)),1,0) | AQ9: =IF(ISNUMBER(SEARCH("GREYSTONE",D9)),1,0) | AR9: =IF(OR(Q9="3896",Q9="3557"),1,0) | AS9: =V9*W9 | AT9: =V$4*(V9-V$3) | AU9: =W$4*(W9-W$3) | AV9: =X$4*(X9-X$3) | AW9: =Y$4*(Y9-Y$3) | AX9: =Z$4*(Z9-Z$3) | AY9: =AA$4*(AA9-AA$3) | AZ9: =AB$4*(AB9-AB$3) | BA9: =AC$4*(AC9-AC$3) | ... BQ9: =AS$4*(AS9-AS$3) | BR9: =SUM(AT9:BQ9) | BS9: =INTERCEPT_SCALED+BR9 | BT9: =1/(1+EXP(-BS9)) | BU9: =1-(1-BT9)^12 | BV9: =IFERROR(AT9/BR9*(BU9-BASELINE_CPR),0) | BW9: =IFERROR(AU9/BR9*(BU9-BASELINE_CPR),0) | BX9: =IFERROR(AV9/BR9*(BU9-BASELINE_CPR),0) | BY9: =IFERROR(AW9/BR9*(BU9-BASELINE_CPR),0) | BZ9: =IFERROR(AX9/BR9*(BU9-BASELINE_CPR),0) | CA9: =IFERROR(AY9/BR9*(BU9-BASELINE_CPR),0) | CB9: =IFERROR(AZ9/BR9*(BU9-BASELINE_CPR),0) | CC9: =IFERROR(BA9/BR9*(BU9-BASELINE_CPR),0) | CD9: =IFERROR(BB9/BR9*(BU9-BASELINE_CPR),0) | CE9: =IFERROR(BC9/BR9*(BU9-BASELINE_CPR),0) | CF9: =IFERROR(BD9/BR9*(BU9-BASELINE_CPR),0) | CG9: =IFERROR(BE9/BR9*(BU9-BASELINE_CPR),0) | CH9: =IFERROR(BF9/BR9*(BU9-BASELINE_CPR),0) | CI9: =IFERROR(BG9/BR9*(BU9-BASELINE_CPR),0) | CJ9: =IFERROR(BH9/BR9*(BU9-BASELINE_CPR),0) | CK9: =IFERROR(BI9/BR9*(BU9-BASELINE_CPR),0) | CL9: =IFERROR(BJ9/BR9*(BU9-BASELINE_CPR),0) | CM9: =IFERROR(BK9/BR9*(BU9-BASELINE_CPR),0) | CN9: =IFERROR(BL9/BR9*(BU9-BASELINE_CPR),0) | CO9: =IFERROR(BM9/BR9*(BU9-BASELINE_CPR),0) | CP9: =IFERROR(BN9/BR9*(BU9-BASELINE_CPR),0) | CQ9: =IFERROR(BO9/BR9*(BU9-BASELINE_CPR),0) | CR9: =IFERROR(BP9/BR9*(BU9-BASELINE_CPR),0) | CS9: =IFERROR(BQ9/BR9*(BU9-BASELINE_CPR),0) | CT9: =BASELINE_CPR+SUM(BV9:CS9)-BU9
A10: 3617X74P8_000000007343145 | B10: LUMENT_PRE21 | C10: 3617X74P8 | D10: LUMENT REAL ESTATE CAPITAL,LLC | E10: 232 | F10: RP | G10: 2013 | H10: 202602 | I10: 11587614 | J10: 3.42 | K10: 447 | L10: 6 | M10: 148 | N10: 1 | O10: 205108 | Q10: 3896 | R10: 1 | S10: 1 | T10: 0 | U10: 0 | V10: =J10*100-K10 | W10: =L10 | X10: =MIN(M10,36) | Y10: =MIN(MAX(M10-36,0),84) | Z10: =MAX(M10-120,0) | AA10: =IF(OR(O10="",NOT(ISNUMBER(O10))),360,MAX(0,MIN(480,(INT(O10/100)-INT(VALUE(H10)/100))*12+MOD(O10,100)-MOD(VALUE(H10),100)))) | AB10: =IF(AND(AA10>0,AA10<=24),1,0) | AC10: =IF(OR(P10="",NOT(ISNUMBER(P10))),0,MAX(0,MIN(24,(INT(VALUE(H10)/100)-INT(P10/100))*12+MOD(VALUE(H10),100)-MOD(P10,100)))) | AD10: =LN(1+I10) | AE10: =IF(I10<2000000,1,0) | AF10: =IF(I10>50000000,1,0) | AG10: =IF(ISNUMBER(M10),N10/MAX(M10,1),0) | AH10: =IF(G10>=2021,1,0) | AI10: =S10 | AJ10: =T10 | AK10: =R10 | AL10: =U10 | AM10: =IF(ISNUMBER(SEARCH("CAPITAL FUNDING",D10)),1,0) | AN10: =IF(ISNUMBER(SEARCH("PNC",D10)),1,0) | AO10: =IF(ISNUMBER(SEARCH("WELLS FARGO",D10)),1,0) | AP10: =IF(ISNUMBER(SEARCH("DWIGHT",D10)),1,0) | AQ10: =IF(ISNUMBER(SEARCH("GREYSTONE",D10)),1,0) | AR10: =IF(OR(Q10="3896",Q10="3557"),1,0) | AS10: =V10*W10 | AT10: =V$4*(V10-V$3) | AU10: =W$4*(W10-W$3) | AV10: =X$4*(X10-X$3) | AW10: =Y$4*(Y10-Y$3) | AX10: =Z$4*(Z10-Z$3) | AY10: =AA$4*(AA10-AA$3) | AZ10: =AB$4*(AB10-AB$3) | BA10: =AC$4*(AC10-AC$3) | ... BQ10: =AS$4*(AS10-AS$3) | BR10: =SUM(AT10:BQ10) | BS10: =INTERCEPT_SCALED+BR10 | BT10: =1/(1+EXP(-BS10)) | BU10: =1-(1-BT10)^12 | BV10: =IFERROR(AT10/BR10*(BU10-BASELINE_CPR),0) | BW10: =IFERROR(AU10/BR10*(BU10-BASELINE_CPR),0) | BX10: =IFERROR(AV10/BR10*(BU10-BASELINE_CPR),0) | BY10: =IFERROR(AW10/BR10*(BU10-BASELINE_CPR),0) | BZ10: =IFERROR(AX10/BR10*(BU10-BASELINE_CPR),0) | CA10: =IFERROR(AY10/BR10*(BU10-BASELINE_CPR),0) | CB10: =IFERROR(AZ10/BR10*(BU10-BASELINE_CPR),0) | CC10: =IFERROR(BA10/BR10*(BU10-BASELINE_CPR),0) | CD10: =IFERROR(BB10/BR10*(BU10-BASELINE_CPR),0) | CE10: =IFERROR(BC10/BR10*(BU10-BASELINE_CPR),0) | CF10: =IFERROR(BD10/BR10*(BU10-BASELINE_CPR),0) | CG10: =IFERROR(BE10/BR10*(BU10-BASELINE_CPR),0) | CH10: =IFERROR(BF10/BR10*(BU10-BASELINE_CPR),0) | CI10: =IFERROR(BG10/BR10*(BU10-BASELINE_CPR),0) | CJ10: =IFERROR(BH10/BR10*(BU10-BASELINE_CPR),0) | CK10: =IFERROR(BI10/BR10*(BU10-BASELINE_CPR),0) | CL10: =IFERROR(BJ10/BR10*(BU10-BASELINE_CPR),0) | CM10: =IFERROR(BK10/BR10*(BU10-BASELINE_CPR),0) | CN10: =IFERROR(BL10/BR10*(BU10-BASELINE_CPR),0) | CO10: =IFERROR(BM10/BR10*(BU10-BASELINE_CPR),0) | CP10: =IFERROR(BN10/BR10*(BU10-BASELINE_CPR),0) | CQ10: =IFERROR(BO10/BR10*(BU10-BASELINE_CPR),0) | CR10: =IFERROR(BP10/BR10*(BU10-BASELINE_CPR),0) | CS10: =IFERROR(BQ10/BR10*(BU10-BASELINE_CPR),0) | CT10: =BASELINE_CPR+SUM(BV10:CS10)-BU10
A11: 3620AEYZ7_000000010535179 | B11: LUMENT_PRE21 | C11: 3620AEYZ7 | D11: LUMENT REAL ESTATE CAPITAL,LLC | E11: OTHER | F11: OTHER | G11: 2010 | H11: 202602 | I11: 7782165.9 | J11: 3.38 | K11: 447 | L11: 0 | M11: 182 | N11: 36 | O11: 205206 | Q11: 3896 | R11: 0 | S11: 0 | T11: 0 | U11: 0 | V11: =J11*100-K11 | W11: =L11 | X11: =MIN(M11,36) | Y11: =MIN(MAX(M11-36,0),84) | Z11: =MAX(M11-120,0) | AA11: =IF(OR(O11="",NOT(ISNUMBER(O11))),360,MAX(0,MIN(480,(INT(O11/100)-INT(VALUE(H11)/100))*12+MOD(O11,100)-MOD(VALUE(H11),100)))) | AB11: =IF(AND(AA11>0,AA11<=24),1,0) | AC11: =IF(OR(P11="",NOT(ISNUMBER(P11))),0,MAX(0,MIN(24,(INT(VALUE(H11)/100)-INT(P11/100))*12+MOD(VALUE(H11),100)-MOD(P11,100)))) | AD11: =LN(1+I11) | AE11: =IF(I11<2000000,1,0) | AF11: =IF(I11>50000000,1,0) | AG11: =IF(ISNUMBER(M11),N11/MAX(M11,1),0) | AH11: =IF(G11>=2021,1,0) | AI11: =S11 | AJ11: =T11 | AK11: =R11 | AL11: =U11 | AM11: =IF(ISNUMBER(SEARCH("CAPITAL FUNDING",D11)),1,0) | AN11: =IF(ISNUMBER(SEARCH("PNC",D11)),1,0) | AO11: =IF(ISNUMBER(SEARCH("WELLS FARGO",D11)),1,0) | AP11: =IF(ISNUMBER(SEARCH("DWIGHT",D11)),1,0) | AQ11: =IF(ISNUMBER(SEARCH("GREYSTONE",D11)),1,0) | AR11: =IF(OR(Q11="3896",Q11="3557"),1,0) | AS11: =V11*W11 | AT11: =V$4*(V11-V$3) | AU11: =W$4*(W11-W$3) | AV11: =X$4*(X11-X$3) | AW11: =Y$4*(Y11-Y$3) | AX11: =Z$4*(Z11-Z$3) | AY11: =AA$4*(AA11-AA$3) | AZ11: =AB$4*(AB11-AB$3) | BA11: =AC$4*(AC11-AC$3) | ... BQ11: =AS$4*(AS11-AS$3) | BR11: =SUM(AT11:BQ11) | BS11: =INTERCEPT_SCALED+BR11 | BT11: =1/(1+EXP(-BS11)) | BU11: =1-(1-BT11)^12 | BV11: =IFERROR(AT11/BR11*(BU11-BASELINE_CPR),0) | BW11: =IFERROR(AU11/BR11*(BU11-BASELINE_CPR),0) | BX11: =IFERROR(AV11/BR11*(BU11-BASELINE_CPR),0) | BY11: =IFERROR(AW11/BR11*(BU11-BASELINE_CPR),0) | BZ11: =IFERROR(AX11/BR11*(BU11-BASELINE_CPR),0) | CA11: =IFERROR(AY11/BR11*(BU11-BASELINE_CPR),0) | CB11: =IFERROR(AZ11/BR11*(BU11-BASELINE_CPR),0) | CC11: =IFERROR(BA11/BR11*(BU11-BASELINE_CPR),0) | CD11: =IFERROR(BB11/BR11*(BU11-BASELINE_CPR),0) | CE11: =IFERROR(BC11/BR11*(BU11-BASELINE_CPR),0) | CF11: =IFERROR(BD11/BR11*(BU11-BASELINE_CPR),0) | CG11: =IFERROR(BE11/BR11*(BU11-BASELINE_CPR),0) | CH11: =IFERROR(BF11/BR11*(BU11-BASELINE_CPR),0) | CI11: =IFERROR(BG11/BR11*(BU11-BASELINE_CPR),0) | CJ11: =IFERROR(BH11/BR11*(BU11-BASELINE_CPR),0) | CK11: =IFERROR(BI11/BR11*(BU11-BASELINE_CPR),0) | CL11: =IFERROR(BJ11/BR11*(BU11-BASELINE_CPR),0) | CM11: =IFERROR(BK11/BR11*(BU11-BASELINE_CPR),0) | CN11: =IFERROR(BL11/BR11*(BU11-BASELINE_CPR),0) | CO11: =IFERROR(BM11/BR11*(BU11-BASELINE_CPR),0) | CP11: =IFERROR(BN11/BR11*(BU11-BASELINE_CPR),0) | CQ11: =IFERROR(BO11/BR11*(BU11-BASELINE_CPR),0) | CR11: =IFERROR(BP11/BR11*(BU11-BASELINE_CPR),0) | CS11: =IFERROR(BQ11/BR11*(BU11-BASELINE_CPR),0) | CT11: =BASELINE_CPR+SUM(BV11:CS11)-BU11
A12: 3618BNC43_000000001211581 | B12: LUMENT_POST21 | C12: 3618BNC43 | D12: LUMENT REAL ESTATE CAPITAL,LLC | E12: 223f | F12: RP | G12: 2023 | H12: 202602 | I12: 30791262 | J12: 5.36 | K12: 447 | L12: 8 | M12: 32 | N12: 0 | O12: 205707 | Q12: 3896 | R12: 0 | S12: 0 | T12: 0 | U12: 0 | V12: =J12*100-K12 | W12: =L12 | X12: =MIN(M12,36) | Y12: =MIN(MAX(M12-36,0),84) | Z12: =MAX(M12-120,0) | AA12: =IF(OR(O12="",NOT(ISNUMBER(O12))),360,MAX(0,MIN(480,(INT(O12/100)-INT(VALUE(H12)/100))*12+MOD(O12,100)-MOD(VALUE(H12),100)))) | AB12: =IF(AND(AA12>0,AA12<=24),1,0) | AC12: =IF(OR(P12="",NOT(ISNUMBER(P12))),0,MAX(0,MIN(24,(INT(VALUE(H12)/100)-INT(P12/100))*12+MOD(VALUE(H12),100)-MOD(P12,100)))) | AD12: =LN(1+I12) | AE12: =IF(I12<2000000,1,0) | AF12: =IF(I12>50000000,1,0) | AG12: =IF(ISNUMBER(M12),N12/MAX(M12,1),0) | AH12: =IF(G12>=2021,1,0) | AI12: =S12 | AJ12: =T12 | AK12: =R12 | AL12: =U12 | AM12: =IF(ISNUMBER(SEARCH("CAPITAL FUNDING",D12)),1,0) | AN12: =IF(ISNUMBER(SEARCH("PNC",D12)),1,0) | AO12: =IF(ISNUMBER(SEARCH("WELLS FARGO",D12)),1,0) | AP12: =IF(ISNUMBER(SEARCH("DWIGHT",D12)),1,0) | AQ12: =IF(ISNUMBER(SEARCH("GREYSTONE",D12)),1,0) | AR12: =IF(OR(Q12="3896",Q12="3557"),1,0) | AS12: =V12*W12 | AT12: =V$4*(V12-V$3) | AU12: =W$4*(W12-W$3) | AV12: =X$4*(X12-X$3) | AW12: =Y$4*(Y12-Y$3) | AX12: =Z$4*(Z12-Z$3) | AY12: =AA$4*(AA12-AA$3) | AZ12: =AB$4*(AB12-AB$3) | BA12: =AC$4*(AC12-AC$3) | ... BQ12: =AS$4*(AS12-AS$3) | BR12: =SUM(AT12:BQ12) | BS12: =INTERCEPT_SCALED+BR12 | BT12: =1/(1+EXP(-BS12)) | BU12: =1-(1-BT12)^12 | BV12: =IFERROR(AT12/BR12*(BU12-BASELINE_CPR),0) | BW12: =IFERROR(AU12/BR12*(BU12-BASELINE_CPR),0) | BX12: =IFERROR(AV12/BR12*(BU12-BASELINE_CPR),0) | BY12: =IFERROR(AW12/BR12*(BU12-BASELINE_CPR),0) | BZ12: =IFERROR(AX12/BR12*(BU12-BASELINE_CPR),0) | CA12: =IFERROR(AY12/BR12*(BU12-BASELINE_CPR),0) | CB12: =IFERROR(AZ12/BR12*(BU12-BASELINE_CPR),0) | CC12: =IFERROR(BA12/BR12*(BU12-BASELINE_CPR),0) | CD12: =IFERROR(BB12/BR12*(BU12-BASELINE_CPR),0) | CE12: =IFERROR(BC12/BR12*(BU12-BASELINE_CPR),0) | CF12: =IFERROR(BD12/BR12*(BU12-BASELINE_CPR),0) | CG12: =IFERROR(BE12/BR12*(BU12-BASELINE_CPR),0) | CH12: =IFERROR(BF12/BR12*(BU12-BASELINE_CPR),0) | CI12: =IFERROR(BG12/BR12*(BU12-BASELINE_CPR),0) | CJ12: =IFERROR(BH12/BR12*(BU12-BASELINE_CPR),0) | CK12: =IFERROR(BI12/BR12*(BU12-BASELINE_CPR),0) | CL12: =IFERROR(BJ12/BR12*(BU12-BASELINE_CPR),0) | CM12: =IFERROR(BK12/BR12*(BU12-BASELINE_CPR),0) | CN12: =IFERROR(BL12/BR12*(BU12-BASELINE_CPR),0) | CO12: =IFERROR(BM12/BR12*(BU12-BASELINE_CPR),0) | CP12: =IFERROR(BN12/BR12*(BU12-BASELINE_CPR),0) | CQ12: =IFERROR(BO12/BR12*(BU12-BASELINE_CPR),0) | CR12: =IFERROR(BP12/BR12*(BU12-BASELINE_CPR),0) | CS12: =IFERROR(BQ12/BR12*(BU12-BASELINE_CPR),0) | CT12: =BASELINE_CPR+SUM(BV12:CS12)-BU12
A13: 3618KLMG9_000000001211630 | B13: LUMENT_POST21 | C13: 3618KLMG9 | D13: LUMENT REAL ESTATE CAPITAL,LLC | E13: 223f | F13: RP | G13: 2025 | H13: 202602 | I13: 59508580 | J13: 5.65 | K13: 447 | L13: 10 | M13: 4 | N13: 0 | O13: 206011 | Q13: 3896 | R13: 0 | S13: 0 | T13: 0 | U13: 0 | V13: =J13*100-K13 | W13: =L13 | X13: =MIN(M13,36) | Y13: =MIN(MAX(M13-36,0),84) | Z13: =MAX(M13-120,0) | AA13: =IF(OR(O13="",NOT(ISNUMBER(O13))),360,MAX(0,MIN(480,(INT(O13/100)-INT(VALUE(H13)/100))*12+MOD(O13,100)-MOD(VALUE(H13),100)))) | AB13: =IF(AND(AA13>0,AA13<=24),1,0) | AC13: =IF(OR(P13="",NOT(ISNUMBER(P13))),0,MAX(0,MIN(24,(INT(VALUE(H13)/100)-INT(P13/100))*12+MOD(VALUE(H13),100)-MOD(P13,100)))) | AD13: =LN(1+I13) | AE13: =IF(I13<2000000,1,0) | AF13: =IF(I13>50000000,1,0) | AG13: =IF(ISNUMBER(M13),N13/MAX(M13,1),0) | AH13: =IF(G13>=2021,1,0) | AI13: =S13 | AJ13: =T13 | AK13: =R13 | AL13: =U13 | AM13: =IF(ISNUMBER(SEARCH("CAPITAL FUNDING",D13)),1,0) | AN13: =IF(ISNUMBER(SEARCH("PNC",D13)),1,0) | AO13: =IF(ISNUMBER(SEARCH("WELLS FARGO",D13)),1,0) | AP13: =IF(ISNUMBER(SEARCH("DWIGHT",D13)),1,0) | AQ13: =IF(ISNUMBER(SEARCH("GREYSTONE",D13)),1,0) | AR13: =IF(OR(Q13="3896",Q13="3557"),1,0) | AS13: =V13*W13 | AT13: =V$4*(V13-V$3) | AU13: =W$4*(W13-W$3) | AV13: =X$4*(X13-X$3) | AW13: =Y$4*(Y13-Y$3) | AX13: =Z$4*(Z13-Z$3) | AY13: =AA$4*(AA13-AA$3) | AZ13: =AB$4*(AB13-AB$3) | BA13: =AC$4*(AC13-AC$3) | ... BQ13: =AS$4*(AS13-AS$3) | BR13: =SUM(AT13:BQ13) | BS13: =INTERCEPT_SCALED+BR13 | BT13: =1/(1+EXP(-BS13)) | BU13: =1-(1-BT13)^12 | BV13: =IFERROR(AT13/BR13*(BU13-BASELINE_CPR),0) | BW13: =IFERROR(AU13/BR13*(BU13-BASELINE_CPR),0) | BX13: =IFERROR(AV13/BR13*(BU13-BASELINE_CPR),0) | BY13: =IFERROR(AW13/BR13*(BU13-BASELINE_CPR),0) | BZ13: =IFERROR(AX13/BR13*(BU13-BASELINE_CPR),0) | CA13: =IFERROR(AY13/BR13*(BU13-BASELINE_CPR),0) | CB13: =IFERROR(AZ13/BR13*(BU13-BASELINE_CPR),0) | CC13: =IFERROR(BA13/BR13*(BU13-BASELINE_CPR),0) | CD13: =IFERROR(BB13/BR13*(BU13-BASELINE_CPR),0) | CE13: =IFERROR(BC13/BR13*(BU13-BASELINE_CPR),0) | CF13: =IFERROR(BD13/BR13*(BU13-BASELINE_CPR),0) | CG13: =IFERROR(BE13/BR13*(BU13-BASELINE_CPR),0) | CH13: =IFERROR(BF13/BR13*(BU13-BASELINE_CPR),0) | CI13: =IFERROR(BG13/BR13*(BU13-BASELINE_CPR),0) | CJ13: =IFERROR(BH13/BR13*(BU13-BASELINE_CPR),0) | CK13: =IFERROR(BI13/BR13*(BU13-BASELINE_CPR),0) | CL13: =IFERROR(BJ13/BR13*(BU13-BASELINE_CPR),0) | CM13: =IFERROR(BK13/BR13*(BU13-BASELINE_CPR),0) | CN13: =IFERROR(BL13/BR13*(BU13-BASELINE_CPR),0) | CO13: =IFERROR(BM13/BR13*(BU13-BASELINE_CPR),0) | CP13: =IFERROR(BN13/BR13*(BU13-BASELINE_CPR),0) | CQ13: =IFERROR(BO13/BR13*(BU13-BASELINE_CPR),0) | CR13: =IFERROR(BP13/BR13*(BU13-BASELINE_CPR),0) | CS13: =IFERROR(BQ13/BR13*(BU13-BASELINE_CPR),0) | CT13: =BASELINE_CPR+SUM(BV13:CS13)-BU13
A14: 36297HB49_000000010222024 | B14: LUMENT_PRE21 | C14: 36297HB49 | D14: LUMENT REAL ESTATE CAPITAL,LLC | E14: 232 | F14: RP | G14: 2009 | H14: 202602 | I14: 2318598.5 | J14: 5.65 | K14: 447 | L14: 0 | M14: 200 | N14: 84 | O14: 203907 | P14: 201108 | Q14: 3896 | R14: 1 | S14: 0 | T14: 0 | U14: 0 | V14: =J14*100-K14 | W14: =L14 | X14: =MIN(M14,36) | Y14: =MIN(MAX(M14-36,0),84) | Z14: =MAX(M14-120,0) | AA14: =IF(OR(O14="",NOT(ISNUMBER(O14))),360,MAX(0,MIN(480,(INT(O14/100)-INT(VALUE(H14)/100))*12+MOD(O14,100)-MOD(VALUE(H14),100)))) | AB14: =IF(AND(AA14>0,AA14<=24),1,0) | AC14: =IF(OR(P14="",NOT(ISNUMBER(P14))),0,MAX(0,MIN(24,(INT(VALUE(H14)/100)-INT(P14/100))*12+MOD(VALUE(H14),100)-MOD(P14,100)))) | AD14: =LN(1+I14) | AE14: =IF(I14<2000000,1,0) | AF14: =IF(I14>50000000,1,0) | AG14: =IF(ISNUMBER(M14),N14/MAX(M14,1),0) | AH14: =IF(G14>=2021,1,0) | AI14: =S14 | AJ14: =T14 | AK14: =R14 | AL14: =U14 | AM14: =IF(ISNUMBER(SEARCH("CAPITAL FUNDING",D14)),1,0) | AN14: =IF(ISNUMBER(SEARCH("PNC",D14)),1,0) | AO14: =IF(ISNUMBER(SEARCH("WELLS FARGO",D14)),1,0) | AP14: =IF(ISNUMBER(SEARCH("DWIGHT",D14)),1,0) | AQ14: =IF(ISNUMBER(SEARCH("GREYSTONE",D14)),1,0) | AR14: =IF(OR(Q14="3896",Q14="3557"),1,0) | AS14: =V14*W14 | AT14: =V$4*(V14-V$3) | AU14: =W$4*(W14-W$3) | AV14: =X$4*(X14-X$3) | AW14: =Y$4*(Y14-Y$3) | AX14: =Z$4*(Z14-Z$3) | AY14: =AA$4*(AA14-AA$3) | AZ14: =AB$4*(AB14-AB$3) | BA14: =AC$4*(AC14-AC$3) | ... BQ14: =AS$4*(AS14-AS$3) | BR14: =SUM(AT14:BQ14) | BS14: =INTERCEPT_SCALED+BR14 | BT14: =1/(1+EXP(-BS14)) | BU14: =1-(1-BT14)^12 | BV14: =IFERROR(AT14/BR14*(BU14-BASELINE_CPR),0) | BW14: =IFERROR(AU14/BR14*(BU14-BASELINE_CPR),0) | BX14: =IFERROR(AV14/BR14*(BU14-BASELINE_CPR),0) | BY14: =IFERROR(AW14/BR14*(BU14-BASELINE_CPR),0) | BZ14: =IFERROR(AX14/BR14*(BU14-BASELINE_CPR),0) | CA14: =IFERROR(AY14/BR14*(BU14-BASELINE_CPR),0) | CB14: =IFERROR(AZ14/BR14*(BU14-BASELINE_CPR),0) | CC14: =IFERROR(BA14/BR14*(BU14-BASELINE_CPR),0) | CD14: =IFERROR(BB14/BR14*(BU14-BASELINE_CPR),0) | CE14: =IFERROR(BC14/BR14*(BU14-BASELINE_CPR),0) | CF14: =IFERROR(BD14/BR14*(BU14-BASELINE_CPR),0) | CG14: =IFERROR(BE14/BR14*(BU14-BASELINE_CPR),0) | CH14: =IFERROR(BF14/BR14*(BU14-BASELINE_CPR),0) | CI14: =IFERROR(BG14/BR14*(BU14-BASELINE_CPR),0) | CJ14: =IFERROR(BH14/BR14*(BU14-BASELINE_CPR),0) | CK14: =IFERROR(BI14/BR14*(BU14-BASELINE_CPR),0) | CL14: =IFERROR(BJ14/BR14*(BU14-BASELINE_CPR),0) | CM14: =IFERROR(BK14/BR14*(BU14-BASELINE_CPR),0) | CN14: =IFERROR(BL14/BR14*(BU14-BASELINE_CPR),0) | CO14: =IFERROR(BM14/BR14*(BU14-BASELINE_CPR),0) | CP14: =IFERROR(BN14/BR14*(BU14-BASELINE_CPR),0) | CQ14: =IFERROR(BO14/BR14*(BU14-BASELINE_CPR),0) | CR14: =IFERROR(BP14/BR14*(BU14-BASELINE_CPR),0) | CS14: =IFERROR(BQ14/BR14*(BU14-BASELINE_CPR),0) | CT14: =BASELINE_CPR+SUM(BV14:CS14)-BU14
A15: 3618HNAN7_000000006122229 | B15: LUMENT_POST21 | C15: 3618HNAN7 | D15: LUMENT REAL ESTATE CAPITAL,LLC | E15: 232 | F15: RP | G15: 2024 | H15: 202602 | I15: 10649283 | J15: 5.35 | K15: 447 | L15: 9 | M15: 14 | N15: 0 | O15: 206001 | Q15: 3896 | R15: 1 | S15: 0 | T15: 0 | U15: 0 | V15: =J15*100-K15 | W15: =L15 | X15: =MIN(M15,36) | Y15: =MIN(MAX(M15-36,0),84) | Z15: =MAX(M15-120,0) | AA15: =IF(OR(O15="",NOT(ISNUMBER(O15))),360,MAX(0,MIN(480,(INT(O15/100)-INT(VALUE(H15)/100))*12+MOD(O15,100)-MOD(VALUE(H15),100)))) | AB15: =IF(AND(AA15>0,AA15<=24),1,0) | AC15: =IF(OR(P15="",NOT(ISNUMBER(P15))),0,MAX(0,MIN(24,(INT(VALUE(H15)/100)-INT(P15/100))*12+MOD(VALUE(H15),100)-MOD(P15,100)))) | AD15: =LN(1+I15) | AE15: =IF(I15<2000000,1,0) | AF15: =IF(I15>50000000,1,0) | AG15: =IF(ISNUMBER(M15),N15/MAX(M15,1),0) | AH15: =IF(G15>=2021,1,0) | AI15: =S15 | AJ15: =T15 | AK15: =R15 | AL15: =U15 | AM15: =IF(ISNUMBER(SEARCH("CAPITAL FUNDING",D15)),1,0) | AN15: =IF(ISNUMBER(SEARCH("PNC",D15)),1,0) | AO15: =IF(ISNUMBER(SEARCH("WELLS FARGO",D15)),1,0) | AP15: =IF(ISNUMBER(SEARCH("DWIGHT",D15)),1,0) | AQ15: =IF(ISNUMBER(SEARCH("GREYSTONE",D15)),1,0) | AR15: =IF(OR(Q15="3896",Q15="3557"),1,0) | AS15: =V15*W15 | AT15: =V$4*(V15-V$3) | AU15: =W$4*(W15-W$3) | AV15: =X$4*(X15-X$3) | AW15: =Y$4*(Y15-Y$3) | AX15: =Z$4*(Z15-Z$3) | AY15: =AA$4*(AA15-AA$3) | AZ15: =AB$4*(AB15-AB$3) | BA15: =AC$4*(AC15-AC$3) | ... BQ15: =AS$4*(AS15-AS$3) | BR15: =SUM(AT15:BQ15) | BS15: =INTERCEPT_SCALED+BR15 | BT15: =1/(1+EXP(-BS15)) | BU15: =1-(1-BT15)^12 | BV15: =IFERROR(AT15/BR15*(BU15-BASELINE_CPR),0) | BW15: =IFERROR(AU15/BR15*(BU15-BASELINE_CPR),0) | BX15: =IFERROR(AV15/BR15*(BU15-BASELINE_CPR),0) | BY15: =IFERROR(AW15/BR15*(BU15-BASELINE_CPR),0) | BZ15: =IFERROR(AX15/BR15*(BU15-BASELINE_CPR),0) | CA15: =IFERROR(AY15/BR15*(BU15-BASELINE_CPR),0) | CB15: =IFERROR(AZ15/BR15*(BU15-BASELINE_CPR),0) | CC15: =IFERROR(BA15/BR15*(BU15-BASELINE_CPR),0) | CD15: =IFERROR(BB15/BR15*(BU15-BASELINE_CPR),0) | CE15: =IFERROR(BC15/BR15*(BU15-BASELINE_CPR),0) | CF15: =IFERROR(BD15/BR15*(BU15-BASELINE_CPR),0) | CG15: =IFERROR(BE15/BR15*(BU15-BASELINE_CPR),0) | CH15: =IFERROR(BF15/BR15*(BU15-BASELINE_CPR),0) | CI15: =IFERROR(BG15/BR15*(BU15-BASELINE_CPR),0) | CJ15: =IFERROR(BH15/BR15*(BU15-BASELINE_CPR),0) | CK15: =IFERROR(BI15/BR15*(BU15-BASELINE_CPR),0) | CL15: =IFERROR(BJ15/BR15*(BU15-BASELINE_CPR),0) | CM15: =IFERROR(BK15/BR15*(BU15-BASELINE_CPR),0) | CN15: =IFERROR(BL15/BR15*(BU15-BASELINE_CPR),0) | CO15: =IFERROR(BM15/BR15*(BU15-BASELINE_CPR),0) | CP15: =IFERROR(BN15/BR15*(BU15-BASELINE_CPR),0) | CQ15: =IFERROR(BO15/BR15*(BU15-BASELINE_CPR),0) | CR15: =IFERROR(BP15/BR15*(BU15-BASELINE_CPR),0) | CS15: =IFERROR(BQ15/BR15*(BU15-BASELINE_CPR),0) | CT15: =BASELINE_CPR+SUM(BV15:CS15)-BU15
A16: 3617LC5T1_000000004611186 | B16: LUMENT_PRE21 | C16: 3617LC5T1 | D16: LUMENT REAL ESTATE CAPITAL,LLC | E16: 223f | F16: RP | G16: 2019 | H16: 202602 | I16: 14083196 | J16: 2.95 | K16: 447 | L16: 4 | M16: 75 | N16: 7 | O16: 205412 | Q16: 3896 | R16: 0 | S16: 0 | T16: 0 | U16: 0 | V16: =J16*100-K16 | W16: =L16 | X16: =MIN(M16,36) | Y16: =MIN(MAX(M16-36,0),84) | Z16: =MAX(M16-120,0) | AA16: =IF(OR(O16="",NOT(ISNUMBER(O16))),360,MAX(0,MIN(480,(INT(O16/100)-INT(VALUE(H16)/100))*12+MOD(O16,100)-MOD(VALUE(H16),100)))) | AB16: =IF(AND(AA16>0,AA16<=24),1,0) | AC16: =IF(OR(P16="",NOT(ISNUMBER(P16))),0,MAX(0,MIN(24,(INT(VALUE(H16)/100)-INT(P16/100))*12+MOD(VALUE(H16),100)-MOD(P16,100)))) | AD16: =LN(1+I16) | AE16: =IF(I16<2000000,1,0) | AF16: =IF(I16>50000000,1,0) | AG16: =IF(ISNUMBER(M16),N16/MAX(M16,1),0) | AH16: =IF(G16>=2021,1,0) | AI16: =S16 | AJ16: =T16 | AK16: =R16 | AL16: =U16 | AM16: =IF(ISNUMBER(SEARCH("CAPITAL FUNDING",D16)),1,0) | AN16: =IF(ISNUMBER(SEARCH("PNC",D16)),1,0) | AO16: =IF(ISNUMBER(SEARCH("WELLS FARGO",D16)),1,0) | AP16: =IF(ISNUMBER(SEARCH("DWIGHT",D16)),1,0) | AQ16: =IF(ISNUMBER(SEARCH("GREYSTONE",D16)),1,0) | AR16: =IF(OR(Q16="3896",Q16="3557"),1,0) | AS16: =V16*W16 | AT16: =V$4*(V16-V$3) | AU16: =W$4*(W16-W$3) | AV16: =X$4*(X16-X$3) | AW16: =Y$4*(Y16-Y$3) | AX16: =Z$4*(Z16-Z$3) | AY16: =AA$4*(AA16-AA$3) | AZ16: =AB$4*(AB16-AB$3) | BA16: =AC$4*(AC16-AC$3) | ... BQ16: =AS$4*(AS16-AS$3) | BR16: =SUM(AT16:BQ16) | BS16: =INTERCEPT_SCALED+BR16 | BT16: =1/(1+EXP(-BS16)) | BU16: =1-(1-BT16)^12 | BV16: =IFERROR(AT16/BR16*(BU16-BASELINE_CPR),0) | BW16: =IFERROR(AU16/BR16*(BU16-BASELINE_CPR),0) | BX16: =IFERROR(AV16/BR16*(BU16-BASELINE_CPR),0) | BY16: =IFERROR(AW16/BR16*(BU16-BASELINE_CPR),0) | BZ16: =IFERROR(AX16/BR16*(BU16-BASELINE_CPR),0) | CA16: =IFERROR(AY16/BR16*(BU16-BASELINE_CPR),0) | CB16: =IFERROR(AZ16/BR16*(BU16-BASELINE_CPR),0) | CC16: =IFERROR(BA16/BR16*(BU16-BASELINE_CPR),0) | CD16: =IFERROR(BB16/BR16*(BU16-BASELINE_CPR),0) | CE16: =IFERROR(BC16/BR16*(BU16-BASELINE_CPR),0) | CF16: =IFERROR(BD16/BR16*(BU16-BASELINE_CPR),0) | CG16: =IFERROR(BE16/BR16*(BU16-BASELINE_CPR),0) | CH16: =IFERROR(BF16/BR16*(BU16-BASELINE_CPR),0) | CI16: =IFERROR(BG16/BR16*(BU16-BASELINE_CPR),0) | CJ16: =IFERROR(BH16/BR16*(BU16-BASELINE_CPR),0) | CK16: =IFERROR(BI16/BR16*(BU16-BASELINE_CPR),0) | CL16: =IFERROR(BJ16/BR16*(BU16-BASELINE_CPR),0) | CM16: =IFERROR(BK16/BR16*(BU16-BASELINE_CPR),0) | CN16: =IFERROR(BL16/BR16*(BU16-BASELINE_CPR),0) | CO16: =IFERROR(BM16/BR16*(BU16-BASELINE_CPR),0) | CP16: =IFERROR(BN16/BR16*(BU16-BASELINE_CPR),0) | CQ16: =IFERROR(BO16/BR16*(BU16-BASELINE_CPR),0) | CR16: =IFERROR(BP16/BR16*(BU16-BASELINE_CPR),0) | CS16: =IFERROR(BQ16/BR16*(BU16-BASELINE_CPR),0) | CT16: =BASELINE_CPR+SUM(BV16:CS16)-BU16
A17: 3617J9LY2_000000001411271 | B17: LUMENT_PRE21 | C17: 3617J9LY2 | D17: LUMENT REAL ESTATE CAPITAL,LLC | E17: 223f | F17: RP | G17: 2019 | H17: 202602 | I17: 6145581.9 | J17: 4.3 | K17: 447 | L17: 4 | M17: 82 | N17: 35 | O17: 205405 | Q17: 3896 | R17: 0 | S17: 0 | T17: 0 | U17: 0 | V17: =J17*100-K17 | W17: =L17 | X17: =MIN(M17,36) | Y17: =MIN(MAX(M17-36,0),84) | Z17: =MAX(M17-120,0) | AA17: =IF(OR(O17="",NOT(ISNUMBER(O17))),360,MAX(0,MIN(480,(INT(O17/100)-INT(VALUE(H17)/100))*12+MOD(O17,100)-MOD(VALUE(H17),100)))) | AB17: =IF(AND(AA17>0,AA17<=24),1,0) | AC17: =IF(OR(P17="",NOT(ISNUMBER(P17))),0,MAX(0,MIN(24,(INT(VALUE(H17)/100)-INT(P17/100))*12+MOD(VALUE(H17),100)-MOD(P17,100)))) | AD17: =LN(1+I17) | AE17: =IF(I17<2000000,1,0) | AF17: =IF(I17>50000000,1,0) | AG17: =IF(ISNUMBER(M17),N17/MAX(M17,1),0) | AH17: =IF(G17>=2021,1,0) | AI17: =S17 | AJ17: =T17 | AK17: =R17 | AL17: =U17 | AM17: =IF(ISNUMBER(SEARCH("CAPITAL FUNDING",D17)),1,0) | AN17: =IF(ISNUMBER(SEARCH("PNC",D17)),1,0) | AO17: =IF(ISNUMBER(SEARCH("WELLS FARGO",D17)),1,0) | AP17: =IF(ISNUMBER(SEARCH("DWIGHT",D17)),1,0) | AQ17: =IF(ISNUMBER(SEARCH("GREYSTONE",D17)),1,0) | AR17: =IF(OR(Q17="3896",Q17="3557"),1,0) | AS17: =V17*W17 | AT17: =V$4*(V17-V$3) | AU17: =W$4*(W17-W$3) | AV17: =X$4*(X17-X$3) | AW17: =Y$4*(Y17-Y$3) | AX17: =Z$4*(Z17-Z$3) | AY17: =AA$4*(AA17-AA$3) | AZ17: =AB$4*(AB17-AB$3) | BA17: =AC$4*(AC17-AC$3) | ... BQ17: =AS$4*(AS17-AS$3) | BR17: =SUM(AT17:BQ17) | BS17: =INTERCEPT_SCALED+BR17 | BT17: =1/(1+EXP(-BS17)) | BU17: =1-(1-BT17)^12 | BV17: =IFERROR(AT17/BR17*(BU17-BASELINE_CPR),0) | BW17: =IFERROR(AU17/BR17*(BU17-BASELINE_CPR),0) | BX17: =IFERROR(AV17/BR17*(BU17-BASELINE_CPR),0) | BY17: =IFERROR(AW17/BR17*(BU17-BASELINE_CPR),0) | BZ17: =IFERROR(AX17/BR17*(BU17-BASELINE_CPR),0) | CA17: =IFERROR(AY17/BR17*(BU17-BASELINE_CPR),0) | CB17: =IFERROR(AZ17/BR17*(BU17-BASELINE_CPR),0) | CC17: =IFERROR(BA17/BR17*(BU17-BASELINE_CPR),0) | CD17: =IFERROR(BB17/BR17*(BU17-BASELINE_CPR),0) | CE17: =IFERROR(BC17/BR17*(BU17-BASELINE_CPR),0) | CF17: =IFERROR(BD17/BR17*(BU17-BASELINE_CPR),0) | CG17: =IFERROR(BE17/BR17*(BU17-BASELINE_CPR),0) | CH17: =IFERROR(BF17/BR17*(BU17-BASELINE_CPR),0) | CI17: =IFERROR(BG17/BR17*(BU17-BASELINE_CPR),0) | CJ17: =IFERROR(BH17/BR17*(BU17-BASELINE_CPR),0) | CK17: =IFERROR(BI17/BR17*(BU17-BASELINE_CPR),0) | CL17: =IFERROR(BJ17/BR17*(BU17-BASELINE_CPR),0) | CM17: =IFERROR(BK17/BR17*(BU17-BASELINE_CPR),0) | CN17: =IFERROR(BL17/BR17*(BU17-BASELINE_CPR),0) | CO17: =IFERROR(BM17/BR17*(BU17-BASELINE_CPR),0) | CP17: =IFERROR(BN17/BR17*(BU17-BASELINE_CPR),0) | CQ17: =IFERROR(BO17/BR17*(BU17-BASELINE_CPR),0) | CR17: =IFERROR(BP17/BR17*(BU17-BASELINE_CPR),0) | CS17: =IFERROR(BQ17/BR17*(BU17-BASELINE_CPR),0) | CT17: =BASELINE_CPR+SUM(BV17:CS17)-BU17
A18: 3617FTDM7_000000008311235 | B18: LUMENT_POST21 | C18: 3617FTDM7 | D18: LUMENT REAL ESTATE CAPITAL,LLC | E18: 223f | F18: RP | G18: 2023 | H18: 202602 | I18: 15752462 | J18: 5.1 | K18: 447 | L18: 8 | M18: 34 | N18: 0 | O18: 205805 | Q18: 3896 | R18: 0 | S18: 0 | T18: 0 | U18: 0 | V18: =J18*100-K18 | W18: =L18 | X18: =MIN(M18,36) | Y18: =MIN(MAX(M18-36,0),84) | Z18: =MAX(M18-120,0) | AA18: =IF(OR(O18="",NOT(ISNUMBER(O18))),360,MAX(0,MIN(480,(INT(O18/100)-INT(VALUE(H18)/100))*12+MOD(O18,100)-MOD(VALUE(H18),100)))) | AB18: =IF(AND(AA18>0,AA18<=24),1,0) | AC18: =IF(OR(P18="",NOT(ISNUMBER(P18))),0,MAX(0,MIN(24,(INT(VALUE(H18)/100)-INT(P18/100))*12+MOD(VALUE(H18),100)-MOD(P18,100)))) | AD18: =LN(1+I18) | AE18: =IF(I18<2000000,1,0) | AF18: =IF(I18>50000000,1,0) | AG18: =IF(ISNUMBER(M18),N18/MAX(M18,1),0) | AH18: =IF(G18>=2021,1,0) | AI18: =S18 | AJ18: =T18 | AK18: =R18 | AL18: =U18 | AM18: =IF(ISNUMBER(SEARCH("CAPITAL FUNDING",D18)),1,0) | AN18: =IF(ISNUMBER(SEARCH("PNC",D18)),1,0) | AO18: =IF(ISNUMBER(SEARCH("WELLS FARGO",D18)),1,0) | AP18: =IF(ISNUMBER(SEARCH("DWIGHT",D18)),1,0) | AQ18: =IF(ISNUMBER(SEARCH("GREYSTONE",D18)),1,0) | AR18: =IF(OR(Q18="3896",Q18="3557"),1,0) | AS18: =V18*W18 | AT18: =V$4*(V18-V$3) | AU18: =W$4*(W18-W$3) | AV18: =X$4*(X18-X$3) | AW18: =Y$4*(Y18-Y$3) | AX18: =Z$4*(Z18-Z$3) | AY18: =AA$4*(AA18-AA$3) | AZ18: =AB$4*(AB18-AB$3) | BA18: =AC$4*(AC18-AC$3) | ... BQ18: =AS$4*(AS18-AS$3) | BR18: =SUM(AT18:BQ18) | BS18: =INTERCEPT_SCALED+BR18 | BT18: =1/(1+EXP(-BS18)) | BU18: =1-(1-BT18)^12 | BV18: =IFERROR(AT18/BR18*(BU18-BASELINE_CPR),0) | BW18: =IFERROR(AU18/BR18*(BU18-BASELINE_CPR),0) | BX18: =IFERROR(AV18/BR18*(BU18-BASELINE_CPR),0) | BY18: =IFERROR(AW18/BR18*(BU18-BASELINE_CPR),0) | BZ18: =IFERROR(AX18/BR18*(BU18-BASELINE_CPR),0) | CA18: =IFERROR(AY18/BR18*(BU18-BASELINE_CPR),0) | CB18: =IFERROR(AZ18/BR18*(BU18-BASELINE_CPR),0) | CC18: =IFERROR(BA18/BR18*(BU18-BASELINE_CPR),0) | CD18: =IFERROR(BB18/BR18*(BU18-BASELINE_CPR),0) | CE18: =IFERROR(BC18/BR18*(BU18-BASELINE_CPR),0) | CF18: =IFERROR(BD18/BR18*(BU18-BASELINE_CPR),0) | CG18: =IFERROR(BE18/BR18*(BU18-BASELINE_CPR),0) | CH18: =IFERROR(BF18/BR18*(BU18-BASELINE_CPR),0) | CI18: =IFERROR(BG18/BR18*(BU18-BASELINE_CPR),0) | CJ18: =IFERROR(BH18/BR18*(BU18-BASELINE_CPR),0) | CK18: =IFERROR(BI18/BR18*(BU18-BASELINE_CPR),0) | CL18: =IFERROR(BJ18/BR18*(BU18-BASELINE_CPR),0) | CM18: =IFERROR(BK18/BR18*(BU18-BASELINE_CPR),0) | CN18: =IFERROR(BL18/BR18*(BU18-BASELINE_CPR),0) | CO18: =IFERROR(BM18/BR18*(BU18-BASELINE_CPR),0) | CP18: =IFERROR(BN18/BR18*(BU18-BASELINE_CPR),0) | CQ18: =IFERROR(BO18/BR18*(BU18-BASELINE_CPR),0) | CR18: =IFERROR(BP18/BR18*(BU18-BASELINE_CPR),0) | CS18: =IFERROR(BQ18/BR18*(BU18-BASELINE_CPR),0) | CT18: =BASELINE_CPR+SUM(BV18:CS18)-BU18
A19: 36187SCA3_000000001411159 | B19: LUMENT_PRE21 | C19: 36187SCA3 | D19: LUMENT REAL ESTATE CAPITAL,LLC | E19: 223f | F19: RP | G19: 2009 | H19: 202602 | I19: 1334344.3 | J19: 4.29 | K19: 447 | L19: 0 | M19: 205 | N19: 38 | O19: 204403 | Q19: 3896 | R19: 0 | S19: 0 | T19: 0 | U19: 0 | V19: =J19*100-K19 | W19: =L19 | X19: =MIN(M19,36) | Y19: =MIN(MAX(M19-36,0),84) | Z19: =MAX(M19-120,0) | AA19: =IF(OR(O19="",NOT(ISNUMBER(O19))),360,MAX(0,MIN(480,(INT(O19/100)-INT(VALUE(H19)/100))*12+MOD(O19,100)-MOD(VALUE(H19),100)))) | AB19: =IF(AND(AA19>0,AA19<=24),1,0) | AC19: =IF(OR(P19="",NOT(ISNUMBER(P19))),0,MAX(0,MIN(24,(INT(VALUE(H19)/100)-INT(P19/100))*12+MOD(VALUE(H19),100)-MOD(P19,100)))) | AD19: =LN(1+I19) | AE19: =IF(I19<2000000,1,0) | AF19: =IF(I19>50000000,1,0) | AG19: =IF(ISNUMBER(M19),N19/MAX(M19,1),0) | AH19: =IF(G19>=2021,1,0) | AI19: =S19 | AJ19: =T19 | AK19: =R19 | AL19: =U19 | AM19: =IF(ISNUMBER(SEARCH("CAPITAL FUNDING",D19)),1,0) | AN19: =IF(ISNUMBER(SEARCH("PNC",D19)),1,0) | AO19: =IF(ISNUMBER(SEARCH("WELLS FARGO",D19)),1,0) | AP19: =IF(ISNUMBER(SEARCH("DWIGHT",D19)),1,0) | AQ19: =IF(ISNUMBER(SEARCH("GREYSTONE",D19)),1,0) | AR19: =IF(OR(Q19="3896",Q19="3557"),1,0) | AS19: =V19*W19 | AT19: =V$4*(V19-V$3) | AU19: =W$4*(W19-W$3) | AV19: =X$4*(X19-X$3) | AW19: =Y$4*(Y19-Y$3) | AX19: =Z$4*(Z19-Z$3) | AY19: =AA$4*(AA19-AA$3) | AZ19: =AB$4*(AB19-AB$3) | BA19: =AC$4*(AC19-AC$3) | ... BQ19: =AS$4*(AS19-AS$3) | BR19: =SUM(AT19:BQ19) | BS19: =INTERCEPT_SCALED+BR19 | BT19: =1/(1+EXP(-BS19)) | BU19: =1-(1-BT19)^12 | BV19: =IFERROR(AT19/BR19*(BU19-BASELINE_CPR),0) | BW19: =IFERROR(AU19/BR19*(BU19-BASELINE_CPR),0) | BX19: =IFERROR(AV19/BR19*(BU19-BASELINE_CPR),0) | BY19: =IFERROR(AW19/BR19*(BU19-BASELINE_CPR),0) | BZ19: =IFERROR(AX19/BR19*(BU19-BASELINE_CPR),0) | CA19: =IFERROR(AY19/BR19*(BU19-BASELINE_CPR),0) | CB19: =IFERROR(AZ19/BR19*(BU19-BASELINE_CPR),0) | CC19: =IFERROR(BA19/BR19*(BU19-BASELINE_CPR),0) | CD19: =IFERROR(BB19/BR19*(BU19-BASELINE_CPR),0) | CE19: =IFERROR(BC19/BR19*(BU19-BASELINE_CPR),0) | CF19: =IFERROR(BD19/BR19*(BU19-BASELINE_CPR),0) | CG19: =IFERROR(BE19/BR19*(BU19-BASELINE_CPR),0) | CH19: =IFERROR(BF19/BR19*(BU19-BASELINE_CPR),0) | CI19: =IFERROR(BG19/BR19*(BU19-BASELINE_CPR),0) | CJ19: =IFERROR(BH19/BR19*(BU19-BASELINE_CPR),0) | CK19: =IFERROR(BI19/BR19*(BU19-BASELINE_CPR),0) | CL19: =IFERROR(BJ19/BR19*(BU19-BASELINE_CPR),0) | CM19: =IFERROR(BK19/BR19*(BU19-BASELINE_CPR),0) | CN19: =IFERROR(BL19/BR19*(BU19-BASELINE_CPR),0) | CO19: =IFERROR(BM19/BR19*(BU19-BASELINE_CPR),0) | CP19: =IFERROR(BN19/BR19*(BU19-BASELINE_CPR),0) | CQ19: =IFERROR(BO19/BR19*(BU19-BASELINE_CPR),0) | CR19: =IFERROR(BP19/BR19*(BU19-BASELINE_CPR),0) | CS19: =IFERROR(BQ19/BR19*(BU19-BASELINE_CPR),0) | CT19: =BASELINE_CPR+SUM(BV19:CS19)-BU19
A20: 3617AVUR7_049031028004210 | B20: LUMENT_PRE21 | C20: 3617AVUR7 | D20: LUMENT REAL ESTATE CAPITAL,LLC | E20: 538 | F20: 538 | G20: 2017 | H20: 202602 | I20: 1419192.9 | J20: 3.89 | K20: 447 | L20: 3 | M20: 103 | N20: 31 | O20: 204708 | Q20: 3896 | R20: 0 | S20: 0 | T20: 1 | U20: 0 | V20: =J20*100-K20 | W20: =L20 | X20: =MIN(M20,36) | Y20: =MIN(MAX(M20-36,0),84) | Z20: =MAX(M20-120,0) | AA20: =IF(OR(O20="",NOT(ISNUMBER(O20))),360,MAX(0,MIN(480,(INT(O20/100)-INT(VALUE(H20)/100))*12+MOD(O20,100)-MOD(VALUE(H20),100)))) | AB20: =IF(AND(AA20>0,AA20<=24),1,0) | AC20: =IF(OR(P20="",NOT(ISNUMBER(P20))),0,MAX(0,MIN(24,(INT(VALUE(H20)/100)-INT(P20/100))*12+MOD(VALUE(H20),100)-MOD(P20,100)))) | AD20: =LN(1+I20) | AE20: =IF(I20<2000000,1,0) | AF20: =IF(I20>50000000,1,0) | AG20: =IF(ISNUMBER(M20),N20/MAX(M20,1),0) | AH20: =IF(G20>=2021,1,0) | AI20: =S20 | AJ20: =T20 | AK20: =R20 | AL20: =U20 | AM20: =IF(ISNUMBER(SEARCH("CAPITAL FUNDING",D20)),1,0) | AN20: =IF(ISNUMBER(SEARCH("PNC",D20)),1,0) | AO20: =IF(ISNUMBER(SEARCH("WELLS FARGO",D20)),1,0) | AP20: =IF(ISNUMBER(SEARCH("DWIGHT",D20)),1,0) | AQ20: =IF(ISNUMBER(SEARCH("GREYSTONE",D20)),1,0) | AR20: =IF(OR(Q20="3896",Q20="3557"),1,0) | AS20: =V20*W20 | AT20: =V$4*(V20-V$3) | AU20: =W$4*(W20-W$3) | AV20: =X$4*(X20-X$3) | AW20: =Y$4*(Y20-Y$3) | AX20: =Z$4*(Z20-Z$3) | AY20: =AA$4*(AA20-AA$3) | AZ20: =AB$4*(AB20-AB$3) | BA20: =AC$4*(AC20-AC$3) | ... BQ20: =AS$4*(AS20-AS$3) | BR20: =SUM(AT20:BQ20) | BS20: =INTERCEPT_SCALED+BR20 | BT20: =1/(1+EXP(-BS20)) | BU20: =1-(1-BT20)^12 | BV20: =IFERROR(AT20/BR20*(BU20-BASELINE_CPR),0) | BW20: =IFERROR(AU20/BR20*(BU20-BASELINE_CPR),0) | BX20: =IFERROR(AV20/BR20*(BU20-BASELINE_CPR),0) | BY20: =IFERROR(AW20/BR20*(BU20-BASELINE_CPR),0) | BZ20: =IFERROR(AX20/BR20*(BU20-BASELINE_CPR),0) | CA20: =IFERROR(AY20/BR20*(BU20-BASELINE_CPR),0) | CB20: =IFERROR(AZ20/BR20*(BU20-BASELINE_CPR),0) | CC20: =IFERROR(BA20/BR20*(BU20-BASELINE_CPR),0) | CD20: =IFERROR(BB20/BR20*(BU20-BASELINE_CPR),0) | CE20: =IFERROR(BC20/BR20*(BU20-BASELINE_CPR),0) | CF20: =IFERROR(BD20/BR20*(BU20-BASELINE_CPR),0) | CG20: =IFERROR(BE20/BR20*(BU20-BASELINE_CPR),0) | CH20: =IFERROR(BF20/BR20*(BU20-BASELINE_CPR),0) | CI20: =IFERROR(BG20/BR20*(BU20-BASELINE_CPR),0) | CJ20: =IFERROR(BH20/BR20*(BU20-BASELINE_CPR),0) | CK20: =IFERROR(BI20/BR20*(BU20-BASELINE_CPR),0) | CL20: =IFERROR(BJ20/BR20*(BU20-BASELINE_CPR),0) | CM20: =IFERROR(BK20/BR20*(BU20-BASELINE_CPR),0) | CN20: =IFERROR(BL20/BR20*(BU20-BASELINE_CPR),0) | CO20: =IFERROR(BM20/BR20*(BU20-BASELINE_CPR),0) | CP20: =IFERROR(BN20/BR20*(BU20-BASELINE_CPR),0) | CQ20: =IFERROR(BO20/BR20*(BU20-BASELINE_CPR),0) | CR20: =IFERROR(BP20/BR20*(BU20-BASELINE_CPR),0) | CS20: =IFERROR(BQ20/BR20*(BU20-BASELINE_CPR),0) | CT20: =BASELINE_CPR+SUM(BV20:CS20)-BU20
A21: 3617GKP67_000000002411077 | B21: LUMENT_PRE21 | C21: 3617GKP67 | D21: LUMENT REAL ESTATE CAPITAL,LLC | E21: 223f | F21: RP | G21: 2018 | H21: 202602 | I21: 5685256.4 | J21: 4.02 | K21: 447 | L21: 3 | M21: 93 | N21: 32 | O21: 205306 | Q21: 3896 | R21: 0 | S21: 0 | T21: 0 | U21: 0 | V21: =J21*100-K21 | W21: =L21 | X21: =MIN(M21,36) | Y21: =MIN(MAX(M21-36,0),84) | Z21: =MAX(M21-120,0) | AA21: =IF(OR(O21="",NOT(ISNUMBER(O21))),360,MAX(0,MIN(480,(INT(O21/100)-INT(VALUE(H21)/100))*12+MOD(O21,100)-MOD(VALUE(H21),100)))) | AB21: =IF(AND(AA21>0,AA21<=24),1,0) | AC21: =IF(OR(P21="",NOT(ISNUMBER(P21))),0,MAX(0,MIN(24,(INT(VALUE(H21)/100)-INT(P21/100))*12+MOD(VALUE(H21),100)-MOD(P21,100)))) | AD21: =LN(1+I21) | AE21: =IF(I21<2000000,1,0) | AF21: =IF(I21>50000000,1,0) | AG21: =IF(ISNUMBER(M21),N21/MAX(M21,1),0) | AH21: =IF(G21>=2021,1,0) | AI21: =S21 | AJ21: =T21 | AK21: =R21 | AL21: =U21 | AM21: =IF(ISNUMBER(SEARCH("CAPITAL FUNDING",D21)),1,0) | AN21: =IF(ISNUMBER(SEARCH("PNC",D21)),1,0) | AO21: =IF(ISNUMBER(SEARCH("WELLS FARGO",D21)),1,0) | AP21: =IF(ISNUMBER(SEARCH("DWIGHT",D21)),1,0) | AQ21: =IF(ISNUMBER(SEARCH("GREYSTONE",D21)),1,0) | AR21: =IF(OR(Q21="3896",Q21="3557"),1,0) | AS21: =V21*W21 | AT21: =V$4*(V21-V$3) | AU21: =W$4*(W21-W$3) | AV21: =X$4*(X21-X$3) | AW21: =Y$4*(Y21-Y$3) | AX21: =Z$4*(Z21-Z$3) | AY21: =AA$4*(AA21-AA$3) | AZ21: =AB$4*(AB21-AB$3) | BA21: =AC$4*(AC21-AC$3) | ... BQ21: =AS$4*(AS21-AS$3) | BR21: =SUM(AT21:BQ21) | BS21: =INTERCEPT_SCALED+BR21 | BT21: =1/(1+EXP(-BS21)) | BU21: =1-(1-BT21)^12 | BV21: =IFERROR(AT21/BR21*(BU21-BASELINE_CPR),0) | BW21: =IFERROR(AU21/BR21*(BU21-BASELINE_CPR),0) | BX21: =IFERROR(AV21/BR21*(BU21-BASELINE_CPR),0) | BY21: =IFERROR(AW21/BR21*(BU21-BASELINE_CPR),0) | BZ21: =IFERROR(AX21/BR21*(BU21-BASELINE_CPR),0) | CA21: =IFERROR(AY21/BR21*(BU21-BASELINE_CPR),0) | CB21: =IFERROR(AZ21/BR21*(BU21-BASELINE_CPR),0) | CC21: =IFERROR(BA21/BR21*(BU21-BASELINE_CPR),0) | CD21: =IFERROR(BB21/BR21*(BU21-BASELINE_CPR),0) | CE21: =IFERROR(BC21/BR21*(BU21-BASELINE_CPR),0) | CF21: =IFERROR(BD21/BR21*(BU21-BASELINE_CPR),0) | CG21: =IFERROR(BE21/BR21*(BU21-BASELINE_CPR),0) | CH21: =IFERROR(BF21/BR21*(BU21-BASELINE_CPR),0) | CI21: =IFERROR(BG21/BR21*(BU21-BASELINE_CPR),0) | CJ21: =IFERROR(BH21/BR21*(BU21-BASELINE_CPR),0) | CK21: =IFERROR(BI21/BR21*(BU21-BASELINE_CPR),0) | CL21: =IFERROR(BJ21/BR21*(BU21-BASELINE_CPR),0) | CM21: =IFERROR(BK21/BR21*(BU21-BASELINE_CPR),0) | CN21: =IFERROR(BL21/BR21*(BU21-BASELINE_CPR),0) | CO21: =IFERROR(BM21/BR21*(BU21-BASELINE_CPR),0) | CP21: =IFERROR(BN21/BR21*(BU21-BASELINE_CPR),0) | CQ21: =IFERROR(BO21/BR21*(BU21-BASELINE_CPR),0) | CR21: =IFERROR(BP21/BR21*(BU21-BASELINE_CPR),0) | CS21: =IFERROR(BQ21/BR21*(BU21-BASELINE_CPR),0) | CT21: =BASELINE_CPR+SUM(BV21:CS21)-BU21
A22: 36180QCV8_000000010535250 | B22: LUMENT_PRE21 | C22: 36180QCV8 | D22: LUMENT REAL ESTATE CAPITAL,LLC | E22: 221d4 | F22: NC | G22: 2015 | H22: 202602 | I22: 2808410.9 | J22: 3.35 | K22: 447 | L22: 1 | M22: 128 | N22: 27 | O22: 205604 | Q22: 3896 | R22: 0 | S22: 0 | T22: 0 | U22: 1 | V22: =J22*100-K22 | W22: =L22 | X22: =MIN(M22,36) | Y22: =MIN(MAX(M22-36,0),84) | Z22: =MAX(M22-120,0) | AA22: =IF(OR(O22="",NOT(ISNUMBER(O22))),360,MAX(0,MIN(480,(INT(O22/100)-INT(VALUE(H22)/100))*12+MOD(O22,100)-MOD(VALUE(H22),100)))) | AB22: =IF(AND(AA22>0,AA22<=24),1,0) | AC22: =IF(OR(P22="",NOT(ISNUMBER(P22))),0,MAX(0,MIN(24,(INT(VALUE(H22)/100)-INT(P22/100))*12+MOD(VALUE(H22),100)-MOD(P22,100)))) | AD22: =LN(1+I22) | AE22: =IF(I22<2000000,1,0) | AF22: =IF(I22>50000000,1,0) | AG22: =IF(ISNUMBER(M22),N22/MAX(M22,1),0) | AH22: =IF(G22>=2021,1,0) | AI22: =S22 | AJ22: =T22 | AK22: =R22 | AL22: =U22 | AM22: =IF(ISNUMBER(SEARCH("CAPITAL FUNDING",D22)),1,0) | AN22: =IF(ISNUMBER(SEARCH("PNC",D22)),1,0) | AO22: =IF(ISNUMBER(SEARCH("WELLS FARGO",D22)),1,0) | AP22: =IF(ISNUMBER(SEARCH("DWIGHT",D22)),1,0) | AQ22: =IF(ISNUMBER(SEARCH("GREYSTONE",D22)),1,0) | AR22: =IF(OR(Q22="3896",Q22="3557"),1,0) | AS22: =V22*W22 | AT22: =V$4*(V22-V$3) | AU22: =W$4*(W22-W$3) | AV22: =X$4*(X22-X$3) | AW22: =Y$4*(Y22-Y$3) | AX22: =Z$4*(Z22-Z$3) | AY22: =AA$4*(AA22-AA$3) | AZ22: =AB$4*(AB22-AB$3) | BA22: =AC$4*(AC22-AC$3) | ... BQ22: =AS$4*(AS22-AS$3) | BR22: =SUM(AT22:BQ22) | BS22: =INTERCEPT_SCALED+BR22 | BT22: =1/(1+EXP(-BS22)) | BU22: =1-(1-BT22)^12 | BV22: =IFERROR(AT22/BR22*(BU22-BASELINE_CPR),0) | BW22: =IFERROR(AU22/BR22*(BU22-BASELINE_CPR),0) | BX22: =IFERROR(AV22/BR22*(BU22-BASELINE_CPR),0) | BY22: =IFERROR(AW22/BR22*(BU22-BASELINE_CPR),0) | BZ22: =IFERROR(AX22/BR22*(BU22-BASELINE_CPR),0) | CA22: =IFERROR(AY22/BR22*(BU22-BASELINE_CPR),0) | CB22: =IFERROR(AZ22/BR22*(BU22-BASELINE_CPR),0) | CC22: =IFERROR(BA22/BR22*(BU22-BASELINE_CPR),0) | CD22: =IFERROR(BB22/BR22*(BU22-BASELINE_CPR),0) | CE22: =IFERROR(BC22/BR22*(BU22-BASELINE_CPR),0) | CF22: =IFERROR(BD22/BR22*(BU22-BASELINE_CPR),0) | CG22: =IFERROR(BE22/BR22*(BU22-BASELINE_CPR),0) | CH22: =IFERROR(BF22/BR22*(BU22-BASELINE_CPR),0) | CI22: =IFERROR(BG22/BR22*(BU22-BASELINE_CPR),0) | CJ22: =IFERROR(BH22/BR22*(BU22-BASELINE_CPR),0) | CK22: =IFERROR(BI22/BR22*(BU22-BASELINE_CPR),0) | CL22: =IFERROR(BJ22/BR22*(BU22-BASELINE_CPR),0) | CM22: =IFERROR(BK22/BR22*(BU22-BASELINE_CPR),0) | CN22: =IFERROR(BL22/BR22*(BU22-BASELINE_CPR),0) | CO22: =IFERROR(BM22/BR22*(BU22-BASELINE_CPR),0) | CP22: =IFERROR(BN22/BR22*(BU22-BASELINE_CPR),0) | CQ22: =IFERROR(BO22/BR22*(BU22-BASELINE_CPR),0) | CR22: =IFERROR(BP22/BR22*(BU22-BASELINE_CPR),0) | CS22: =IFERROR(BQ22/BR22*(BU22-BASELINE_CPR),0) | CT22: =BASELINE_CPR+SUM(BV22:CS22)-BU22
A23: 3617X76V3_000000012211483 | B23: LUMENT_POST21 | C23: 3617X76V3 | D23: LUMENT REAL ESTATE CAPITAL,LLC | E23: 223f | F23: RP | G23: 2022 | H23: 202602 | I23: 11152291 | J23: 2.6 | K23: 447 | L23: 7 | M23: 47 | N23: 0 | O23: 205704 | Q23: 3896 | R23: 0 | S23: 0 | T23: 0 | U23: 0 | V23: =J23*100-K23 | W23: =L23 | X23: =MIN(M23,36) | Y23: =MIN(MAX(M23-36,0),84) | Z23: =MAX(M23-120,0) | AA23: =IF(OR(O23="",NOT(ISNUMBER(O23))),360,MAX(0,MIN(480,(INT(O23/100)-INT(VALUE(H23)/100))*12+MOD(O23,100)-MOD(VALUE(H23),100)))) | AB23: =IF(AND(AA23>0,AA23<=24),1,0) | AC23: =IF(OR(P23="",NOT(ISNUMBER(P23))),0,MAX(0,MIN(24,(INT(VALUE(H23)/100)-INT(P23/100))*12+MOD(VALUE(H23),100)-MOD(P23,100)))) | AD23: =LN(1+I23) | AE23: =IF(I23<2000000,1,0) | AF23: =IF(I23>50000000,1,0) | AG23: =IF(ISNUMBER(M23),N23/MAX(M23,1),0) | AH23: =IF(G23>=2021,1,0) | AI23: =S23 | AJ23: =T23 | AK23: =R23 | AL23: =U23 | AM23: =IF(ISNUMBER(SEARCH("CAPITAL FUNDING",D23)),1,0) | AN23: =IF(ISNUMBER(SEARCH("PNC",D23)),1,0) | AO23: =IF(ISNUMBER(SEARCH("WELLS FARGO",D23)),1,0) | AP23: =IF(ISNUMBER(SEARCH("DWIGHT",D23)),1,0) | AQ23: =IF(ISNUMBER(SEARCH("GREYSTONE",D23)),1,0) | AR23: =IF(OR(Q23="3896",Q23="3557"),1,0) | AS23: =V23*W23 | AT23: =V$4*(V23-V$3) | AU23: =W$4*(W23-W$3) | AV23: =X$4*(X23-X$3) | AW23: =Y$4*(Y23-Y$3) | AX23: =Z$4*(Z23-Z$3) | AY23: =AA$4*(AA23-AA$3) | AZ23: =AB$4*(AB23-AB$3) | BA23: =AC$4*(AC23-AC$3) | ... BQ23: =AS$4*(AS23-AS$3) | BR23: =SUM(AT23:BQ23) | BS23: =INTERCEPT_SCALED+BR23 | BT23: =1/(1+EXP(-BS23)) | BU23: =1-(1-BT23)^12 | BV23: =IFERROR(AT23/BR23*(BU23-BASELINE_CPR),0) | BW23: =IFERROR(AU23/BR23*(BU23-BASELINE_CPR),0) | BX23: =IFERROR(AV23/BR23*(BU23-BASELINE_CPR),0) | BY23: =IFERROR(AW23/BR23*(BU23-BASELINE_CPR),0) | BZ23: =IFERROR(AX23/BR23*(BU23-BASELINE_CPR),0) | CA23: =IFERROR(AY23/BR23*(BU23-BASELINE_CPR),0) | CB23: =IFERROR(AZ23/BR23*(BU23-BASELINE_CPR),0) | CC23: =IFERROR(BA23/BR23*(BU23-BASELINE_CPR),0) | CD23: =IFERROR(BB23/BR23*(BU23-BASELINE_CPR),0) | CE23: =IFERROR(BC23/BR23*(BU23-BASELINE_CPR),0) | CF23: =IFERROR(BD23/BR23*(BU23-BASELINE_CPR),0) | CG23: =IFERROR(BE23/BR23*(BU23-BASELINE_CPR),0) | CH23: =IFERROR(BF23/BR23*(BU23-BASELINE_CPR),0) | CI23: =IFERROR(BG23/BR23*(BU23-BASELINE_CPR),0) | CJ23: =IFERROR(BH23/BR23*(BU23-BASELINE_CPR),0) | CK23: =IFERROR(BI23/BR23*(BU23-BASELINE_CPR),0) | CL23: =IFERROR(BJ23/BR23*(BU23-BASELINE_CPR),0) | CM23: =IFERROR(BK23/BR23*(BU23-BASELINE_CPR),0) | CN23: =IFERROR(BL23/BR23*(BU23-BASELINE_CPR),0) | CO23: =IFERROR(BM23/BR23*(BU23-BASELINE_CPR),0) | CP23: =IFERROR(BN23/BR23*(BU23-BASELINE_CPR),0) | CQ23: =IFERROR(BO23/BR23*(BU23-BASELINE_CPR),0) | CR23: =IFERROR(BP23/BR23*(BU23-BASELINE_CPR),0) | CS23: =IFERROR(BQ23/BR23*(BU23-BASELINE_CPR),0) | CT23: =BASELINE_CPR+SUM(BV23:CS23)-BU23
