Workbook
Name V7_BASE_SMM: Multiplier_Params!$B$5
Name V7_SMM_CAP: Multiplier_Params!$B$6
Name V7_AGE_KNOT_Y_0: Multiplier_Params!$B$9
Name V7_AGE_KNOT_Y_1: Multiplier_Params!$B$10
Name V7_AGE_KNOT_Y_2: Multiplier_Params!$B$11
Name V7_AGE_KNOT_Y_3: Multiplier_Params!$B$12
Name V7_AGE_KNOT_Y_4: Multiplier_Params!$B$13
Name V7_AGE_KNOT_Y_5: Multiplier_Params!$B$14
Name V7_AGE_KNOT_X_0: Multiplier_Params!$B$16
Name V7_AGE_KNOT_X_1: Multiplier_Params!$B$17
Name V7_AGE_KNOT_X_2: Multiplier_Params!$B$18
Name V7_AGE_KNOT_X_3: Multiplier_Params!$B$19
Name V7_AGE_KNOT_X_4: Multiplier_Params!$B$20
Name V7_AGE_KNOT_X_5: Multiplier_Params!$B$21
Name V7_RATE_FLOOR: Multiplier_Params!$B$24
Name V7_RATE_ASYMPTOTE: Multiplier_Params!$B$25
Name V7_RATE_MID: Multiplier_Params!$B$26
Name V7_RATE_SLOPE: Multiplier_Params!$B$27
Name V7_SIZE_INTERCEPT: Multiplier_Params!$B$30
Name V7_SIZE_SLOPE: Multiplier_Params!$B$31
Name V7_SIZE_LOG_ANCHOR: Multiplier_Params!$B$32
Name V7_SIZE_LOW: Multiplier_Params!$B$33
Name V7_SIZE_HIGH: Multiplier_Params!$B$34
Name V7_PURPOSE_NC_BUMP: Multiplier_Params!$B$37
Name V7_PURPOSE_PEAK_AGE: Multiplier_Params!$B$38
Name V7_PURPOSE_WIDTH: Multiplier_Params!$B$39
Name V7_LOCKOUT_AMP: Multiplier_Params!$B$42
Name V7_LOCKOUT_TAU: Multiplier_Params!$B$43
Name V7_MTY_AMP: Multiplier_Params!$B$46
Name V7_MTY_CUTOFF: Multiplier_Params!$B$47
Name V7_BURN_FLOOR: Multiplier_Params!$B$50
Name V7_BURN_SLOPE: Multiplier_Params!$B$51
Name V7_USE_ISSUER: Multiplier_Params!$B$54
Name V7_TEST_AUC: Multiplier_Params!$B$57
Name V7_TEST_LL: Multiplier_Params!$B$58
Name V7_BASE_CPR: Multiplier_Params!$B$59
Name V7_PANEL_ACTUAL: Multiplier_Params!$B$60
Name V7_MAX_CPR: Multiplier_Params!$B$61
Name V7_PROGRAM_TABLE: Lookups!$A$5:$B$9
Name V7_PROGRAM_DEFAULT: Lookups!$B$9
Name V7_ISSUER_TABLE: Lookups!$E$5:$G$34

Sheet README
A1: V7 Voluntary Prepayment Calculator (multiplicative)
A3: Test AUC: 0.7788 Test log-loss: 0.04232 Free params: 27
A4: Training period: 201812 to 202602
A5: Training events: 7,686 prepays in 982,361 loan-months
A6: Max predicted CPR over full panel: 85.78% (SMM cap: 0.150)
A8: Architecture
A9: predicted_SMM = MIN(base_SMM × M_age × M_rate × M_size × M_program
A10: × M_purpose × M_lockout × M_maturity × M_burnout, smm_cap)
A11: M_rate input = net_refi_bps = gross_refi_bps - 12.5 × (ppp + 1) ← penalty bp-deductible
A12: predicted_CPR = 1 - (1 - predicted_SMM)^12
A14: Tabs
A15: Multiplier_Params - 9 multipliers + base_SMM + smm_cap, all parameters editable
... A32: base_CPR + SUM(attribution) - pred_CPR should be ≈ 0 (within rounding).

Sheet Multiplier_Params
A1: V7 Multiplier Parameters (edit at your own risk)
A2: Each cell is referenced by name from Loan_Snapshot formulas. Editing cascades through.
A4: Global
A5: base_SMM | B5: 0.0047133357
A6: smm_cap | B6: 0.15
A8: M_age (piecewise linear, 6 knots)
A9: knot 0: x = 0m → y | B9: 0.32039612
A10: knot 1: x = 12m → y | B10: 0.31570379
A11: knot 2: x = 36m → y | B11: 0.78253442
A12: knot 3: x = 96m → y | B12: 1.3960385
A13: knot 4: x = 180m → y | B13: 0.93148749
A14: knot 5: x = 360m → y | B14: 2.4223914
A15: (knot_x values, frozen)
A16: knot_x_0 | B16: 0
A17: knot_x_1 | B17: 12
A18: knot_x_2 | B18: 36
A19: knot_x_3 | B19: 96
A20: knot_x_4 | B20: 180
A21: knot_x_5 | B21: 360
A23: M_rate (sigmoid: floor + asymp/(1+exp(-(grf-mid)/slope)))
A24: floor | B24: 0.1615701
A25: asymptote | B25: 3.8774187
A26: mid (bp) | B26: 126.9326
A27: slope | B27: 95.706567
A29: M_size (smooth log on log_upb)
A30: intercept | B30: 0.64209336
A31: slope | B31: 0.44603609
A32: log_upb_anchor | B32: 14.508658
A33: low (clip) | B33: 0.39384537
A34: high (clip) | B34: 1.4178433
A36: M_purpose (NC triangular hump centered at peak_age)
A37: NC_bump | B37: 1.0454057
A38: peak_age | B38: 39.478259
A39: width | B39: 14.478228
A41: M_lockout (1 + amp*exp(-msle/tau) for msle ∈ (0,12])
A42: amplitude | B42: 4
A43: tau | B43: 1.7552982
A45: M_maturity (1 + amp*max(0, (cutoff-mtm)/cutoff))
A46: amplitude | B46: 8
A47: cutoff | B47: 12.309808
...

Sheet Lookups
A1: Categorical multiplier lookups
A3: M_program | E3: Issuer overlay (residual ratio)
A4: fha_pattern | B4: multiplier | E4: issuer_number | F4: issuer_name | G4: residual_ratio | H4: n
A5: 232 | B5: 0.90657311 | E5: 3896 | F5: RED MORTGAGE CAPITAL, LLC. | G5: 1.0443 | H5: 205895
A6: 538 | B6: 0.7081221 | E6: 4082 | F6: BERKADIA COMMERCIAL MORTGAGE, LLC | G6: 1.0002 | H6: 106649
A7: 223a7 | B7: 1.0737735 | E7: 4080 | F7: WALKER & DUNLOP, LLC | G7: 1.0311 | H7: 87217
A8: 223f | B8: 1.1183599 | E8: 4168 | F8: GREYSTONE FUNDING COMPANY LLC | G8: 1.5597 | H8: 59556
A9: default | B9: 0.95239057 | E9: 3487 | F9: MERCHANTS CAPITAL CORP. | G9: 0.8934 | H9: 59501
E10: 3998 | F10: WELLS FARGO MULTIFAMILY CAPITAL | G10: 0.8828 | H10: 53686
E11: 3976 | F11: PNC BANK, NA | G11: 0.6567 | H11: 44978
E12: 3866 | F12: CAPITAL FUNDING,LLC. | G12: 0.6435 | H12: 41909
E13: 3153 | F13: PRUDENTIAL HUNTOON PAIGE ASSOCIATES, LLC | G13: 0.9495 | H13: 38806
E14: 4398 | F14: DWIGHT CAPITAL LLC | G14: 1.4887 | H14: 38790
E15: 4012 | F15: BONNEVILLE MORTGAGE COMPANY | G15: 0.9212 | H15: 35248
E16: 4271 | F16: KEYBANK NATIONAL ASSOCIATION | G16: 1.1486 | H16: 32397
E17: 4067 | F17: BELLWETHER ENTERPRISE REAL ESTATE CAPITA | G17: 0.4723 | H17: 27200
E18: 3995 | F18: DOUGHERTY MORTGAGE, LLC | G18: 0.8276 | H18: 25918
E19: 2045 | F19: GERSHMAN INVESTMENT CORP. | G19: 1.7986 | H19: 24926
E20: 4065 | F20: JONES LANG LASALLE MULTIFAMILY LLC | G20: 1.3379 | H20: 24725
E21: 4300 | F21: MIDLAND STATES BANK | G21: 1.019 | H21: 23852
... E34: 2973 | F34: DAVIS-PENN MORTGAGE CO. | G34: 1.105 | H34: 9340

Sheet Loan_Snapshot
A1: Loan Identifiers | I1: Raw Inputs (editable) | T1: Derived inputs (formulas) | W1: V7 Multipliers (formulas) | AF1: Pred SMM/CPR | AI1: Per-multiplier attribution | AQ1: Check
A2: loan_id | B2: deal_id | C2: pool_cusip | D2: issuer_name | E2: fha_category | F2: loan_purpose | G2: vintage_year | H2: period | I2: upb | J2: loan_rate_pct | K2: plc_rate_bps | L2: prepay_penalty_points | M2: loan_age_months | N2: cum_itm | O2: loan_maturity_yyyymm | P2: lockout_end_yyyymm | Q2: issuer_number | R2: burn_ratio_in | S2: is_NC_in | T2: log_upb | U2: gross_refi_bps | V2: net_refi_bps | W2: M_age | X2: M_rate | Y2: M_size | Z2: M_program | AA2: M_purpose | AB2: M_lockout | AC2: M_maturity | AD2: M_burnout | AE2: M_issuer | AF2: product | AG2: capped_SMM | AH2: pred_CPR | AI2: attr_M_age | AJ2: attr_M_rate | AK2: attr_M_size | AL2: attr_M_program | AM2: attr_M_purpose | AN2: attr_M_lockout | AO2: attr_M_maturity | AP2: attr_M_burnout | AQ2: Sanity
A3: 3617UAX72_000000012211373 | B3: LUMENT_PRE21 | C3: 3617UAX72 | D3: LUMENT REAL ESTATE CAPITAL,LLC | E3: 223f | F3: RP | G3: 2015 | H3: 202602 | I3: 4746336.8 | J3: 2.96 | K3: 447 | L3: 5 | M3: 122 | N3: 1 | O3: 205101 | Q3: 3896 | R3: 0.0081967213 | S3: 0 | T3: =LN(1+I3) | U3: =J3*100-K3 | V3: =U3-12.5*(L3+1) | W3: =IF(M3<=V7_AGE_KNOT_X_0,V7_AGE_KNOT_Y_0,IF(M3>=V7_AGE_KNOT_X_5,V7_AGE_KNOT_Y_5,IF(M3<=V7_AGE_KNOT_X_1,V7_AGE_KNOT_Y_0+(M3-V7_AGE_KNOT_X_0)/(V7_AGE_KNOT_X_1-V7_AGE_KNOT_X_0)*(V7_AGE_KNOT_Y_1-V7_AGE_KNOT_Y_0),IF(M3<=V7_AGE_KNOT_X_2,V7_AGE_KNOT_Y_1+(M3-V7_AGE_KNOT_X_1)/(V7_AGE_KNOT_X_2-V7_AGE_KNOT_X_1)*(V7_AGE_KNOT_Y_2-V7_AGE_KNOT_Y_1),IF(M3<=V7_AGE_KNOT_X_3,V7_AGE_KNOT_Y_2+(M3-V7_AGE_KNOT_X_2)/(V7_AGE_KNOT_X_3-V7_AGE_KNOT_X_2)*(V7_AGE_KNOT_Y_3-V7_AGE_KNOT_Y_2),IF(M3<=V7_AGE_KNOT_X_4,V7_AGE_KNOT_Y_3+(M3-V7_AGE_KNOT_X_3)/(V7_AGE_KNOT_X_4-V7_AGE_KNOT_X_3)*(V7_AGE_KNOT_Y_4-V7_AGE_KNOT_Y_3),V7_AGE_KNOT_Y_4+(M3-V7_AGE_KNOT_X_4)/(V7_AGE_KNOT_X_5-V7_AGE_KNOT_X_4)*(V7_AGE_KNOT_Y_5-V7_AGE_KNOT_Y_4))))))) | X3: =V7_RATE_FLOOR+V7_RATE_ASYMPTOTE/(1+EXP(-(V3-V7_RATE_MID)/V7_RATE_SLOPE)) | Y3: =MAX(V7_SIZE_LOW,MIN(V7_SIZE_HIGH,V7_SIZE_INTERCEPT+V7_SIZE_SLOPE*(T3-V7_SIZE_LOG_ANCHOR))) | Z3: =IF(ISNUMBER(SEARCH("232",E3)),VLOOKUP("232",V7_PROGRAM_TABLE,2,FALSE),IF(ISNUMBER(SEARCH("538",E3)),VLOOKUP("538",V7_PROGRAM_TABLE,2,FALSE),IF(ISNUMBER(SEARCH("223a7",E3)),VLOOKUP("223a7",V7_PROGRAM_TABLE,2,FALSE),IF(ISNUMBER(SEARCH("223f",E3)),VLOOKUP("223f",V7_PROGRAM_TABLE,2,FALSE),V7_PROGRAM_DEFAULT)))) | AA3: =IF(S3=1,1+V7_PURPOSE_NC_BUMP*MAX(0,1-ABS(M3-V7_PURPOSE_PEAK_AGE)/V7_PURPOSE_WIDTH),1) | AB3: =IF(AND(IF(OR(P3="",NOT(ISNUMBER(P3))),0,MAX(0,MIN(24,(INT(VALUE(H3)/100)-INT(P3/100))*12+MOD(VALUE(H3),100)-MOD(P3,100))))>0,IF(OR(P3="",NOT(ISNUMBER(P3))),0,MAX(0,MIN(24,(INT(VALUE(H3)/100)-INT(P3/100))*12+MOD(VALUE(H3),100)-MOD(P3,100))))<=12),1+V7_LOCKOUT_AMP*EXP(-(IF(OR(P3="",NOT(ISNUMBER(P3))),0,MAX(0,MIN(24,(INT(VALUE(H3)/100)-INT(P3/100))*12+MOD(VALUE(H3),100)-MOD(P3,100)))))/V7_LOCKOUT_TAU),1) | AC3: =IF(IF(OR(O3="",NOT(ISNUMBER(O3))),360,MAX(0,MIN(480,(INT(O3/100)-INT(VALUE(H3)/100))*12+MOD(O3,100)-MOD(VALUE(H3),100))))>0,1+V7_MTY_AMP*MAX(0,(V7_MTY_CUTOFF-(IF(OR(O3="",NOT(ISNUMBER(O3))),360,MAX(0,MIN(480,(INT(O3/100)-INT(VALUE(H3)/100))*12+MOD(O3,100)-MOD(VALUE(H3),100))))))/V7_MTY_CUTOFF),1) | AD3: =MAX(V7_BURN_FLOOR,1-V7_BURN_SLOPE*MIN(1,MAX(0,R3))) | AE3: =IF(V7_USE_ISSUER=1,IFERROR(VLOOKUP(Q3,V7_ISSUER_TABLE,3,FALSE),1),1) | AF3: =PRODUCT(W3:AE3) | AG3: =MIN(V7_BASE_SMM*AF3,V7_SMM_CAP) | AH3: =1-(1-AG3)^12 | AI3: =IFERROR(LN(W3)/(LN(W3)+LN(X3)+LN(Y3)+LN(Z3)+LN(AA3)+LN(AB3)+LN(AC3)+LN(AD3))*(AH3-V7_BASE_CPR),0) | AJ3: =IFERROR(LN(X3)/(LN(W3)+LN(X3)+LN(Y3)+LN(Z3)+LN(AA3)+LN(AB3)+LN(AC3)+LN(AD3))*(AH3-V7_BASE_CPR),0) | AK3: =IFERROR(LN(Y3)/(LN(W3)+LN(X3)+LN(Y3)+LN(Z3)+LN(AA3)+LN(AB3)+LN(AC3)+LN(AD3))*(AH3-V7_BASE_CPR),0) | AL3: =IFERROR(LN(Z3)/(LN(W3)+LN(X3)+LN(Y3)+LN(Z3)+LN(AA3)+LN(AB3)+LN(AC3)+LN(AD3))*(AH3-V7_BASE_CPR),0) | AM3: =IFERROR(LN(AA3)/(LN(W3)+LN(X3)+LN(Y3)+LN(Z3)+LN(AA3)+LN(AB3)+LN(AC3)+LN(AD3))*(AH3-V7_BASE_CPR),0) | AN3: =IFERROR(LN(AB3)/(LN(W3)+LN(X3)+LN(Y3)+LN(Z3)+LN(AA3)+LN(AB3)+LN(AC3)+LN(AD3))*(AH3-V7_BASE_CPR),0) | AO3: =IFERROR(LN(AC3)/(LN(W3)+LN(X3)+LN(Y3)+LN(Z3)+LN(AA3)+LN(AB3)+LN(AC3)+LN(AD3))*(AH3-V7_BASE_CPR),0) | AP3: =IFERROR(LN(AD3)/(LN(W3)+LN(X3)+LN(Y3)+LN(Z3)+LN(AA3)+LN(AB3)+LN(AC3)+LN(AD3))*(AH3-V7_BASE_CPR),0) | AQ3: =V7_BASE_CPR+SUM(AI3:AP3)-AH3
A4: 3617H4UL3_000000012322093 | B4: LUMENT_PRE21 | C4: 3617H4UL3 | D4: LUMENT REAL ESTATE CAPITAL,LLC | E4: 232 | F4: RP | G4: 2018 | H4: 202602 | I4: 11482585 | J4: 4.35 | K4: 447 | L4: 0 | M4: 91 | N4: 35 | O4: 205308 | Q4: 3896 | R4: 0.38461538 | S4: 0 | T4: =LN(1+I4) | U4: =J4*100-K4 | V4: =U4-12.5*(L4+1) | W4: =IF(M4<=V7_AGE_KNOT_X_0,V7_AGE_KNOT_Y_0,IF(M4>=V7_AGE_KNOT_X_5,V7_AGE_KNOT_Y_5,IF(M4<=V7_AGE_KNOT_X_1,V7_AGE_KNOT_Y_0+(M4-V7_AGE_KNOT_X_0)/(V7_AGE_KNOT_X_1-V7_AGE_KNOT_X_0)*(V7_AGE_KNOT_Y_1-V7_AGE_KNOT_Y_0),IF(M4<=V7_AGE_KNOT_X_2,V7_AGE_KNOT_Y_1+(M4-V7_AGE_KNOT_X_1)/(V7_AGE_KNOT_X_2-V7_AGE_KNOT_X_1)*(V7_AGE_KNOT_Y_2-V7_AGE_KNOT_Y_1),IF(M4<=V7_AGE_KNOT_X_3,V7_AGE_KNOT_Y_2+(M4-V7_AGE_KNOT_X_2)/(V7_AGE_KNOT_X_3-V7_AGE_KNOT_X_2)*(V7_AGE_KNOT_Y_3-V7_AGE_KNOT_Y_2),IF(M4<=V7_AGE_KNOT_X_4,V7_AGE_KNOT_Y_3+(M4-V7_AGE_KNOT_X_3)/(V7_AGE_KNOT_X_4-V7_AGE_KNOT_X_3)*(V7_AGE_KNOT_Y_4-V7_AGE_KNOT_Y_3),V7_AGE_KNOT_Y_4+(M4-V7_AGE_KNOT_X_4)/(V7_AGE_KNOT_X_5-V7_AGE_KNOT_X_4)*(V7_AGE_KNOT_Y_5-V7_AGE_KNOT_Y_4))))))) | X4: =V7_RATE_FLOOR+V7_RATE_ASYMPTOTE/(1+EXP(-(V4-V7_RATE_MID)/V7_RATE_SLOPE)) | Y4: =MAX(V7_SIZE_LOW,MIN(V7_SIZE_HIGH,V7_SIZE_INTERCEPT+V7_SIZE_SLOPE*(T4-V7_SIZE_LOG_ANCHOR))) | Z4: =IF(ISNUMBER(SEARCH("232",E4)),VLOOKUP("232",V7_PROGRAM_TABLE,2,FALSE),IF(ISNUMBER(SEARCH("538",E4)),VLOOKUP("538",V7_PROGRAM_TABLE,2,FALSE),IF(ISNUMBER(SEARCH("223a7",E4)),VLOOKUP("223a7",V7_PROGRAM_TABLE,2,FALSE),IF(ISNUMBER(SEARCH("223f",E4)),VLOOKUP("223f",V7_PROGRAM_TABLE,2,FALSE),V7_PROGRAM_DEFAULT)))) | AA4: =IF(S4=1,1+V7_PURPOSE_NC_BUMP*MAX(0,1-ABS(M4-V7_PURPOSE_PEAK_AGE)/V7_PURPOSE_WIDTH),1) | AB4: =IF(AND(IF(OR(P4="",NOT(ISNUMBER(P4))),0,MAX(0,MIN(24,(INT(VALUE(H4)/100)-INT(P4/100))*12+MOD(VALUE(H4),100)-MOD(P4,100))))>0,IF(OR(P4="",NOT(ISNUMBER(P4))),0,MAX(0,MIN(24,(INT(VALUE(H4)/100)-INT(P4/100))*12+MOD(VALUE(H4),100)-MOD(P4,100))))<=12),1+V7_LOCKOUT_AMP*EXP(-(IF(OR(P4="",NOT(ISNUMBER(P4))),0,MAX(0,MIN(24,(INT(VALUE(H4)/100)-INT(P4/100))*12+MOD(VALUE(H4),100)-MOD(P4,100)))))/V7_LOCKOUT_TAU),1) | AC4: =IF(IF(OR(O4="",NOT(ISNUMBER(O4))),360,MAX(0,MIN(480,(INT(O4/100)-INT(VALUE(H4)/100))*12+MOD(O4,100)-MOD(VALUE(H4),100))))>0,1+V7_MTY_AMP*MAX(0,(V7_MTY_CUTOFF-(IF(OR(O4="",NOT(ISNUMBER(O4))),360,MAX(0,MIN(480,(INT(O4/100)-INT(VALUE(H4)/100))*12+MOD(O4,100)-MOD(VALUE(H4),100))))))/V7_MTY_CUTOFF),1) | AD4: =MAX(V7_BURN_FLOOR,1-V7_BURN_SLOPE*MIN(1,MAX(0,R4))) | AE4: =IF(V7_USE_ISSUER=1,IFERROR(VLOOKUP(Q4,V7_ISSUER_TABLE,3,FALSE),1),1) | AF4: =PRODUCT(W4:AE4) | AG4: =MIN(V7_BASE_SMM*AF4,V7_SMM_CAP) | AH4: =1-(1-AG4)^12 | AI4: =IFERROR(LN(W4)/(LN(W4)+LN(X4)+LN(Y4)+LN(Z4)+LN(AA4)+LN(AB4)+LN(AC4)+LN(AD4))*(AH4-V7_BASE_CPR),0) | AJ4: =IFERROR(LN(X4)/(LN(W4)+LN(X4)+LN(Y4)+LN(Z4)+LN(AA4)+LN(AB4)+LN(AC4)+LN(AD4))*(AH4-V7_BASE_CPR),0) | AK4: =IFERROR(LN(Y4)/(LN(W4)+LN(X4)+LN(Y4)+LN(Z4)+LN(AA4)+LN(AB4)+LN(AC4)+LN(AD4))*(AH4-V7_BASE_CPR),0) | AL4: =IFERROR(LN(Z4)/(LN(W4)+LN(X4)+LN(Y4)+LN(Z4)+LN(AA4)+LN(AB4)+LN(AC4)+LN(AD4))*(AH4-V7_BASE_CPR),0) | AM4: =IFERROR(LN(AA4)/(LN(W4)+LN(X4)+LN(Y4)+LN(Z4)+LN(AA4)+LN(AB4)+LN(AC4)+LN(AD4))*(AH4-V7_BASE_CPR),0) | AN4: =IFERROR(LN(AB4)/(LN(W4)+LN(X4)+LN(Y4)+LN(Z4)+LN(AA4)+LN(AB4)+LN(AC4)+LN(AD4))*(AH4-V7_BASE_CPR),0) | AO4: =IFERROR(LN(AC4)/(LN(W4)+LN(X4)+LN(Y4)+LN(Z4)+LN(AA4)+LN(AB4)+LN(AC4)+LN(AD4))*(AH4-V7_BASE_CPR),0) | AP4: =IFERROR(LN(AD4)/(LN(W4)+LN(X4)+LN(Y4)+LN(Z4)+LN(AA4)+LN(AB4)+LN(AC4)+LN(AD4))*(AH4-V7_BASE_CPR),0) | AQ4: =V7_BASE_CPR+SUM(AI4:AP4)-AH4
A5: 3617QRGV6_000000002311435 | B5: LUMENT_PRE21 | C5: 3617QRGV6 | D5: LUMENT REAL ESTATE CAPITAL,LLC | E5: 223f | F5: RP | G5: 2017 | H5: 202602 | I5: 13751711 | J5: 3.15 | K5: 447 | L5: 5 | M5: 106 | N5: 9 | O5: 205205 | Q5: 3896 | R5: 0.08490566 | S5: 0 | T5: =LN(1+I5) | U5: =J5*100-K5 | V5: =U5-12.5*(L5+1) | W5: =IF(M5<=V7_AGE_KNOT_X_0,V7_AGE_KNOT_Y_0,IF(M5>=V7_AGE_KNOT_X_5,V7_AGE_KNOT_Y_5,IF(M5<=V7_AGE_KNOT_X_1,V7_AGE_KNOT_Y_0+(M5-V7_AGE_KNOT_X_0)/(V7_AGE_KNOT_X_1-V7_AGE_KNOT_X_0)*(V7_AGE_KNOT_Y_1-V7_AGE_KNOT_Y_0),IF(M5<=V7_AGE_KNOT_X_2,V7_AGE_KNOT_Y_1+(M5-V7_AGE_KNOT_X_1)/(V7_AGE_KNOT_X_2-V7_AGE_KNOT_X_1)*(V7_AGE_KNOT_Y_2-V7_AGE_KNOT_Y_1),IF(M5<=V7_AGE_KNOT_X_3,V7_AGE_KNOT_Y_2+(M5-V7_AGE_KNOT_X_2)/(V7_AGE_KNOT_X_3-V7_AGE_KNOT_X_2)*(V7_AGE_KNOT_Y_3-V7_AGE_KNOT_Y_2),IF(M5<=V7_AGE_KNOT_X_4,V7_AGE_KNOT_Y_3+(M5-V7_AGE_KNOT_X_3)/(V7_AGE_KNOT_X_4-V7_AGE_KNOT_X_3)*(V7_AGE_KNOT_Y_4-V7_AGE_KNOT_Y_3),V7_AGE_KNOT_Y_4+(M5-V7_AGE_KNOT_X_4)/(V7_AGE_KNOT_X_5-V7_AGE_KNOT_X_4)*(V7_AGE_KNOT_Y_5-V7_AGE_KNOT_Y_4))))))) | X5: =V7_RATE_FLOOR+V7_RATE_ASYMPTOTE/(1+EXP(-(V5-V7_RATE_MID)/V7_RATE_SLOPE)) | Y5: =MAX(V7_SIZE_LOW,MIN(V7_SIZE_HIGH,V7_SIZE_INTERCEPT+V7_SIZE_SLOPE*(T5-V7_SIZE_LOG_ANCHOR))) | Z5: =IF(ISNUMBER(SEARCH("232",E5)),VLOOKUP("232",V7_PROGRAM_TABLE,2,FALSE),IF(ISNUMBER(SEARCH("538",E5)),VLOOKUP("538",V7_PROGRAM_TABLE,2,FALSE),IF(ISNUMBER(SEARCH("223a7",E5)),VLOOKUP("223a7",V7_PROGRAM_TABLE,2,FALSE),IF(ISNUMBER(SEARCH("223f",E5)),VLOOKUP("223f",V7_PROGRAM_TABLE,2,FALSE),V7_PROGRAM_DEFAULT)))) | AA5: =IF(S5=1,1+V7_PURPOSE_NC_BUMP*MAX(0,1-ABS(M5-V7_PURPOSE_PEAK_AGE)/V7_PURPOSE_WIDTH),1) | AB5: =IF(AND(IF(OR(P5="",NOT(ISNUMBER(P5))),0,MAX(0,MIN(24,(INT(VALUE(H5)/100)-INT(P5/100))*12+MOD(VALUE(H5),100)-MOD(P5,100))))>0,IF(OR(P5="",NOT(ISNUMBER(P5))),0,MAX(0,MIN(24,(INT(VALUE(H5)/100)-INT(P5/100))*12+MOD(VALUE(H5),100)-MOD(P5,100))))<=12),1+V7_LOCKOUT_AMP*EXP(-(IF(OR(P5="",NOT(ISNUMBER(P5))),0,MAX(0,MIN(24,(INT(VALUE(H5)/100)-INT(P5/100))*12+MOD(VALUE(H5),100)-MOD(P5,100)))))/V7_LOCKOUT_TAU),1) | AC5: =IF(IF(OR(O5="",NOT(ISNUMBER(O5))),360,MAX(0,MIN(480,(INT(O5/100)-INT(VALUE(H5)/100))*12+MOD(O5,100)-MOD(VALUE(H5),100))))>0,1+V7_MTY_AMP*MAX(0,(V7_MTY_CUTOFF-(IF(OR(O5="",NOT(ISNUMBER(O5))),360,MAX(0,MIN(480,(INT(O5/100)-INT(VALUE(H5)/100))*12+MOD(O5,100)-MOD(VALUE(H5),100))))))/V7_MTY_CUTOFF),1) | AD5: =MAX(V7_BURN_FLOOR,1-V7_BURN_SLOPE*MIN(1,MAX(0,R5))) | AE5: =IF(V7_USE_ISSUER=1,IFERROR(VLOOKUP(Q5,V7_ISSUER_TABLE,3,FALSE),1),1) | AF5: =PRODUCT(W5:AE5) | AG5: =MIN(V7_BASE_SMM*AF5,V7_SMM_CAP) | AH5: =1-(1-AG5)^12 | AI5: =IFERROR(LN(W5)/(LN(W5)+LN(X5)+LN(Y5)+LN(Z5)+LN(AA5)+LN(AB5)+LN(AC5)+LN(AD5))*(AH5-V7_BASE_CPR),0) | AJ5: =IFERROR(LN(X5)/(LN(W5)+LN(X5)+LN(Y5)+LN(Z5)+LN(AA5)+LN(AB5)+LN(AC5)+LN(AD5))*(AH5-V7_BASE_CPR),0) | AK5: =IFERROR(LN(Y5)/(LN(W5)+LN(X5)+LN(Y5)+LN(Z5)+LN(AA5)+LN(AB5)+LN(AC5)+LN(AD5))*(AH5-V7_BASE_CPR),0) | AL5: =IFERROR(LN(Z5)/(LN(W5)+LN(X5)+LN(Y5)+LN(Z5)+LN(AA5)+LN(AB5)+LN(AC5)+LN(AD5))*(AH5-V7_BASE_CPR),0) | AM5: =IFERROR(LN(AA5)/(LN(W5)+LN(X5)+LN(Y5)+LN(Z5)+LN(AA5)+LN(AB5)+LN(AC5)+LN(AD5))*(AH5-V7_BASE_CPR),0) | AN5: =IFERROR(LN(AB5)/(LN(W5)+LN(X5)+LN(Y5)+LN(Z5)+LN(AA5)+LN(AB5)+LN(AC5)+LN(AD5))*(AH5-V7_BASE_CPR),0) | AO5: =IFERROR(LN(AC5)/(LN(W5)+LN(X5)+LN(Y5)+LN(Z5)+LN(AA5)+LN(AB5)+LN(AC5)+LN(AD5))*(AH5-V7_BASE_CPR),0) | AP5: =IFERROR(LN(AD5)/(LN(W5)+LN(X5)+LN(Y5)+LN(Z5)+LN(AA5)+LN(AB5)+LN(AC5)+LN(AD5))*(AH5-V7_BASE_CPR),0) | AQ5: =V7_BASE_CPR+SUM(AI5:AP5)-AH5
A6: 3617GAE46_000000007122391 | B6: LUMENT_PRE21 | C6: 3617GAE46 | D6: LUMENT REAL ESTATE CAPITAL,LLC | E6: 232 | F6: RP | G6: 2018 | H6: 202602 | I6: 9767084.7 | J6: 3.58 | K6: 447 | L6: 4 | M6: 95 | N6: 27 | O6: 205304 | Q6: 3896 | R6: 0.28421053 | S6: 0 | T6: =LN(1+I6) | U6: =J6*100-K6 | V6: =U6-12.5*(L6+1) | W6: =IF(M6<=V7_AGE_KNOT_X_0,V7_AGE_KNOT_Y_0,IF(M6>=V7_AGE_KNOT_X_5,V7_AGE_KNOT_Y_5,IF(M6<=V7_AGE_KNOT_X_1,V7_AGE_KNOT_Y_0+(M6-V7_AGE_KNOT_X_0)/(V7_AGE_KNOT_X_1-V7_AGE_KNOT_X_0)*(V7_AGE_KNOT_Y_1-V7_AGE_KNOT_Y_0),IF(M6<=V7_AGE_KNOT_X_2,V7_AGE_KNOT_Y_1+(M6-V7_AGE_KNOT_X_1)/(V7_AGE_KNOT_X_2-V7_AGE_KNOT_X_1)*(V7_AGE_KNOT_Y_2-V7_AGE_KNOT_Y_1),IF(M6<=V7_AGE_KNOT_X_3,V7_AGE_KNOT_Y_2+(M6-V7_AGE_KNOT_X_2)/(V7_AGE_KNOT_X_3-V7_AGE_KNOT_X_2)*(V7_AGE_KNOT_Y_3-V7_AGE_KNOT_Y_2),IF(M6<=V7_AGE_KNOT_X_4,V7_AGE_KNOT_Y_3+(M6-V7_AGE_KNOT_X_3)/(V7_AGE_KNOT_X_4-V7_AGE_KNOT_X_3)*(V7_AGE_KNOT_Y_4-V7_AGE_KNOT_Y_3),V7_AGE_KNOT_Y_4+(M6-V7_AGE_KNOT_X_4)/(V7_AGE_KNOT_X_5-V7_AGE_KNOT_X_4)*(V7_AGE_KNOT_Y_5-V7_AGE_KNOT_Y_4))))))) | X6: =V7_RATE_FLOOR+V7_RATE_ASYMPTOTE/(1+EXP(-(V6-V7_RATE_MID)/V7_RATE_SLOPE)) | Y6: =MAX(V7_SIZE_LOW,MIN(V7_SIZE_HIGH,V7_SIZE_INTERCEPT+V7_SIZE_SLOPE*(T6-V7_SIZE_LOG_ANCHOR))) | Z6: =IF(ISNUMBER(SEARCH("232",E6)),VLOOKUP("232",V7_PROGRAM_TABLE,2,FALSE),IF(ISNUMBER(SEARCH("538",E6)),VLOOKUP("538",V7_PROGRAM_TABLE,2,FALSE),IF(ISNUMBER(SEARCH("223a7",E6)),VLOOKUP("223a7",V7_PROGRAM_TABLE,2,FALSE),IF(ISNUMBER(SEARCH("223f",E6)),VLOOKUP("223f",V7_PROGRAM_TABLE,2,FALSE),V7_PROGRAM_DEFAULT)))) | AA6: =IF(S6=1,1+V7_PURPOSE_NC_BUMP*MAX(0,1-ABS(M6-V7_PURPOSE_PEAK_AGE)/V7_PURPOSE_WIDTH),1) | AB6: =IF(AND(IF(OR(P6="",NOT(ISNUMBER(P6))),0,MAX(0,MIN(24,(INT(VALUE(H6)/100)-INT(P6/100))*12+MOD(VALUE(H6),100)-MOD(P6,100))))>0,IF(OR(P6="",NOT(ISNUMBER(P6))),0,MAX(0,MIN(24,(INT(VALUE(H6)/100)-INT(P6/100))*12+MOD(VALUE(H6),100)-MOD(P6,100))))<=12),1+V7_LOCKOUT_AMP*EXP(-(IF(OR(P6="",NOT(ISNUMBER(P6))),0,MAX(0,MIN(24,(INT(VALUE(H6)/100)-INT(P6/100))*12+MOD(VALUE(H6),100)-MOD(P6,100)))))/V7_LOCKOUT_TAU),1) | AC6: =IF(IF(OR(O6="",NOT(ISNUMBER(O6))),360,MAX(0,MIN(480,(INT(O6/100)-INT(VALUE(H6)/100))*12+MOD(O6,100)-MOD(VALUE(H6),100))))>0,1+V7_MTY_AMP*MAX(0,(V7_MTY_CUTOFF-(IF(OR(O6="",NOT(ISNUMBER(O6))),360,MAX(0,MIN(480,(INT(O6/100)-INT(VALUE(H6)/100))*12+MOD(O6,100)-MOD(VALUE(H6),100))))))/V7_MTY_CUTOFF),1) | AD6: =MAX(V7_BURN_FLOOR,1-V7_BURN_SLOPE*MIN(1,MAX(0,R6))) | AE6: =IF(V7_USE_ISSUER=1,IFERROR(VLOOKUP(Q6,V7_ISSUER_TABLE,3,FALSE),1),1) | AF6: =PRODUCT(W6:AE6) | AG6: =MIN(V7_BASE_SMM*AF6,V7_SMM_CAP) | AH6: =1-(1-AG6)^12 | AI6: =IFERROR(LN(W6)/(LN(W6)+LN(X6)+LN(Y6)+LN(Z6)+LN(AA6)+LN(AB6)+LN(AC6)+LN(AD6))*(AH6-V7_BASE_CPR),0) | AJ6: =IFERROR(LN(X6)/(LN(W6)+LN(X6)+LN(Y6)+LN(Z6)+LN(AA6)+LN(AB6)+LN(AC6)+LN(AD6))*(AH6-V7_BASE_CPR),0) | AK6: =IFERROR(LN(Y6)/(LN(W6)+LN(X6)+LN(Y6)+LN(Z6)+LN(AA6)+LN(AB6)+LN(AC6)+LN(AD6))*(AH6-V7_BASE_CPR),0) | AL6: =IFERROR(LN(Z6)/(LN(W6)+LN(X6)+LN(Y6)+LN(Z6)+LN(AA6)+LN(AB6)+LN(AC6)+LN(AD6))*(AH6-V7_BASE_CPR),0) | AM6: =IFERROR(LN(AA6)/(LN(W6)+LN(X6)+LN(Y6)+LN(Z6)+LN(AA6)+LN(AB6)+LN(AC6)+LN(AD6))*(AH6-V7_BASE_CPR),0) | AN6: =IFERROR(LN(AB6)/(LN(W6)+LN(X6)+LN(Y6)+LN(Z6)+LN(AA6)+LN(AB6)+LN(AC6)+LN(AD6))*(AH6-V7_BASE_CPR),0) | AO6: =IFERROR(LN(AC6)/(LN(W6)+LN(X6)+LN(Y6)+LN(Z6)+LN(AA6)+LN(AB6)+LN(AC6)+LN(AD6))*(AH6-V7_BASE_CPR),0) | AP6: =IFERROR(LN(AD6)/(LN(W6)+LN(X6)+LN(Y6)+LN(Z6)+LN(AA6)+LN(AB6)+LN(AC6)+LN(AD6))*(AH6-V7_BASE_CPR),0) | AQ6: =V7_BASE_CPR+SUM(AI6:AP6)-AH6
A7: 3617X72J4_000000003422052 | B7: LUMENT_PRE21 | C7: 3617X72J4 | D7: LUMENT REAL ESTATE CAPITAL,LLC | E7: 232 | F7: RP | G7: 2011 | H7: 202602 | I7: 5069016.5 | J7: 3.05 | K7: 447 | L7: 6 | M7: 176 | N7: 0 | O7: 204607 | Q7: 3896 | R7: 0 | S7: 0 | T7: =LN(1+I7) | U7: =J7*100-K7 | V7: =U7-12.5*(L7+1) | W7: =IF(M7<=V7_AGE_KNOT_X_0,V7_AGE_KNOT_Y_0,IF(M7>=V7_AGE_KNOT_X_5,V7_AGE_KNOT_Y_5,IF(M7<=V7_AGE_KNOT_X_1,V7_AGE_KNOT_Y_0+(M7-V7_AGE_KNOT_X_0)/(V7_AGE_KNOT_X_1-V7_AGE_KNOT_X_0)*(V7_AGE_KNOT_Y_1-V7_AGE_KNOT_Y_0),IF(M7<=V7_AGE_KNOT_X_2,V7_AGE_KNOT_Y_1+(M7-V7_AGE_KNOT_X_1)/(V7_AGE_KNOT_X_2-V7_AGE_KNOT_X_1)*(V7_AGE_KNOT_Y_2-V7_AGE_KNOT_Y_1),IF(M7<=V7_AGE_KNOT_X_3,V7_AGE_KNOT_Y_2+(M7-V7_AGE_KNOT_X_2)/(V7_AGE_KNOT_X_3-V7_AGE_KNOT_X_2)*(V7_AGE_KNOT_Y_3-V7_AGE_KNOT_Y_2),IF(M7<=V7_AGE_KNOT_X_4,V7_AGE_KNOT_Y_3+(M7-V7_AGE_KNOT_X_3)/(V7_AGE_KNOT_X_4-V7_AGE_KNOT_X_3)*(V7_AGE_KNOT_Y_4-V7_AGE_KNOT_Y_3),V7_AGE_KNOT_Y_4+(M7-V7_AGE_KNOT_X_4)/(V7_AGE_KNOT_X_5-V7_AGE_KNOT_X_4)*(V7_AGE_KNOT_Y_5-V7_AGE_KNOT_Y_4))))))) | X7: =V7_RATE_FLOOR+V7_RATE_ASYMPTOTE/(1+EXP(-(V7-V7_RATE_MID)/V7_RATE_SLOPE)) | Y7: =MAX(V7_SIZE_LOW,MIN(V7_SIZE_HIGH,V7_SIZE_INTERCEPT+V7_SIZE_SLOPE*(T7-V7_SIZE_LOG_ANCHOR))) | Z7: =IF(ISNUMBER(SEARCH("232",E7)),VLOOKUP("232",V7_PROGRAM_TABLE,2,FALSE),IF(ISNUMBER(SEARCH("538",E7)),VLOOKUP("538",V7_PROGRAM_TABLE,2,FALSE),IF(ISNUMBER(SEARCH("223a7",E7)),VLOOKUP("223a7",V7_PROGRAM_TABLE,2,FALSE),IF(ISNUMBER(SEARCH("223f",E7)),VLOOKUP("223f",V7_PROGRAM_TABLE,2,FALSE),V7_PROGRAM_DEFAULT)))) | AA7: =IF(S7=1,1+V7_PURPOSE_NC_BUMP*MAX(0,1-ABS(M7-V7_PURPOSE_PEAK_AGE)/V7_PURPOSE_WIDTH),1) | AB7: =IF(AND(IF(OR(P7="",NOT(ISNUMBER(P7))),0,MAX(0,MIN(24,(INT(VALUE(H7)/100)-INT(P7/100))*12+MOD(VALUE(H7),100)-MOD(P7,100))))>0,IF(OR(P7="",NOT(ISNUMBER(P7))),0,MAX(0,MIN(24,(INT(VALUE(H7)/100)-INT(P7/100))*12+MOD(VALUE(H7),100)-MOD(P7,100))))<=12),1+V7_LOCKOUT_AMP*EXP(-(IF(OR(P7="",NOT(ISNUMBER(P7))),0,MAX(0,MIN(24,(INT(VALUE(H7)/100)-INT(P7/100))*12+MOD(VALUE(H7),100)-MOD(P7,100)))))/V7_LOCKOUT_TAU),1) | AC7: =IF(IF(OR(O7="",NOT(ISNUMBER(O7))),360,MAX(0,MIN(480,(INT(O7/100)-INT(VALUE(H7)/100))*12+MOD(O7,100)-MOD(VALUE(H7),100))))>0,1+V7_MTY_AMP*MAX(0,(V7_MTY_CUTOFF-(IF(OR(O7="",NOT(ISNUMBER(O7))),360,MAX(0,MIN(480,(INT(O7/100)-INT(VALUE(H7)/100))*12+MOD(O7,100)-MOD(VALUE(H7),100))))))/V7_MTY_CUTOFF),1) | AD7: =MAX(V7_BURN_FLOOR,1-V7_BURN_SLOPE*MIN(1,MAX(0,R7))) | AE7: =IF(V7_USE_ISSUER=1,IFERROR(VLOOKUP(Q7,V7_ISSUER_TABLE,3,FALSE),1),1) | AF7: =PRODUCT(W7:AE7) | AG7: =MIN(V7_BASE_SMM*AF7,V7_SMM_CAP) | AH7: =1-(1-AG7)^12 | AI7: =IFERROR(LN(W7)/(LN(W7)+LN(X7)+LN(Y7)+LN(Z7)+LN(AA7)+LN(AB7)+LN(AC7)+LN(AD7))*(AH7-V7_BASE_CPR),0) | AJ7: =IFERROR(LN(X7)/(LN(W7)+LN(X7)+LN(Y7)+LN(Z7)+LN(AA7)+LN(AB7)+LN(AC7)+LN(AD7))*(AH7-V7_BASE_CPR),0) | AK7: =IFERROR(LN(Y7)/(LN(W7)+LN(X7)+LN(Y7)+LN(Z7)+LN(AA7)+LN(AB7)+LN(AC7)+LN(AD7))*(AH7-V7_BASE_CPR),0) | AL7: =IFERROR(LN(Z7)/(LN(W7)+LN(X7)+LN(Y7)+LN(Z7)+LN(AA7)+LN(AB7)+LN(AC7)+LN(AD7))*(AH7-V7_BASE_CPR),0) | AM7: =IFERROR(LN(AA7)/(LN(W7)+LN(X7)+LN(Y7)+LN(Z7)+LN(AA7)+LN(AB7)+LN(AC7)+LN(AD7))*(AH7-V7_BASE_CPR),0) | AN7: =IFERROR(LN(AB7)/(LN(W7)+LN(X7)+LN(Y7)+LN(Z7)+LN(AA7)+LN(AB7)+LN(AC7)+LN(AD7))*(AH7-V7_BASE_CPR),0) | AO7: =IFERROR(LN(AC7)/(LN(W7)+LN(X7)+LN(Y7)+LN(Z7)+LN(AA7)+LN(AB7)+LN(AC7)+LN(AD7))*(AH7-V7_BASE_CPR),0) | AP7: =IFERROR(LN(AD7)/(LN(W7)+LN(X7)+LN(Y7)+LN(Z7)+LN(AA7)+LN(AB7)+LN(AC7)+LN(AD7))*(AH7-V7_BASE_CPR),0) | AQ7: =V7_BASE_CPR+SUM(AI7:AP7)-AH7
A8: 3617X74P8_000000007343145 | B8: LUMENT_PRE21 | C8: 3617X74P8 | D8: LUMENT REAL ESTATE CAPITAL,LLC | E8: 232 | F8: RP | G8: 2013 | H8: 202602 | I8: 11587614 | J8: 3.42 | K8: 447 | L8: 6 | M8: 148 | N8: 1 | O8: 205108 | Q8: 3896 | R8: 0.0067567568 | S8: 0 | T8: =LN(1+I8) | U8: =J8*100-K8 | V8: =U8-12.5*(L8+1) | W8: =IF(M8<=V7_AGE_KNOT_X_0,V7_AGE_KNOT_Y_0,IF(M8>=V7_AGE_KNOT_X_5,V7_AGE_KNOT_Y_5,IF(M8<=V7_AGE_KNOT_X_1,V7_AGE_KNOT_Y_0+(M8-V7_AGE_KNOT_X_0)/(V7_AGE_KNOT_X_1-V7_AGE_KNOT_X_0)*(V7_AGE_KNOT_Y_1-V7_AGE_KNOT_Y_0),IF(M8<=V7_AGE_KNOT_X_2,V7_AGE_KNOT_Y_1+(M8-V7_AGE_KNOT_X_1)/(V7_AGE_KNOT_X_2-V7_AGE_KNOT_X_1)*(V7_AGE_KNOT_Y_2-V7_AGE_KNOT_Y_1),IF(M8<=V7_AGE_KNOT_X_3,V7_AGE_KNOT_Y_2+(M8-V7_AGE_KNOT_X_2)/(V7_AGE_KNOT_X_3-V7_AGE_KNOT_X_2)*(V7_AGE_KNOT_Y_3-V7_AGE_KNOT_Y_2),IF(M8<=V7_AGE_KNOT_X_4,V7_AGE_KNOT_Y_3+(M8-V7_AGE_KNOT_X_3)/(V7_AGE_KNOT_X_4-V7_AGE_KNOT_X_3)*(V7_AGE_KNOT_Y_4-V7_AGE_KNOT_Y_3),V7_AGE_KNOT_Y_4+(M8-V7_AGE_KNOT_X_4)/(V7_AGE_KNOT_X_5-V7_AGE_KNOT_X_4)*(V7_AGE_KNOT_Y_5-V7_AGE_KNOT_Y_4))))))) | X8: =V7_RATE_FLOOR+V7_RATE_ASYMPTOTE/(1+EXP(-(V8-V7_RATE_MID)/V7_RATE_SLOPE)) | Y8: =MAX(V7_SIZE_LOW,MIN(V7_SIZE_HIGH,V7_SIZE_INTERCEPT+V7_SIZE_SLOPE*(T8-V7_SIZE_LOG_ANCHOR))) | Z8: =IF(ISNUMBER(SEARCH("232",E8)),VLOOKUP("232",V7_PROGRAM_TABLE,2,FALSE),IF(ISNUMBER(SEARCH("538",E8)),VLOOKUP("538",V7_PROGRAM_TABLE,2,FALSE),IF(ISNUMBER(SEARCH("223a7",E8)),VLOOKUP("223a7",V7_PROGRAM_TABLE,2,FALSE),IF(ISNUMBER(SEARCH("223f",E8)),VLOOKUP("223f",V7_PROGRAM_TABLE,2,FALSE),V7_PROGRAM_DEFAULT)))) | AA8: =IF(S8=1,1+V7_PURPOSE_NC_BUMP*MAX(0,1-ABS(M8-V7_PURPOSE_PEAK_AGE)/V7_PURPOSE_WIDTH),1) | AB8: =IF(AND(IF(OR(P8="",NOT(ISNUMBER(P8))),0,MAX(0,MIN(24,(INT(VALUE(H8)/100)-INT(P8/100))*12+MOD(VALUE(H8),100)-MOD(P8,100))))>0,IF(OR(P8="",NOT(ISNUMBER(P8))),0,MAX(0,MIN(24,(INT(VALUE(H8)/100)-INT(P8/100))*12+MOD(VALUE(H8),100)-MOD(P8,100))))<=12),1+V7_LOCKOUT_AMP*EXP(-(IF(OR(P8="",NOT(ISNUMBER(P8))),0,MAX(0,MIN(24,(INT(VALUE(H8)/100)-INT(P8/100))*12+MOD(VALUE(H8),100)-MOD(P8,100)))))/V7_LOCKOUT_TAU),1) | AC8: =IF(IF(OR(O8="",NOT(ISNUMBER(O8))),360,MAX(0,MIN(480,(INT(O8/100)-INT(VALUE(H8)/100))*12+MOD(O8,100)-MOD(VALUE(H8),100))))>0,1+V7_MTY_AMP*MAX(0,(V7_MTY_CUTOFF-(IF(OR(O8="",NOT(ISNUMBER(O8))),360,MAX(0,MIN(480,(INT(O8/100)-INT(VALUE(H8)/100))*12+MOD(O8,100)-MOD(VALUE(H8),100))))))/V7_MTY_CUTOFF),1) | AD8: =MAX(V7_BURN_FLOOR,1-V7_BURN_SLOPE*MIN(1,MAX(0,R8))) | AE8: =IF(V7_USE_ISSUER=1,IFERROR(VLOOKUP(Q8,V7_ISSUER_TABLE,3,FALSE),1),1) | AF8: =PRODUCT(W8:AE8) | AG8: =MIN(V7_BASE_SMM*AF8,V7_SMM_CAP) | AH8: =1-(1-AG8)^12 | AI8: =IFERROR(LN(W8)/(LN(W8)+LN(X8)+LN(Y8)+LN(Z8)+LN(AA8)+LN(AB8)+LN(AC8)+LN(AD8))*(AH8-V7_BASE_CPR),0) | AJ8: =IFERROR(LN(X8)/(LN(W8)+LN(X8)+LN(Y8)+LN(Z8)+LN(AA8)+LN(AB8)+LN(AC8)+LN(AD8))*(AH8-V7_BASE_CPR),0) | AK8: =IFERROR(LN(Y8)/(LN(W8)+LN(X8)+LN(Y8)+LN(Z8)+LN(AA8)+LN(AB8)+LN(AC8)+LN(AD8))*(AH8-V7_BASE_CPR),0) | AL8: =IFERROR(LN(Z8)/(LN(W8)+LN(X8)+LN(Y8)+LN(Z8)+LN(AA8)+LN(AB8)+LN(AC8)+LN(AD8))*(AH8-V7_BASE_CPR),0) | AM8: =IFERROR(LN(AA8)/(LN(W8)+LN(X8)+LN(Y8)+LN(Z8)+LN(AA8)+LN(AB8)+LN(AC8)+LN(AD8))*(AH8-V7_BASE_CPR),0) | AN8: =IFERROR(LN(AB8)/(LN(W8)+LN(X8)+LN(Y8)+LN(Z8)+LN(AA8)+LN(AB8)+LN(AC8)+LN(AD8))*(AH8-V7_BASE_CPR),0) | AO8: =IFERROR(LN(AC8)/(LN(W8)+LN(X8)+LN(Y8)+LN(Z8)+LN(AA8)+LN(AB8)+LN(AC8)+LN(AD8))*(AH8-V7_BASE_CPR),0) | AP8: =IFERROR(LN(AD8)/(LN(W8)+LN(X8)+LN(Y8)+LN(Z8)+LN(AA8)+LN(AB8)+LN(AC8)+LN(AD8))*(AH8-V7_BASE_CPR),0) | AQ8: =V7_BASE_CPR+SUM(AI8:AP8)-AH8
A9: 3620AEYZ7_000000010535179 | B9: LUMENT_PRE21 | C9: 3620AEYZ7 | D9: LUMENT REAL ESTATE CAPITAL,LLC | E9: OTHER | F9: OTHER | G9: 2010 | H9: 202602 | I9: 7782165.9 | J9: 3.38 | K9: 447 | L9: 0 | M9: 182 | N9: 36 | O9: 205206 | Q9: 3896 | R9: 0.1978022 | S9: 0 | T9: =LN(1+I9) | U9: =J9*100-K9 | V9: =U9-12.5*(L9+1) | W9: =IF(M9<=V7_AGE_KNOT_X_0,V7_AGE_KNOT_Y_0,IF(M9>=V7_AGE_KNOT_X_5,V7_AGE_KNOT_Y_5,IF(M9<=V7_AGE_KNOT_X_1,V7_AGE_KNOT_Y_0+(M9-V7_AGE_KNOT_X_0)/(V7_AGE_KNOT_X_1-V7_AGE_KNOT_X_0)*(V7_AGE_KNOT_Y_1-V7_AGE_KNOT_Y_0),IF(M9<=V7_AGE_KNOT_X_2,V7_AGE_KNOT_Y_1+(M9-V7_AGE_KNOT_X_1)/(V7_AGE_KNOT_X_2-V7_AGE_KNOT_X_1)*(V7_AGE_KNOT_Y_2-V7_AGE_KNOT_Y_1),IF(M9<=V7_AGE_KNOT_X_3,V7_AGE_KNOT_Y_2+(M9-V7_AGE_KNOT_X_2)/(V7_AGE_KNOT_X_3-V7_AGE_KNOT_X_2)*(V7_AGE_KNOT_Y_3-V7_AGE_KNOT_Y_2),IF(M9<=V7_AGE_KNOT_X_4,V7_AGE_KNOT_Y_3+(M9-V7_AGE_KNOT_X_3)/(V7_AGE_KNOT_X_4-V7_AGE_KNOT_X_3)*(V7_AGE_KNOT_Y_4-V7_AGE_KNOT_Y_3),V7_AGE_KNOT_Y_4+(M9-V7_AGE_KNOT_X_4)/(V7_AGE_KNOT_X_5-V7_AGE_KNOT_X_4)*(V7_AGE_KNOT_Y_5-V7_AGE_KNOT_Y_4))))))) | X9: =V7_RATE_FLOOR+V7_RATE_ASYMPTOTE/(1+EXP(-(V9-V7_RATE_MID)/V7_RATE_SLOPE)) | Y9: =MAX(V7_SIZE_LOW,MIN(V7_SIZE_HIGH,V7_SIZE_INTERCEPT+V7_SIZE_SLOPE*(T9-V7_SIZE_LOG_ANCHOR))) | Z9: =IF(ISNUMBER(SEARCH("232",E9)),VLOOKUP("232",V7_PROGRAM_TABLE,2,FALSE),IF(ISNUMBER(SEARCH("538",E9)),VLOOKUP("538",V7_PROGRAM_TABLE,2,FALSE),IF(ISNUMBER(SEARCH("223a7",E9)),VLOOKUP("223a7",V7_PROGRAM_TABLE,2,FALSE),IF(ISNUMBER(SEARCH("223f",E9)),VLOOKUP("223f",V7_PROGRAM_TABLE,2,FALSE),V7_PROGRAM_DEFAULT)))) | AA9: =IF(S9=1,1+V7_PURPOSE_NC_BUMP*MAX(0,1-ABS(M9-V7_PURPOSE_PEAK_AGE)/V7_PURPOSE_WIDTH),1) | AB9: =IF(AND(IF(OR(P9="",NOT(ISNUMBER(P9))),0,MAX(0,MIN(24,(INT(VALUE(H9)/100)-INT(P9/100))*12+MOD(VALUE(H9),100)-MOD(P9,100))))>0,IF(OR(P9="",NOT(ISNUMBER(P9))),0,MAX(0,MIN(24,(INT(VALUE(H9)/100)-INT(P9/100))*12+MOD(VALUE(H9),100)-MOD(P9,100))))<=12),1+V7_LOCKOUT_AMP*EXP(-(IF(OR(P9="",NOT(ISNUMBER(P9))),0,MAX(0,MIN(24,(INT(VALUE(H9)/100)-INT(P9/100))*12+MOD(VALUE(H9),100)-MOD(P9,100)))))/V7_LOCKOUT_TAU),1) | AC9: =IF(IF(OR(O9="",NOT(ISNUMBER(O9))),360,MAX(0,MIN(480,(INT(O9/100)-INT(VALUE(H9)/100))*12+MOD(O9,100)-MOD(VALUE(H9),100))))>0,1+V7_MTY_AMP*MAX(0,(V7_MTY_CUTOFF-(IF(OR(O9="",NOT(ISNUMBER(O9))),360,MAX(0,MIN(480,(INT(O9/100)-INT(VALUE(H9)/100))*12+MOD(O9,100)-MOD(VALUE(H9),100))))))/V7_MTY_CUTOFF),1) | AD9: =MAX(V7_BURN_FLOOR,1-V7_BURN_SLOPE*MIN(1,MAX(0,R9))) | AE9: =IF(V7_USE_ISSUER=1,IFERROR(VLOOKUP(Q9,V7_ISSUER_TABLE,3,FALSE),1),1) | AF9: =PRODUCT(W9:AE9) | AG9: =MIN(V7_BASE_SMM*AF9,V7_SMM_CAP) | AH9: =1-(1-AG9)^12 | AI9: =IFERROR(LN(W9)/(LN(W9)+LN(X9)+LN(Y9)+LN(Z9)+LN(AA9)+LN(AB9)+LN(AC9)+LN(AD9))*(AH9-V7_BASE_CPR),0) | AJ9: =IFERROR(LN(X9)/(LN(W9)+LN(X9)+LN(Y9)+LN(Z9)+LN(AA9)+LN(AB9)+LN(AC9)+LN(AD9))*(AH9-V7_BASE_CPR),0) | AK9: =IFERROR(LN(Y9)/(LN(W9)+LN(X9)+LN(Y9)+LN(Z9)+LN(AA9)+LN(AB9)+LN(AC9)+LN(AD9))*(AH9-V7_BASE_CPR),0) | AL9: =IFERROR(LN(Z9)/(LN(W9)+LN(X9)+LN(Y9)+LN(Z9)+LN(AA9)+LN(AB9)+LN(AC9)+LN(AD9))*(AH9-V7_BASE_CPR),0) | AM9: =IFERROR(LN(AA9)/(LN(W9)+LN(X9)+LN(Y9)+LN(Z9)+LN(AA9)+LN(AB9)+LN(AC9)+LN(AD9))*(AH9-V7_BASE_CPR),0) | AN9: =IFERROR(LN(AB9)/(LN(W9)+LN(X9)+LN(Y9)+LN(Z9)+LN(AA9)+LN(AB9)+LN(AC9)+LN(AD9))*(AH9-V7_BASE_CPR),0) | AO9: =IFERROR(LN(AC9)/(LN(W9)+LN(X9)+LN(Y9)+LN(Z9)+LN(AA9)+LN(AB9)+LN(AC9)+LN(AD9))*(AH9-V7_BASE_CPR),0) | AP9: =IFERROR(LN(AD9)/(LN(W9)+LN(X9)+LN(Y9)+LN(Z9)+LN(AA9)+LN(AB9)+LN(AC9)+LN(AD9))*(AH9-V7_BASE_CPR),0) | AQ9: =V7_BASE_CPR+SUM(AI9:AP9)-AH9
A10: 3618BNC43_000000001211581 | B10: LUMENT_POST21 | C10: 3618BNC43 | D10: LUMENT REAL ESTATE CAPITAL,LLC | E10: 223f | F10: RP | G10: 2023 | H10: 202602 | I10: 30791262 | J10: 5.36 | K10: 447 | L10: 8 | M10: 32 | N10: 0 | O10: 205707 | Q10: 3896 | R10: 0 | S10: 0 | T10: =LN(1+I10) | U10: =J10*100-K10 | V10: =U10-12.5*(L10+1) | W10: =IF(M10<=V7_AGE_KNOT_X_0,V7_AGE_KNOT_Y_0,IF(M10>=V7_AGE_KNOT_X_5,V7_AGE_KNOT_Y_5,IF(M10<=V7_AGE_KNOT_X_1,V7_AGE_KNOT_Y_0+(M10-V7_AGE_KNOT_X_0)/(V7_AGE_KNOT_X_1-V7_AGE_KNOT_X_0)*(V7_AGE_KNOT_Y_1-V7_AGE_KNOT_Y_0),IF(M10<=V7_AGE_KNOT_X_2,V7_AGE_KNOT_Y_1+(M10-V7_AGE_KNOT_X_1)/(V7_AGE_KNOT_X_2-V7_AGE_KNOT_X_1)*(V7_AGE_KNOT_Y_2-V7_AGE_KNOT_Y_1),IF(M10<=V7_AGE_KNOT_X_3,V7_AGE_KNOT_Y_2+(M10-V7_AGE_KNOT_X_2)/(V7_AGE_KNOT_X_3-V7_AGE_KNOT_X_2)*(V7_AGE_KNOT_Y_3-V7_AGE_KNOT_Y_2),IF(M10<=V7_AGE_KNOT_X_4,V7_AGE_KNOT_Y_3+(M10-V7_AGE_KNOT_X_3)/(V7_AGE_KNOT_X_4-V7_AGE_KNOT_X_3)*(V7_AGE_KNOT_Y_4-V7_AGE_KNOT_Y_3),V7_AGE_KNOT_Y_4+(M10-V7_AGE_KNOT_X_4)/(V7_AGE_KNOT_X_5-V7_AGE_KNOT_X_4)*(V7_AGE_KNOT_Y_5-V7_AGE_KNOT_Y_4))))))) | X10: =V7_RATE_FLOOR+V7_RATE_ASYMPTOTE/(1+EXP(-(V10-V7_RATE_MID)/V7_RATE_SLOPE)) | Y10: =MAX(V7_SIZE_LOW,MIN(V7_SIZE_HIGH,V7_SIZE_INTERCEPT+V7_SIZE_SLOPE*(T10-V7_SIZE_LOG_ANCHOR))) | Z10: =IF(ISNUMBER(SEARCH("232",E10)),VLOOKUP("232",V7_PROGRAM_TABLE,2,FALSE),IF(ISNUMBER(SEARCH("538",E10)),VLOOKUP("538",V7_PROGRAM_TABLE,2,FALSE),IF(ISNUMBER(SEARCH("223a7",E10)),VLOOKUP("223a7",V7_PROGRAM_TABLE,2,FALSE),IF(ISNUMBER(SEARCH("223f",E10)),VLOOKUP("223f",V7_PROGRAM_TABLE,2,FALSE),V7_PROGRAM_DEFAULT)))) | AA10: =IF(S10=1,1+V7_PURPOSE_NC_BUMP*MAX(0,1-ABS(M10-V7_PURPOSE_PEAK_AGE)/V7_PURPOSE_WIDTH),1) | AB10: =IF(AND(IF(OR(P10="",NOT(ISNUMBER(P10))),0,MAX(0,MIN(24,(INT(VALUE(H10)/100)-INT(P10/100))*12+MOD(VALUE(H10),100)-MOD(P10,100))))>0,IF(OR(P10="",NOT(ISNUMBER(P10))),0,MAX(0,MIN(24,(INT(VALUE(H10)/100)-INT(P10/100))*12+MOD(VALUE(H10),100)-MOD(P10,100))))<=12),1+V7_LOCKOUT_AMP*EXP(-(IF(OR(P10="",NOT(ISNUMBER(P10))),0,MAX(0,MIN(24,(INT(VALUE(H10)/100)-INT(P10/100))*12+MOD(VALUE(H10),100)-MOD(P10,100)))))/V7_LOCKOUT_TAU),1) | AC10: =IF(IF(OR(O10="",NOT(ISNUMBER(O10))),360,MAX(0,MIN(480,(INT(O10/100)-INT(VALUE(H10)/100))*12+MOD(O10,100)-MOD(VALUE(H10),100))))>0,1+V7_MTY_AMP*MAX(0,(V7_MTY_CUTOFF-(IF(OR(O10="",NOT(ISNUMBER(O10))),360,MAX(0,MIN(480,(INT(O10/100)-INT(VALUE(H10)/100))*12+MOD(O10,100)-MOD(VALUE(H10),100))))))/V7_MTY_CUTOFF),1) | AD10: =MAX(V7_BURN_FLOOR,1-V7_BURN_SLOPE*MIN(1,MAX(0,R10))) | AE10: =IF(V7_USE_ISSUER=1,IFERROR(VLOOKUP(Q10,V7_ISSUER_TABLE,3,FALSE),1),1) | AF10: =PRODUCT(W10:AE10) | AG10: =MIN(V7_BASE_SMM*AF10,V7_SMM_CAP) | AH10: =1-(1-AG10)^12 | AI10: =IFERROR(LN(W10)/(LN(W10)+LN(X10)+LN(Y10)+LN(Z10)+LN(AA10)+LN(AB10)+LN(AC10)+LN(AD10))*(AH10-V7_BASE_CPR),0) | AJ10: =IFERROR(LN(X10)/(LN(W10)+LN(X10)+LN(Y10)+LN(Z10)+LN(AA10)+LN(AB10)+LN(AC10)+LN(AD10))*(AH10-V7_BASE_CPR),0) | AK10: =IFERROR(LN(Y10)/(LN(W10)+LN(X10)+LN(Y10)+LN(Z10)+LN(AA10)+LN(AB10)+LN(AC10)+LN(AD10))*(AH10-V7_BASE_CPR),0) | AL10: =IFERROR(LN(Z10)/(LN(W10)+LN(X10)+LN(Y10)+LN(Z10)+LN(AA10)+LN(AB10)+LN(AC10)+LN(AD10))*(AH10-V7_BASE_CPR),0) | AM10: =IFERROR(LN(AA10)/(LN(W10)+LN(X10)+LN(Y10)+LN(Z10)+LN(AA10)+LN(AB10)+LN(AC10)+LN(AD10))*(AH10-V7_BASE_CPR),0) | AN10: =IFERROR(LN(AB10)/(LN(W10)+LN(X10)+LN(Y10)+LN(Z10)+LN(AA10)+LN(AB10)+LN(AC10)+LN(AD10))*(AH10-V7_BASE_CPR),0) | AO10: =IFERROR(LN(AC10)/(LN(W10)+LN(X10)+LN(Y10)+LN(Z10)+LN(AA10)+LN(AB10)+LN(AC10)+LN(AD10))*(AH10-V7_BASE_CPR),0) | AP10: =IFERROR(LN(AD10)/(LN(W10)+LN(X10)+LN(Y10)+LN(Z10)+LN(AA10)+LN(AB10)+LN(AC10)+LN(AD10))*(AH10-V7_BASE_CPR),0) | AQ10: =V7_BASE_CPR+SUM(AI10:AP10)-AH10
A11: 3618KLMG9_000000001211630 | B11: LUMENT_POST21 | C11: 3618KLMG9 | D11: LUMENT REAL ESTATE CAPITAL,LLC | E11: 223f | F11: RP | G11: 2025 | H11: 202602 | I11: 59508580 | J11: 5.65 | K11: 447 | L11: 10 | M11: 4 | N11: 0 | O11: 206011 | Q11: 3896 | R11: 0 | S11: 0 | T11: =LN(1+I11) | U11: =J11*100-K11 | V11: =U11-12.5*(L11+1) | W11: =IF(M11<=V7_AGE_KNOT_X_0,V7_AGE_KNOT_Y_0,IF(M11>=V7_AGE_KNOT_X_5,V7_AGE_KNOT_Y_5,IF(M11<=V7_AGE_KNOT_X_1,V7_AGE_KNOT_Y_0+(M11-V7_AGE_KNOT_X_0)/(V7_AGE_KNOT_X_1-V7_AGE_KNOT_X_0)*(V7_AGE_KNOT_Y_1-V7_AGE_KNOT_Y_0),IF(M11<=V7_AGE_KNOT_X_2,V7_AGE_KNOT_Y_1+(M11-V7_AGE_KNOT_X_1)/(V7_AGE_KNOT_X_2-V7_AGE_KNOT_X_1)*(V7_AGE_KNOT_Y_2-V7_AGE_KNOT_Y_1),IF(M11<=V7_AGE_KNOT_X_3,V7_AGE_KNOT_Y_2+(M11-V7_AGE_KNOT_X_2)/(V7_AGE_KNOT_X_3-V7_AGE_KNOT_X_2)*(V7_AGE_KNOT_Y_3-V7_AGE_KNOT_Y_2),IF(M11<=V7_AGE_KNOT_X_4,V7_AGE_KNOT_Y_3+(M11-V7_AGE_KNOT_X_3)/(V7_AGE_KNOT_X_4-V7_AGE_KNOT_X_3)*(V7_AGE_KNOT_Y_4-V7_AGE_KNOT_Y_3),V7_AGE_KNOT_Y_4+(M11-V7_AGE_KNOT_X_4)/(V7_AGE_KNOT_X_5-V7_AGE_KNOT_X_4)*(V7_AGE_KNOT_Y_5-V7_AGE_KNOT_Y_4))))))) | X11: =V7_RATE_FLOOR+V7_RATE_ASYMPTOTE/(1+EXP(-(V11-V7_RATE_MID)/V7_RATE_SLOPE)) | Y11: =MAX(V7_SIZE_LOW,MIN(V7_SIZE_HIGH,V7_SIZE_INTERCEPT+V7_SIZE_SLOPE*(T11-V7_SIZE_LOG_ANCHOR))) | Z11: =IF(ISNUMBER(SEARCH("232",E11)),VLOOKUP("232",V7_PROGRAM_TABLE,2,FALSE),IF(ISNUMBER(SEARCH("538",E11)),VLOOKUP("538",V7_PROGRAM_TABLE,2,FALSE),IF(ISNUMBER(SEARCH("223a7",E11)),VLOOKUP("223a7",V7_PROGRAM_TABLE,2,FALSE),IF(ISNUMBER(SEARCH("223f",E11)),VLOOKUP("223f",V7_PROGRAM_TABLE,2,FALSE),V7_PROGRAM_DEFAULT)))) | AA11: =IF(S11=1,1+V7_PURPOSE_NC_BUMP*MAX(0,1-ABS(M11-V7_PURPOSE_PEAK_AGE)/V7_PURPOSE_WIDTH),1) | AB11: =IF(AND(IF(OR(P11="",NOT(ISNUMBER(P11))),0,MAX(0,MIN(24,(INT(VALUE(H11)/100)-INT(P11/100))*12+MOD(VALUE(H11),100)-MOD(P11,100))))>0,IF(OR(P11="",NOT(ISNUMBER(P11))),0,MAX(0,MIN(24,(INT(VALUE(H11)/100)-INT(P11/100))*12+MOD(VALUE(H11),100)-MOD(P11,100))))<=12),1+V7_LOCKOUT_AMP*EXP(-(IF(OR(P11="",NOT(ISNUMBER(P11))),0,MAX(0,MIN(24,(INT(VALUE(H11)/100)-INT(P11/100))*12+MOD(VALUE(H11),100)-MOD(P11,100)))))/V7_LOCKOUT_TAU),1) | AC11: =IF(IF(OR(O11="",NOT(ISNUMBER(O11))),360,MAX(0,MIN(480,(INT(O11/100)-INT(VALUE(H11)/100))*12+MOD(O11,100)-MOD(VALUE(H11),100))))>0,1+V7_MTY_AMP*MAX(0,(V7_MTY_CUTOFF-(IF(OR(O11="",NOT(ISNUMBER(O11))),360,MAX(0,MIN(480,(INT(O11/100)-INT(VALUE(H11)/100))*12+MOD(O11,100)-MOD(VALUE(H11),100))))))/V7_MTY_CUTOFF),1) | AD11: =MAX(V7_BURN_FLOOR,1-V7_BURN_SLOPE*MIN(1,MAX(0,R11))) | AE11: =IF(V7_USE_ISSUER=1,IFERROR(VLOOKUP(Q11,V7_ISSUER_TABLE,3,FALSE),1),1) | AF11: =PRODUCT(W11:AE11) | AG11: =MIN(V7_BASE_SMM*AF11,V7_SMM_CAP) | AH11: =1-(1-AG11)^12 | AI11: =IFERROR(LN(W11)/(LN(W11)+LN(X11)+LN(Y11)+LN(Z11)+LN(AA11)+LN(AB11)+LN(AC11)+LN(AD11))*(AH11-V7_BASE_CPR),0) | AJ11: =IFERROR(LN(X11)/(LN(W11)+LN(X11)+LN(Y11)+LN(Z11)+LN(AA11)+LN(AB11)+LN(AC11)+LN(AD11))*(AH11-V7_BASE_CPR),0) | AK11: =IFERROR(LN(Y11)/(LN(W11)+LN(X11)+LN(Y11)+LN(Z11)+LN(AA11)+LN(AB11)+LN(AC11)+LN(AD11))*(AH11-V7_BASE_CPR),0) | AL11: =IFERROR(LN(Z11)/(LN(W11)+LN(X11)+LN(Y11)+LN(Z11)+LN(AA11)+LN(AB11)+LN(AC11)+LN(AD11))*(AH11-V7_BASE_CPR),0) | AM11: =IFERROR(LN(AA11)/(LN(W11)+LN(X11)+LN(Y11)+LN(Z11)+LN(AA11)+LN(AB11)+LN(AC11)+LN(AD11))*(AH11-V7_BASE_CPR),0) | AN11: =IFERROR(LN(AB11)/(LN(W11)+LN(X11)+LN(Y11)+LN(Z11)+LN(AA11)+LN(AB11)+LN(AC11)+LN(AD11))*(AH11-V7_BASE_CPR),0) | AO11: =IFERROR(LN(AC11)/(LN(W11)+LN(X11)+LN(Y11)+LN(Z11)+LN(AA11)+LN(AB11)+LN(AC11)+LN(AD11))*(AH11-V7_BASE_CPR),0) | AP11: =IFERROR(LN(AD11)/(LN(W11)+LN(X11)+LN(Y11)+LN(Z11)+LN(AA11)+LN(AB11)+LN(AC11)+LN(AD11))*(AH11-V7_BASE_CPR),0) | AQ11: =V7_BASE_CPR+SUM(AI11:AP11)-AH11
A12: 36297HB49_000000010222024 | B12: LUMENT_PRE21 | C12: 36297HB49 | D12: LUMENT REAL ESTATE CAPITAL,LLC | E12: 232 | F12: RP | G12: 2009 | H12: 202602 | I12: 2318598.5 | J12: 5.65 | K12: 447 | L12: 0 | M12: 200 | N12: 84 | O12: 203907 | P12: 201108 | Q12: 3896 | R12: 0.42 | S12: 0 | T12: =LN(1+I12) | U12: =J12*100-K12 | V12: =U12-12.5*(L12+1) | W12: =IF(M12<=V7_AGE_KNOT_X_0,V7_AGE_KNOT_Y_0,IF(M12>=V7_AGE_KNOT_X_5,V7_AGE_KNOT_Y_5,IF(M12<=V7_AGE_KNOT_X_1,V7_AGE_KNOT_Y_0+(M12-V7_AGE_KNOT_X_0)/(V7_AGE_KNOT_X_1-V7_AGE_KNOT_X_0)*(V7_AGE_KNOT_Y_1-V7_AGE_KNOT_Y_0),IF(M12<=V7_AGE_KNOT_X_2,V7_AGE_KNOT_Y_1+(M12-V7_AGE_KNOT_X_1)/(V7_AGE_KNOT_X_2-V7_AGE_KNOT_X_1)*(V7_AGE_KNOT_Y_2-V7_AGE_KNOT_Y_1),IF(M12<=V7_AGE_KNOT_X_3,V7_AGE_KNOT_Y_2+(M12-V7_AGE_KNOT_X_2)/(V7_AGE_KNOT_X_3-V7_AGE_KNOT_X_2)*(V7_AGE_KNOT_Y_3-V7_AGE_KNOT_Y_2),IF(M12<=V7_AGE_KNOT_X_4,V7_AGE_KNOT_Y_3+(M12-V7_AGE_KNOT_X_3)/(V7_AGE_KNOT_X_4-V7_AGE_KNOT_X_3)*(V7_AGE_KNOT_Y_4-V7_AGE_KNOT_Y_3),V7_AGE_KNOT_Y_4+(M12-V7_AGE_KNOT_X_4)/(V7_AGE_KNOT_X_5-V7_AGE_KNOT_X_4)*(V7_AGE_KNOT_Y_5-V7_AGE_KNOT_Y_4))))))) | X12: =V7_RATE_FLOOR+V7_RATE_ASYMPTOTE/(1+EXP(-(V12-V7_RATE_MID)/V7_RATE_SLOPE)) | Y12: =MAX(V7_SIZE_LOW,MIN(V7_SIZE_HIGH,V7_SIZE_INTERCEPT+V7_SIZE_SLOPE*(T12-V7_SIZE_LOG_ANCHOR))) | Z12: =IF(ISNUMBER(SEARCH("232",E12)),VLOOKUP("232",V7_PROGRAM_TABLE,2,FALSE),IF(ISNUMBER(SEARCH("538",E12)),VLOOKUP("538",V7_PROGRAM_TABLE,2,FALSE),IF(ISNUMBER(SEARCH("223a7",E12)),VLOOKUP("223a7",V7_PROGRAM_TABLE,2,FALSE),IF(ISNUMBER(SEARCH("223f",E12)),VLOOKUP("223f",V7_PROGRAM_TABLE,2,FALSE),V7_PROGRAM_DEFAULT)))) | AA12: =IF(S12=1,1+V7_PURPOSE_NC_BUMP*MAX(0,1-ABS(M12-V7_PURPOSE_PEAK_AGE)/V7_PURPOSE_WIDTH),1) | AB12: =IF(AND(IF(OR(P12="",NOT(ISNUMBER(P12))),0,MAX(0,MIN(24,(INT(VALUE(H12)/100)-INT(P12/100))*12+MOD(VALUE(H12),100)-MOD(P12,100))))>0,IF(OR(P12="",NOT(ISNUMBER(P12))),0,MAX(0,MIN(24,(INT(VALUE(H12)/100)-INT(P12/100))*12+MOD(VALUE(H12),100)-MOD(P12,100))))<=12),1+V7_LOCKOUT_AMP*EXP(-(IF(OR(P12="",NOT(ISNUMBER(P12))),0,MAX(0,MIN(24,(INT(VALUE(H12)/100)-INT(P12/100))*12+MOD(VALUE(H12),100)-MOD(P12,100)))))/V7_LOCKOUT_TAU),1) | AC12: =IF(IF(OR(O12="",NOT(ISNUMBER(O12))),360,MAX(0,MIN(480,(INT(O12/100)-INT(VALUE(H12)/100))*12+MOD(O12,100)-MOD(VALUE(H12),100))))>0,1+V7_MTY_AMP*MAX(0,(V7_MTY_CUTOFF-(IF(OR(O12="",NOT(ISNUMBER(O12))),360,MAX(0,MIN(480,(INT(O12/100)-INT(VALUE(H12)/100))*12+MOD(O12,100)-MOD(VALUE(H12),100))))))/V7_MTY_CUTOFF),1) | AD12: =MAX(V7_BURN_FLOOR,1-V7_BURN_SLOPE*MIN(1,MAX(0,R12))) | AE12: =IF(V7_USE_ISSUER=1,IFERROR(VLOOKUP(Q12,V7_ISSUER_TABLE,3,FALSE),1),1) | AF12: =PRODUCT(W12:AE12) | AG12: =MIN(V7_BASE_SMM*AF12,V7_SMM_CAP) | AH12: =1-(1-AG12)^12 | AI12: =IFERROR(LN(W12)/(LN(W12)+LN(X12)+LN(Y12)+LN(Z12)+LN(AA12)+LN(AB12)+LN(AC12)+LN(AD12))*(AH12-V7_BASE_CPR),0) | AJ12: =IFERROR(LN(X12)/(LN(W12)+LN(X12)+LN(Y12)+LN(Z12)+LN(AA12)+LN(AB12)+LN(AC12)+LN(AD12))*(AH12-V7_BASE_CPR),0) | AK12: =IFERROR(LN(Y12)/(LN(W12)+LN(X12)+LN(Y12)+LN(Z12)+LN(AA12)+LN(AB12)+LN(AC12)+LN(AD12))*(AH12-V7_BASE_CPR),0) | AL12: =IFERROR(LN(Z12)/(LN(W12)+LN(X12)+LN(Y12)+LN(Z12)+LN(AA12)+LN(AB12)+LN(AC12)+LN(AD12))*(AH12-V7_BASE_CPR),0) | AM12: =IFERROR(LN(AA12)/(LN(W12)+LN(X12)+LN(Y12)+LN(Z12)+LN(AA12)+LN(AB12)+LN(AC12)+LN(AD12))*(AH12-V7_BASE_CPR),0) | AN12: =IFERROR(LN(AB12)/(LN(W12)+LN(X12)+LN(Y12)+LN(Z12)+LN(AA12)+LN(AB12)+LN(AC12)+LN(AD12))*(AH12-V7_BASE_CPR),0) | AO12: =IFERROR(LN(AC12)/(LN(W12)+LN(X12)+LN(Y12)+LN(Z12)+LN(AA12)+LN(AB12)+LN(AC12)+LN(AD12))*(AH12-V7_BASE_CPR),0) | AP12: =IFERROR(LN(AD12)/(LN(W12)+LN(X12)+LN(Y12)+LN(Z12)+LN(AA12)+LN(AB12)+LN(AC12)+LN(AD12))*(AH12-V7_BASE_CPR),0) | AQ12: =V7_BASE_CPR+SUM(AI12:AP12)-AH12
A13: 3618HNAN7_000000006122229 | B13: LUMENT_POST21 | C13: 3618HNAN7 | D13: LUMENT REAL ESTATE CAPITAL,LLC | E13: 232 | F13: RP | G13: 2024 | H13: 202602 | I13: 10649283 | J13: 5.35 | K13: 447 | L13: 9 | M13: 14 | N13: 0 | O13: 206001 | Q13: 3896 | R13: 0 | S13: 0 | T13: =LN(1+I13) | U13: =J13*100-K13 | V13: =U13-12.5*(L13+1) | W13: =IF(M13<=V7_AGE_KNOT_X_0,V7_AGE_KNOT_Y_0,IF(M13>=V7_AGE_KNOT_X_5,V7_AGE_KNOT_Y_5,IF(M13<=V7_AGE_KNOT_X_1,V7_AGE_KNOT_Y_0+(M13-V7_AGE_KNOT_X_0)/(V7_AGE_KNOT_X_1-V7_AGE_KNOT_X_0)*(V7_AGE_KNOT_Y_1-V7_AGE_KNOT_Y_0),IF(M13<=V7_AGE_KNOT_X_2,V7_AGE_KNOT_Y_1+(M13-V7_AGE_KNOT_X_1)/(V7_AGE_KNOT_X_2-V7_AGE_KNOT_X_1)*(V7_AGE_KNOT_Y_2-V7_AGE_KNOT_Y_1),IF(M13<=V7_AGE_KNOT_X_3,V7_AGE_KNOT_Y_2+(M13-V7_AGE_KNOT_X_2)/(V7_AGE_KNOT_X_3-V7_AGE_KNOT_X_2)*(V7_AGE_KNOT_Y_3-V7_AGE_KNOT_Y_2),IF(M13<=V7_AGE_KNOT_X_4,V7_AGE_KNOT_Y_3+(M13-V7_AGE_KNOT_X_3)/(V7_AGE_KNOT_X_4-V7_AGE_KNOT_X_3)*(V7_AGE_KNOT_Y_4-V7_AGE_KNOT_Y_3),V7_AGE_KNOT_Y_4+(M13-V7_AGE_KNOT_X_4)/(V7_AGE_KNOT_X_5-V7_AGE_KNOT_X_4)*(V7_AGE_KNOT_Y_5-V7_AGE_KNOT_Y_4))))))) | X13: =V7_RATE_FLOOR+V7_RATE_ASYMPTOTE/(1+EXP(-(V13-V7_RATE_MID)/V7_RATE_SLOPE)) | Y13: =MAX(V7_SIZE_LOW,MIN(V7_SIZE_HIGH,V7_SIZE_INTERCEPT+V7_SIZE_SLOPE*(T13-V7_SIZE_LOG_ANCHOR))) | Z13: =IF(ISNUMBER(SEARCH("232",E13)),VLOOKUP("232",V7_PROGRAM_TABLE,2,FALSE),IF(ISNUMBER(SEARCH("538",E13)),VLOOKUP("538",V7_PROGRAM_TABLE,2,FALSE),IF(ISNUMBER(SEARCH("223a7",E13)),VLOOKUP("223a7",V7_PROGRAM_TABLE,2,FALSE),IF(ISNUMBER(SEARCH("223f",E13)),VLOOKUP("223f",V7_PROGRAM_TABLE,2,FALSE),V7_PROGRAM_DEFAULT)))) | AA13: =IF(S13=1,1+V7_PURPOSE_NC_BUMP*MAX(0,1-ABS(M13-V7_PURPOSE_PEAK_AGE)/V7_PURPOSE_WIDTH),1) | AB13: =IF(AND(IF(OR(P13="",NOT(ISNUMBER(P13))),0,MAX(0,MIN(24,(INT(VALUE(H13)/100)-INT(P13/100))*12+MOD(VALUE(H13),100)-MOD(P13,100))))>0,IF(OR(P13="",NOT(ISNUMBER(P13))),0,MAX(0,MIN(24,(INT(VALUE(H13)/100)-INT(P13/100))*12+MOD(VALUE(H13),100)-MOD(P13,100))))<=12),1+V7_LOCKOUT_AMP*EXP(-(IF(OR(P13="",NOT(ISNUMBER(P13))),0,MAX(0,MIN(24,(INT(VALUE(H13)/100)-INT(P13/100))*12+MOD(VALUE(H13),100)-MOD(P13,100)))))/V7_LOCKOUT_TAU),1) | AC13: =IF(IF(OR(O13="",NOT(ISNUMBER(O13))),360,MAX(0,MIN(480,(INT(O13/100)-INT(VALUE(H13)/100))*12+MOD(O13,100)-MOD(VALUE(H13),100))))>0,1+V7_MTY_AMP*MAX(0,(V7_MTY_CUTOFF-(IF(OR(O13="",NOT(ISNUMBER(O13))),360,MAX(0,MIN(480,(INT(O13/100)-INT(VALUE(H13)/100))*12+MOD(O13,100)-MOD(VALUE(H13),100))))))/V7_MTY_CUTOFF),1) | AD13: =MAX(V7_BURN_FLOOR,1-V7_BURN_SLOPE*MIN(1,MAX(0,R13))) | AE13: =IF(V7_USE_ISSUER=1,IFERROR(VLOOKUP(Q13,V7_ISSUER_TABLE,3,FALSE),1),1) | AF13: =PRODUCT(W13:AE13) | AG13: =MIN(V7_BASE_SMM*AF13,V7_SMM_CAP) | AH13: =1-(1-AG13)^12 | AI13: =IFERROR(LN(W13)/(LN(W13)+LN(X13)+LN(Y13)+LN(Z13)+LN(AA13)+LN(AB13)+LN(AC13)+LN(AD13))*(AH13-V7_BASE_CPR),0) | AJ13: =IFERROR(LN(X13)/(LN(W13)+LN(X13)+LN(Y13)+LN(Z13)+LN(AA13)+LN(AB13)+LN(AC13)+LN(AD13))*(AH13-V7_BASE_CPR),0) | AK13: =IFERROR(LN(Y13)/(LN(W13)+LN(X13)+LN(Y13)+LN(Z13)+LN(AA13)+LN(AB13)+LN(AC13)+LN(AD13))*(AH13-V7_BASE_CPR),0) | AL13: =IFERROR(LN(Z13)/(LN(W13)+LN(X13)+LN(Y13)+LN(Z13)+LN(AA13)+LN(AB13)+LN(AC13)+LN(AD13))*(AH13-V7_BASE_CPR),0) | AM13: =IFERROR(LN(AA13)/(LN(W13)+LN(X13)+LN(Y13)+LN(Z13)+LN(AA13)+LN(AB13)+LN(AC13)+LN(AD13))*(AH13-V7_BASE_CPR),0) | AN13: =IFERROR(LN(AB13)/(LN(W13)+LN(X13)+LN(Y13)+LN(Z13)+LN(AA13)+LN(AB13)+LN(AC13)+LN(AD13))*(AH13-V7_BASE_CPR),0) | AO13: =IFERROR(LN(AC13)/(LN(W13)+LN(X13)+LN(Y13)+LN(Z13)+LN(AA13)+LN(AB13)+LN(AC13)+LN(AD13))*(AH13-V7_BASE_CPR),0) | AP13: =IFERROR(LN(AD13)/(LN(W13)+LN(X13)+LN(Y13)+LN(Z13)+LN(AA13)+LN(AB13)+LN(AC13)+LN(AD13))*(AH13-V7_BASE_CPR),0) | AQ13: =V7_BASE_CPR+SUM(AI13:AP13)-AH13
A14: 3617LC5T1_000000004611186 | B14: LUMENT_PRE21 | C14: 3617LC5T1 | D14: LUMENT REAL ESTATE CAPITAL,LLC | E14: 223f | F14: RP | G14: 2019 | H14: 202602 | I14: 14083196 | J14: 2.95 | K14: 447 | L14: 4 | M14: 75 | N14: 7 | O14: 205412 | Q14: 3896 | R14: 0.093333333 | S14: 0 | T14: =LN(1+I14) | U14: =J14*100-K14 | V14: =U14-12.5*(L14+1) | W14: =IF(M14<=V7_AGE_KNOT_X_0,V7_AGE_KNOT_Y_0,IF(M14>=V7_AGE_KNOT_X_5,V7_AGE_KNOT_Y_5,IF(M14<=V7_AGE_KNOT_X_1,V7_AGE_KNOT_Y_0+(M14-V7_AGE_KNOT_X_0)/(V7_AGE_KNOT_X_1-V7_AGE_KNOT_X_0)*(V7_AGE_KNOT_Y_1-V7_AGE_KNOT_Y_0),IF(M14<=V7_AGE_KNOT_X_2,V7_AGE_KNOT_Y_1+(M14-V7_AGE_KNOT_X_1)/(V7_AGE_KNOT_X_2-V7_AGE_KNOT_X_1)*(V7_AGE_KNOT_Y_2-V7_AGE_KNOT_Y_1),IF(M14<=V7_AGE_KNOT_X_3,V7_AGE_KNOT_Y_2+(M14-V7_AGE_KNOT_X_2)/(V7_AGE_KNOT_X_3-V7_AGE_KNOT_X_2)*(V7_AGE_KNOT_Y_3-V7_AGE_KNOT_Y_2),IF(M14<=V7_AGE_KNOT_X_4,V7_AGE_KNOT_Y_3+(M14-V7_AGE_KNOT_X_3)/(V7_AGE_KNOT_X_4-V7_AGE_KNOT_X_3)*(V7_AGE_KNOT_Y_4-V7_AGE_KNOT_Y_3),V7_AGE_KNOT_Y_4+(M14-V7_AGE_KNOT_X_4)/(V7_AGE_KNOT_X_5-V7_AGE_KNOT_X_4)*(V7_AGE_KNOT_Y_5-V7_AGE_KNOT_Y_4))))))) | X14: =V7_RATE_FLOOR+V7_RATE_ASYMPTOTE/(1+EXP(-(V14-V7_RATE_MID)/V7_RATE_SLOPE)) | Y14: =MAX(V7_SIZE_LOW,MIN(V7_SIZE_HIGH,V7_SIZE_INTERCEPT+V7_SIZE_SLOPE*(T14-V7_SIZE_LOG_ANCHOR))) | Z14: =IF(ISNUMBER(SEARCH("232",E14)),VLOOKUP("232",V7_PROGRAM_TABLE,2,FALSE),IF(ISNUMBER(SEARCH("538",E14)),VLOOKUP("538",V7_PROGRAM_TABLE,2,FALSE),IF(ISNUMBER(SEARCH("223a7",E14)),VLOOKUP("223a7",V7_PROGRAM_TABLE,2,FALSE),IF(ISNUMBER(SEARCH("223f",E14)),VLOOKUP("223f",V7_PROGRAM_TABLE,2,FALSE),V7_PROGRAM_DEFAULT)))) | AA14: =IF(S14=1,1+V7_PURPOSE_NC_BUMP*MAX(0,1-ABS(M14-V7_PURPOSE_PEAK_AGE)/V7_PURPOSE_WIDTH),1) | AB14: =IF(AND(IF(OR(P14="",NOT(ISNUMBER(P14))),0,MAX(0,MIN(24,(INT(VALUE(H14)/100)-INT(P14/100))*12+MOD(VALUE(H14),100)-MOD(P14,100))))>0,IF(OR(P14="",NOT(ISNUMBER(P14))),0,MAX(0,MIN(24,(INT(VALUE(H14)/100)-INT(P14/100))*12+MOD(VALUE(H14),100)-MOD(P14,100))))<=12),1+V7_LOCKOUT_AMP*EXP(-(IF(OR(P14="",NOT(ISNUMBER(P14))),0,MAX(0,MIN(24,(INT(VALUE(H14)/100)-INT(P14/100))*12+MOD(VALUE(H14),100)-MOD(P14,100)))))/V7_LOCKOUT_TAU),1) | AC14: =IF(IF(OR(O14="",NOT(ISNUMBER(O14))),360,MAX(0,MIN(480,(INT(O14/100)-INT(VALUE(H14)/100))*12+MOD(O14,100)-MOD(VALUE(H14),100))))>0,1+V7_MTY_AMP*MAX(0,(V7_MTY_CUTOFF-(IF(OR(O14="",NOT(ISNUMBER(O14))),360,MAX(0,MIN(480,(INT(O14/100)-INT(VALUE(H14)/100))*12+MOD(O14,100)-MOD(VALUE(H14),100))))))/V7_MTY_CUTOFF),1) | AD14: =MAX(V7_BURN_FLOOR,1-V7_BURN_SLOPE*MIN(1,MAX(0,R14))) | AE14: =IF(V7_USE_ISSUER=1,IFERROR(VLOOKUP(Q14,V7_ISSUER_TABLE,3,FALSE),1),1) | AF14: =PRODUCT(W14:AE14) | AG14: =MIN(V7_BASE_SMM*AF14,V7_SMM_CAP) | AH14: =1-(1-AG14)^12 | AI14: =IFERROR(LN(W14)/(LN(W14)+LN(X14)+LN(Y14)+LN(Z14)+LN(AA14)+LN(AB14)+LN(AC14)+LN(AD14))*(AH14-V7_BASE_CPR),0) | AJ14: =IFERROR(LN(X14)/(LN(W14)+LN(X14)+LN(Y14)+LN(Z14)+LN(AA14)+LN(AB14)+LN(AC14)+LN(AD14))*(AH14-V7_BASE_CPR),0) | AK14: =IFERROR(LN(Y14)/(LN(W14)+LN(X14)+LN(Y14)+LN(Z14)+LN(AA14)+LN(AB14)+LN(AC14)+LN(AD14))*(AH14-V7_BASE_CPR),0) | AL14: =IFERROR(LN(Z14)/(LN(W14)+LN(X14)+LN(Y14)+LN(Z14)+LN(AA14)+LN(AB14)+LN(AC14)+LN(AD14))*(AH14-V7_BASE_CPR),0) | AM14: =IFERROR(LN(AA14)/(LN(W14)+LN(X14)+LN(Y14)+LN(Z14)+LN(AA14)+LN(AB14)+LN(AC14)+LN(AD14))*(AH14-V7_BASE_CPR),0) | AN14: =IFERROR(LN(AB14)/(LN(W14)+LN(X14)+LN(Y14)+LN(Z14)+LN(AA14)+LN(AB14)+LN(AC14)+LN(AD14))*(AH14-V7_BASE_CPR),0) | AO14: =IFERROR(LN(AC14)/(LN(W14)+LN(X14)+LN(Y14)+LN(Z14)+LN(AA14)+LN(AB14)+LN(AC14)+LN(AD14))*(AH14-V7_BASE_CPR),0) | AP14: =IFERROR(LN(AD14)/(LN(W14)+LN(X14)+LN(Y14)+LN(Z14)+LN(AA14)+LN(AB14)+LN(AC14)+LN(AD14))*(AH14-V7_BASE_CPR),0) | AQ14: =V7_BASE_CPR+SUM(AI14:AP14)-AH14
A15: 3617J9LY2_000000001411271 | B15: LUMENT_PRE21 | C15: 3617J9LY2 | D15: LUMENT REAL ESTATE CAPITAL,LLC | E15: 223f | F15: RP | G15: 2019 | H15: 202602 | I15: 6145581.9 | J15: 4.3 | K15: 447 | L15: 4 | M15: 82 | N15: 35 | O15: 205405 | Q15: 3896 | R15: 0.42682927 | S15: 0 | T15: =LN(1+I15) | U15: =J15*100-K15 | V15: =U15-12.5*(L15+1) | W15: =IF(M15<=V7_AGE_KNOT_X_0,V7_AGE_KNOT_Y_0,IF(M15>=V7_AGE_KNOT_X_5,V7_AGE_KNOT_Y_5,IF(M15<=V7_AGE_KNOT_X_1,V7_AGE_KNOT_Y_0+(M15-V7_AGE_KNOT_X_0)/(V7_AGE_KNOT_X_1-V7_AGE_KNOT_X_0)*(V7_AGE_KNOT_Y_1-V7_AGE_KNOT_Y_0),IF(M15<=V7_AGE_KNOT_X_2,V7_AGE_KNOT_Y_1+(M15-V7_AGE_KNOT_X_1)/(V7_AGE_KNOT_X_2-V7_AGE_KNOT_X_1)*(V7_AGE_KNOT_Y_2-V7_AGE_KNOT_Y_1),IF(M15<=V7_AGE_KNOT_X_3,V7_AGE_KNOT_Y_2+(M15-V7_AGE_KNOT_X_2)/(V7_AGE_KNOT_X_3-V7_AGE_KNOT_X_2)*(V7_AGE_KNOT_Y_3-V7_AGE_KNOT_Y_2),IF(M15<=V7_AGE_KNOT_X_4,V7_AGE_KNOT_Y_3+(M15-V7_AGE_KNOT_X_3)/(V7_AGE_KNOT_X_4-V7_AGE_KNOT_X_3)*(V7_AGE_KNOT_Y_4-V7_AGE_KNOT_Y_3),V7_AGE_KNOT_Y_4+(M15-V7_AGE_KNOT_X_4)/(V7_AGE_KNOT_X_5-V7_AGE_KNOT_X_4)*(V7_AGE_KNOT_Y_5-V7_AGE_KNOT_Y_4))))))) | X15: =V7_RATE_FLOOR+V7_RATE_ASYMPTOTE/(1+EXP(-(V15-V7_RATE_MID)/V7_RATE_SLOPE)) | Y15: =MAX(V7_SIZE_LOW,MIN(V7_SIZE_HIGH,V7_SIZE_INTERCEPT+V7_SIZE_SLOPE*(T15-V7_SIZE_LOG_ANCHOR))) | Z15: =IF(ISNUMBER(SEARCH("232",E15)),VLOOKUP("232",V7_PROGRAM_TABLE,2,FALSE),IF(ISNUMBER(SEARCH("538",E15)),VLOOKUP("538",V7_PROGRAM_TABLE,2,FALSE),IF(ISNUMBER(SEARCH("223a7",E15)),VLOOKUP("223a7",V7_PROGRAM_TABLE,2,FALSE),IF(ISNUMBER(SEARCH("223f",E15)),VLOOKUP("223f",V7_PROGRAM_TABLE,2,FALSE),V7_PROGRAM_DEFAULT)))) | AA15: =IF(S15=1,1+V7_PURPOSE_NC_BUMP*MAX(0,1-ABS(M15-V7_PURPOSE_PEAK_AGE)/V7_PURPOSE_WIDTH),1) | AB15: =IF(AND(IF(OR(P15="",NOT(ISNUMBER(P15))),0,MAX(0,MIN(24,(INT(VALUE(H15)/100)-INT(P15/100))*12+MOD(VALUE(H15),100)-MOD(P15,100))))>0,IF(OR(P15="",NOT(ISNUMBER(P15))),0,MAX(0,MIN(24,(INT(VALUE(H15)/100)-INT(P15/100))*12+MOD(VALUE(H15),100)-MOD(P15,100))))<=12),1+V7_LOCKOUT_AMP*EXP(-(IF(OR(P15="",NOT(ISNUMBER(P15))),0,MAX(0,MIN(24,(INT(VALUE(H15)/100)-INT(P15/100))*12+MOD(VALUE(H15),100)-MOD(P15,100)))))/V7_LOCKOUT_TAU),1) | AC15: =IF(IF(OR(O15="",NOT(ISNUMBER(O15))),360,MAX(0,MIN(480,(INT(O15/100)-INT(VALUE(H15)/100))*12+MOD(O15,100)-MOD(VALUE(H15),100))))>0,1+V7_MTY_AMP*MAX(0,(V7_MTY_CUTOFF-(IF(OR(O15="",NOT(ISNUMBER(O15))),360,MAX(0,MIN(480,(INT(O15/100)-INT(VALUE(H15)/100))*12+MOD(O15,100)-MOD(VALUE(H15),100))))))/V7_MTY_CUTOFF),1) | AD15: =MAX(V7_BURN_FLOOR,1-V7_BURN_SLOPE*MIN(1,MAX(0,R15))) | AE15: =IF(V7_USE_ISSUER=1,IFERROR(VLOOKUP(Q15,V7_ISSUER_TABLE,3,FALSE),1),1) | AF15: =PRODUCT(W15:AE15) | AG15: =MIN(V7_BASE_SMM*AF15,V7_SMM_CAP) | AH15: =1-(1-AG15)^12 | AI15: =IFERROR(LN(W15)/(LN(W15)+LN(X15)+LN(Y15)+LN(Z15)+LN(AA15)+LN(AB15)+LN(AC15)+LN(AD15))*(AH15-V7_BASE_CPR),0) | AJ15: =IFERROR(LN(X15)/(LN(W15)+LN(X15)+LN(Y15)+LN(Z15)+LN(AA15)+LN(AB15)+LN(AC15)+LN(AD15))*(AH15-V7_BASE_CPR),0) | AK15: =IFERROR(LN(Y15)/(LN(W15)+LN(X15)+LN(Y15)+LN(Z15)+LN(AA15)+LN(AB15)+LN(AC15)+LN(AD15))*(AH15-V7_BASE_CPR),0) | AL15: =IFERROR(LN(Z15)/(LN(W15)+LN(X15)+LN(Y15)+LN(Z15)+LN(AA15)+LN(AB15)+LN(AC15)+LN(AD15))*(AH15-V7_BASE_CPR),0) | AM15: =IFERROR(LN(AA15)/(LN(W15)+LN(X15)+LN(Y15)+LN(Z15)+LN(AA15)+LN(AB15)+LN(AC15)+LN(AD15))*(AH15-V7_BASE_CPR),0) | AN15: =IFERROR(LN(AB15)/(LN(W15)+LN(X15)+LN(Y15)+LN(Z15)+LN(AA15)+LN(AB15)+LN(AC15)+LN(AD15))*(AH15-V7_BASE_CPR),0) | AO15: =IFERROR(LN(AC15)/(LN(W15)+LN(X15)+LN(Y15)+LN(Z15)+LN(AA15)+LN(AB15)+LN(AC15)+LN(AD15))*(AH15-V7_BASE_CPR),0) | AP15: =IFERROR(LN(AD15)/(LN(W15)+LN(X15)+LN(Y15)+LN(Z15)+LN(AA15)+LN(AB15)+LN(AC15)+LN(AD15))*(AH15-V7_BASE_CPR),0) | AQ15: =V7_BASE_CPR+SUM(AI15:AP15)-AH15
A16: 3617FTDM7_000000008311235 | B16: LUMENT_POST21 | C16: 3617FTDM7 | D16: LUMENT REAL ESTATE CAPITAL,LLC | E16: 223f | F16: RP | G16: 2023 | H16: 202602 | I16: 15752462 | J16: 5.1 | K16: 447 | L16: 8 | M16: 34 | N16: 0 | O16: 205805 | Q16: 3896 | R16: 0 | S16: 0 | T16: =LN(1+I16) | U16: =J16*100-K16 | V16: =U16-12.5*(L16+1) | W16: =IF(M16<=V7_AGE_KNOT_X_0,V7_AGE_KNOT_Y_0,IF(M16>=V7_AGE_KNOT_X_5,V7_AGE_KNOT_Y_5,IF(M16<=V7_AGE_KNOT_X_1,V7_AGE_KNOT_Y_0+(M16-V7_AGE_KNOT_X_0)/(V7_AGE_KNOT_X_1-V7_AGE_KNOT_X_0)*(V7_AGE_KNOT_Y_1-V7_AGE_KNOT_Y_0),IF(M16<=V7_AGE_KNOT_X_2,V7_AGE_KNOT_Y_1+(M16-V7_AGE_KNOT_X_1)/(V7_AGE_KNOT_X_2-V7_AGE_KNOT_X_1)*(V7_AGE_KNOT_Y_2-V7_AGE_KNOT_Y_1),IF(M16<=V7_AGE_KNOT_X_3,V7_AGE_KNOT_Y_2+(M16-V7_AGE_KNOT_X_2)/(V7_AGE_KNOT_X_3-V7_AGE_KNOT_X_2)*(V7_AGE_KNOT_Y_3-V7_AGE_KNOT_Y_2),IF(M16<=V7_AGE_KNOT_X_4,V7_AGE_KNOT_Y_3+(M16-V7_AGE_KNOT_X_3)/(V7_AGE_KNOT_X_4-V7_AGE_KNOT_X_3)*(V7_AGE_KNOT_Y_4-V7_AGE_KNOT_Y_3),V7_AGE_KNOT_Y_4+(M16-V7_AGE_KNOT_X_4)/(V7_AGE_KNOT_X_5-V7_AGE_KNOT_X_4)*(V7_AGE_KNOT_Y_5-V7_AGE_KNOT_Y_4))))))) | X16: =V7_RATE_FLOOR+V7_RATE_ASYMPTOTE/(1+EXP(-(V16-V7_RATE_MID)/V7_RATE_SLOPE)) | Y16: =MAX(V7_SIZE_LOW,MIN(V7_SIZE_HIGH,V7_SIZE_INTERCEPT+V7_SIZE_SLOPE*(T16-V7_SIZE_LOG_ANCHOR))) | Z16: =IF(ISNUMBER(SEARCH("232",E16)),VLOOKUP("232",V7_PROGRAM_TABLE,2,FALSE),IF(ISNUMBER(SEARCH("538",E16)),VLOOKUP("538",V7_PROGRAM_TABLE,2,FALSE),IF(ISNUMBER(SEARCH("223a7",E16)),VLOOKUP("223a7",V7_PROGRAM_TABLE,2,FALSE),IF(ISNUMBER(SEARCH("223f",E16)),VLOOKUP("223f",V7_PROGRAM_TABLE,2,FALSE),V7_PROGRAM_DEFAULT)))) | AA16: =IF(S16=1,1+V7_PURPOSE_NC_BUMP*MAX(0,1-ABS(M16-V7_PURPOSE_PEAK_AGE)/V7_PURPOSE_WIDTH),1) | AB16: =IF(AND(IF(OR(P16="",NOT(ISNUMBER(P16))),0,MAX(0,MIN(24,(INT(VALUE(H16)/100)-INT(P16/100))*12+MOD(VALUE(H16),100)-MOD(P16,100))))>0,IF(OR(P16="",NOT(ISNUMBER(P16))),0,MAX(0,MIN(24,(INT(VALUE(H16)/100)-INT(P16/100))*12+MOD(VALUE(H16),100)-MOD(P16,100))))<=12),1+V7_LOCKOUT_AMP*EXP(-(IF(OR(P16="",NOT(ISNUMBER(P16))),0,MAX(0,MIN(24,(INT(VALUE(H16)/100)-INT(P16/100))*12+MOD(VALUE(H16),100)-MOD(P16,100)))))/V7_LOCKOUT_TAU),1) | AC16: =IF(IF(OR(O16="",NOT(ISNUMBER(O16))),360,MAX(0,MIN(480,(INT(O16/100)-INT(VALUE(H16)/100))*12+MOD(O16,100)-MOD(VALUE(H16),100))))>0,1+V7_MTY_AMP*MAX(0,(V7_MTY_CUTOFF-(IF(OR(O16="",NOT(ISNUMBER(O16))),360,MAX(0,MIN(480,(INT(O16/100)-INT(VALUE(H16)/100))*12+MOD(O16,100)-MOD(VALUE(H16),100))))))/V7_MTY_CUTOFF),1) | AD16: =MAX(V7_BURN_FLOOR,1-V7_BURN_SLOPE*MIN(1,MAX(0,R16))) | AE16: =IF(V7_USE_ISSUER=1,IFERROR(VLOOKUP(Q16,V7_ISSUER_TABLE,3,FALSE),1),1) | AF16: =PRODUCT(W16:AE16) | AG16: =MIN(V7_BASE_SMM*AF16,V7_SMM_CAP) | AH16: =1-(1-AG16)^12 | AI16: =IFERROR(LN(W16)/(LN(W16)+LN(X16)+LN(Y16)+LN(Z16)+LN(AA16)+LN(AB16)+LN(AC16)+LN(AD16))*(AH16-V7_BASE_CPR),0) | AJ16: =IFERROR(LN(X16)/(LN(W16)+LN(X16)+LN(Y16)+LN(Z16)+LN(AA16)+LN(AB16)+LN(AC16)+LN(AD16))*(AH16-V7_BASE_CPR),0) | AK16: =IFERROR(LN(Y16)/(LN(W16)+LN(X16)+LN(Y16)+LN(Z16)+LN(AA16)+LN(AB16)+LN(AC16)+LN(AD16))*(AH16-V7_BASE_CPR),0) | AL16: =IFERROR(LN(Z16)/(LN(W16)+LN(X16)+LN(Y16)+LN(Z16)+LN(AA16)+LN(AB16)+LN(AC16)+LN(AD16))*(AH16-V7_BASE_CPR),0) | AM16: =IFERROR(LN(AA16)/(LN(W16)+LN(X16)+LN(Y16)+LN(Z16)+LN(AA16)+LN(AB16)+LN(AC16)+LN(AD16))*(AH16-V7_BASE_CPR),0) | AN16: =IFERROR(LN(AB16)/(LN(W16)+LN(X16)+LN(Y16)+LN(Z16)+LN(AA16)+LN(AB16)+LN(AC16)+LN(AD16))*(AH16-V7_BASE_CPR),0) | AO16: =IFERROR(LN(AC16)/(LN(W16)+LN(X16)+LN(Y16)+LN(Z16)+LN(AA16)+LN(AB16)+LN(AC16)+LN(AD16))*(AH16-V7_BASE_CPR),0) | AP16: =IFERROR(LN(AD16)/(LN(W16)+LN(X16)+LN(Y16)+LN(Z16)+LN(AA16)+LN(AB16)+LN(AC16)+LN(AD16))*(AH16-V7_BASE_CPR),0) | AQ16: =V7_BASE_CPR+SUM(AI16:AP16)-AH16
A17: 36187SCA3_000000001411159 | B17: LUMENT_PRE21 | C17: 36187SCA3 | D17: LUMENT REAL ESTATE CAPITAL,LLC | E17: 223f | F17: RP | G17: 2009 | H17: 202602 | I17: 1334344.3 | J17: 4.29 | K17: 447 | L17: 0 | M17: 205 | N17: 38 | O17: 204403 | Q17: 3896 | R17: 0.18536585 | S17: 0 | T17: =LN(1+I17) | U17: =J17*100-K17 | V17: =U17-12.5*(L17+1) | W17: =IF(M17<=V7_AGE_KNOT_X_0,V7_AGE_KNOT_Y_0,IF(M17>=V7_AGE_KNOT_X_5,V7_AGE_KNOT_Y_5,IF(M17<=V7_AGE_KNOT_X_1,V7_AGE_KNOT_Y_0+(M17-V7_AGE_KNOT_X_0)/(V7_AGE_KNOT_X_1-V7_AGE_KNOT_X_0)*(V7_AGE_KNOT_Y_1-V7_AGE_KNOT_Y_0),IF(M17<=V7_AGE_KNOT_X_2,V7_AGE_KNOT_Y_1+(M17-V7_AGE_KNOT_X_1)/(V7_AGE_KNOT_X_2-V7_AGE_KNOT_X_1)*(V7_AGE_KNOT_Y_2-V7_AGE_KNOT_Y_1),IF(M17<=V7_AGE_KNOT_X_3,V7_AGE_KNOT_Y_2+(M17-V7_AGE_KNOT_X_2)/(V7_AGE_KNOT_X_3-V7_AGE_KNOT_X_2)*(V7_AGE_KNOT_Y_3-V7_AGE_KNOT_Y_2),IF(M17<=V7_AGE_KNOT_X_4,V7_AGE_KNOT_Y_3+(M17-V7_AGE_KNOT_X_3)/(V7_AGE_KNOT_X_4-V7_AGE_KNOT_X_3)*(V7_AGE_KNOT_Y_4-V7_AGE_KNOT_Y_3),V7_AGE_KNOT_Y_4+(M17-V7_AGE_KNOT_X_4)/(V7_AGE_KNOT_X_5-V7_AGE_KNOT_X_4)*(V7_AGE_KNOT_Y_5-V7_AGE_KNOT_Y_4))))))) | X17: =V7_RATE_FLOOR+V7_RATE_ASYMPTOTE/(1+EXP(-(V17-V7_RATE_MID)/V7_RATE_SLOPE)) | Y17: =MAX(V7_SIZE_LOW,MIN(V7_SIZE_HIGH,V7_SIZE_INTERCEPT+V7_SIZE_SLOPE*(T17-V7_SIZE_LOG_ANCHOR))) | Z17: =IF(ISNUMBER(SEARCH("232",E17)),VLOOKUP("232",V7_PROGRAM_TABLE,2,FALSE),IF(ISNUMBER(SEARCH("538",E17)),VLOOKUP("538",V7_PROGRAM_TABLE,2,FALSE),IF(ISNUMBER(SEARCH("223a7",E17)),VLOOKUP("223a7",V7_PROGRAM_TABLE,2,FALSE),IF(ISNUMBER(SEARCH("223f",E17)),VLOOKUP("223f",V7_PROGRAM_TABLE,2,FALSE),V7_PROGRAM_DEFAULT)))) | AA17: =IF(S17=1,1+V7_PURPOSE_NC_BUMP*MAX(0,1-ABS(M17-V7_PURPOSE_PEAK_AGE)/V7_PURPOSE_WIDTH),1) | AB17: =IF(AND(IF(OR(P17="",NOT(ISNUMBER(P17))),0,MAX(0,MIN(24,(INT(VALUE(H17)/100)-INT(P17/100))*12+MOD(VALUE(H17),100)-MOD(P17,100))))>0,IF(OR(P17="",NOT(ISNUMBER(P17))),0,MAX(0,MIN(24,(INT(VALUE(H17)/100)-INT(P17/100))*12+MOD(VALUE(H17),100)-MOD(P17,100))))<=12),1+V7_LOCKOUT_AMP*EXP(-(IF(OR(P17="",NOT(ISNUMBER(P17))),0,MAX(0,MIN(24,(INT(VALUE(H17)/100)-INT(P17/100))*12+MOD(VALUE(H17),100)-MOD(P17,100)))))/V7_LOCKOUT_TAU),1) | AC17: =IF(IF(OR(O17="",NOT(ISNUMBER(O17))),360,MAX(0,MIN(480,(INT(O17/100)-INT(VALUE(H17)/100))*12+MOD(O17,100)-MOD(VALUE(H17),100))))>0,1+V7_MTY_AMP*MAX(0,(V7_MTY_CUTOFF-(IF(OR(O17="",NOT(ISNUMBER(O17))),360,MAX(0,MIN(480,(INT(O17/100)-INT(VALUE(H17)/100))*12+MOD(O17,100)-MOD(VALUE(H17),100))))))/V7_MTY_CUTOFF),1) | AD17: =MAX(V7_BURN_FLOOR,1-V7_BURN_SLOPE*MIN(1,MAX(0,R17))) | AE17: =IF(V7_USE_ISSUER=1,IFERROR(VLOOKUP(Q17,V7_ISSUER_TABLE,3,FALSE),1),1) | AF17: =PRODUCT(W17:AE17) | AG17: =MIN(V7_BASE_SMM*AF17,V7_SMM_CAP) | AH17: =1-(1-AG17)^12 | AI17: =IFERROR(LN(W17)/(LN(W17)+LN(X17)+LN(Y17)+LN(Z17)+LN(AA17)+LN(AB17)+LN(AC17)+LN(AD17))*(AH17-V7_BASE_CPR),0) | AJ17: =IFERROR(LN(X17)/(LN(W17)+LN(X17)+LN(Y17)+LN(Z17)+LN(AA17)+LN(AB17)+LN(AC17)+LN(AD17))*(AH17-V7_BASE_CPR),0) | AK17: =IFERROR(LN(Y17)/(LN(W17)+LN(X17)+LN(Y17)+LN(Z17)+LN(AA17)+LN(AB17)+LN(AC17)+LN(AD17))*(AH17-V7_BASE_CPR),0) | AL17: =IFERROR(LN(Z17)/(LN(W17)+LN(X17)+LN(Y17)+LN(Z17)+LN(AA17)+LN(AB17)+LN(AC17)+LN(AD17))*(AH17-V7_BASE_CPR),0) | AM17: =IFERROR(LN(AA17)/(LN(W17)+LN(X17)+LN(Y17)+LN(Z17)+LN(AA17)+LN(AB17)+LN(AC17)+LN(AD17))*(AH17-V7_BASE_CPR),0) | AN17: =IFERROR(LN(AB17)/(LN(W17)+LN(X17)+LN(Y17)+LN(Z17)+LN(AA17)+LN(AB17)+LN(AC17)+LN(AD17))*(AH17-V7_BASE_CPR),0) | AO17: =IFERROR(LN(AC17)/(LN(W17)+LN(X17)+LN(Y17)+LN(Z17)+LN(AA17)+LN(AB17)+LN(AC17)+LN(AD17))*(AH17-V7_BASE_CPR),0) | AP17: =IFERROR(LN(AD17)/(LN(W17)+LN(X17)+LN(Y17)+LN(Z17)+LN(AA17)+LN(AB17)+LN(AC17)+LN(AD17))*(AH17-V7_BASE_CPR),0) | AQ17: =V7_BASE_CPR+SUM(AI17:AP17)-AH17
